Workbook

Sheet OIS vs Treasury
B2: Year Fraction | C2: OIS_Par | D2: Treasury_Par | E2: Diff(Bond-Swap Spread) | F2: OIS_DF | G2: Treasury_DF | H2: Diff | I2: OIS_Spot | J2: Treasury_Spot | K2: Diff | L2: OIS_Forward | M2: Treasury_Forward | N2: Diff
B3: {=_xlfn.SEQUENCE(40,1,0.25,0.25)} -> 0.25 | C3: =-LN(F3)/B3 -> 0.036534696 | D3: =VLOOKUP(B3,'Treasury DF Log Linear'!$G$5:$H$18,2,0) -> 0.037 | E3: =C3-D3 -> -0.00046530389 | F3: ='OIS DF Log Linear'!G63 -> 0.99090791 | G3: ='Treasury DF Log Linear'!G46 -> 0.9908764 | H3: =F3-G3 -> 3.1514646e-05 | I3: ='OIS DF Log Linear'!I63 -> 0.036534696 | J3: ='Treasury DF Log Linear'!I46 -> 0.036661913 | K3: =I3-J3 -> -0.00012721726 | L3: ='OIS DF Log Linear'!J63 -> 0.036534696 | M3: ='Treasury DF Log Linear'!K46 -> 0.036661913 | N3: =L3-M3 -> -0.00012721726
B4: 0.5 | C4: =-LN(F4)/B4 -> 0.036228089 | D4: =VLOOKUP(B4,'Treasury DF Log Linear'!$G$5:$H$18,2,0) -> 0.0361 | E4: =C4-D4 -> 0.00012808933 | F4: ='OIS DF Log Linear'!G64 -> 0.98204903 | G4: ='Treasury DF Log Linear'!G47 -> 0.98227003 | H4: =F4-G4 -> -0.00022099751 | I4: ='OIS DF Log Linear'!I64 -> 0.036228089 | J4: ='Treasury DF Log Linear'!I47 -> 0.035778066 | K4: =I4-J4 -> 0.00045002366 | L4: ='OIS DF Log Linear'!J64 -> 0.035921483 | M4: ='Treasury DF Log Linear'!K47 -> 0.034894218 | N4: =L4-M4 -> 0.0010272646
B5: 0.75 | C5: =-LN(F5)/B5 -> 0.035723705 | D5: =AVERAGE(D4,D6) -> 0.0357 | E5: =C5-D5 -> 2.3704512e-05 | F5: ='OIS DF Log Linear'!G65 -> 0.97356296 | G5: ='Treasury DF Log Linear'!G48 -> 0.9739093 | H5: =F5-G5 -> -0.00034634017 | I5: ='OIS DF Log Linear'!I65 -> 0.035723705 | J5: ='Treasury DF Log Linear'!I48 -> 0.035249462 | K5: =I5-J5 -> 0.00047424233 | L5: ='OIS DF Log Linear'!J65 -> 0.034714935 | M5: ='Treasury DF Log Linear'!K48 -> 0.034192255 | N5: =L5-M5 -> 0.00052267969
B6: 1 | C6: 0.03524 | D6: =VLOOKUP(B6,'Treasury DF Log Linear'!$G$5:$H$18,2,0) -> 0.0353 | E6: =C6-D6 -> -6e-05 | F6: ='OIS DF Log Linear'!G66 -> 0.96595958 | G6: ='Treasury DF Log Linear'!G49 -> 0.96561975 | H6: =F6-G6 -> 0.00033983872 | I6: ='OIS DF Log Linear'!I66 -> 0.034633284 | J6: ='Treasury DF Log Linear'!I49 -> 0.03498516 | K6: =I6-J6 -> -0.00035187654 | L6: ='OIS DF Log Linear'!J66 -> 0.031362022 | M6: ='Treasury DF Log Linear'!K49 -> 0.034192255 | N6: =L6-M6 -> -0.0028302332
B7: 1.25 | C7: =$C$6 + (B7 - $B$6) * ($C$10 - $C$6) / ($B$10 - $B$6) -> 0.0350225 | D7: {=TREND(CHOOSE({1,2}, D6, D10), CHOOSE({1,2}, B6, B10), B7:B9)} -> 0.035475 | E7: =C7-D7 -> -0.0004525 | F7: ='OIS DF Log Linear'!G67 -> 0.95804166 | G7: ='Treasury DF Log Linear'!G50 -> 0.95687428 | H7: =F7-G7 -> 0.0011673814 | I7: ='OIS DF Log Linear'!I67 -> 0.034291212 | J7: ='Treasury DF Log Linear'!I50 -> 0.035266613 | K7: =I7-J7 -> -0.00097540077 | L7: ='OIS DF Log Linear'!J67 -> 0.032922924 | M7: ='Treasury DF Log Linear'!K50 -> 0.036392422 | N7: =L7-M7 -> -0.0034694977
B8: 1.5 | C8: =$C$6 + (B8 - $B$6) * ($C$10 - $C$6) / ($B$10 - $B$6) -> 0.034805 | D8: 0.03565 | E8: =C8-D8 -> -0.000845 | F8: ='OIS DF Log Linear'!G68 -> 0.95018864 | G8: ='Treasury DF Log Linear'!G51 -> 0.94820802 | H8: =F8-G8 -> 0.0019806206 | I8: ='OIS DF Log Linear'!I68 -> 0.034063164 | J8: ='Treasury DF Log Linear'!I51 -> 0.035454248 | K8: =I8-J8 -> -0.0013910836 | L8: ='OIS DF Log Linear'!J68 -> 0.032922924 | M8: ='Treasury DF Log Linear'!K51 -> 0.036392422 | N8: =L8-M8 -> -0.0034694977
B9: 1.75 | C9: =$C$6 + (B9 - $B$6) * ($C$10 - $C$6) / ($B$10 - $B$6) -> 0.0345875 | D9: 0.035825 | E9: =C9-D9 -> -0.0012375 | F9: ='OIS DF Log Linear'!G69 -> 0.94239999 | G9: ='Treasury DF Log Linear'!G52 -> 0.93962025 | H9: =F9-G9 -> 0.0027797417 | I9: ='OIS DF Log Linear'!I69 -> 0.033900272 | J9: ='Treasury DF Log Linear'!I52 -> 0.035588272 | K9: =I9-J9 -> -0.0016879999 | L9: ='OIS DF Log Linear'!J69 -> 0.032922924 | M9: ='Treasury DF Log Linear'!K52 -> 0.036392422 | N9: =L9-M9 -> -0.0034694977
B10: 2 | C10: 0.03437 | D10: =VLOOKUP(B10,'Treasury DF Log Linear'!$G$5:$H$18,2,0) -> 0.036 | E10: =C10-D10 -> -0.00163 | F10: ='OIS DF Log Linear'!G70 -> 0.93467518 | G10: ='Treasury DF Log Linear'!G53 -> 0.93111026 | H10: =F10-G10 -> 0.0035649279 | I10: ='OIS DF Log Linear'!I70 -> 0.033778104 | J10: ='Treasury DF Log Linear'!I53 -> 0.035688791 | K10: =I10-J10 -> -0.0019106871 | L10: ='OIS DF Log Linear'!J70 -> 0.032922924 | M10: ='Treasury DF Log Linear'!K53 -> 0.036392422 | N10: =L10-M10 -> -0.0034694977
B11: 2.25 | C11: =$C$10 + (B11 - $B$10) * ($C$14 - $C$10) / ($B$14 - $B$10) -> 0.0344425 | D11: {=TREND(CHOOSE({1,2}, D10, D14), CHOOSE({1,2}, B10, B14), B11:B13)} -> 0.036175 | E11: =C11-D11 -> -0.0017325 | F11: ='OIS DF Log Linear'!G71 -> 0.92661057 | G11: ='Treasury DF Log Linear'!G54 -> 0.92234807 | H11: =F11-G11 -> 0.0042624999 | I11: ='OIS DF Log Linear'!I71 -> 0.033876398 | J11: ='Treasury DF Log Linear'!I54 -> 0.035925603 | K11: =I11-J11 -> -0.0020492051 | L11: ='OIS DF Log Linear'!J71 -> 0.034662751 | M11: ='Treasury DF Log Linear'!K54 -> 0.0378201 | N11: =L11-M11 -> -0.0031573491
B12: 2.5 | C12: =$C$10 + (B12 - $B$10) * ($C$14 - $C$10) / ($B$14 - $B$10) -> 0.034515 | D12: 0.03635 | E12: =C12-D12 -> -0.001835 | F12: ='OIS DF Log Linear'!G72 -> 0.91861555 | G12: ='Treasury DF Log Linear'!G55 -> 0.91366835 | H12: =F12-G12 -> 0.0049471992 | I12: ='OIS DF Log Linear'!I72 -> 0.033955033 | J12: ='Treasury DF Log Linear'!I55 -> 0.036115053 | K12: =I12-J12 -> -0.0021600195 | L12: ='OIS DF Log Linear'!J72 -> 0.034662751 | M12: ='Treasury DF Log Linear'!K55 -> 0.0378201 | N12: =L12-M12 -> -0.0031573491
B13: 2.75 | C13: =$C$10 + (B13 - $B$10) * ($C$14 - $C$10) / ($B$14 - $B$10) -> 0.0345875 | D13: 0.036525 | E13: =C13-D13 -> -0.0019375 | F13: ='OIS DF Log Linear'!G73 -> 0.9106895 | G13: ='Treasury DF Log Linear'!G56 -> 0.9050703 | H13: =F13-G13 -> 0.0056192013 | I13: ='OIS DF Log Linear'!I73 -> 0.034019371 | J13: ='Treasury DF Log Linear'!I56 -> 0.036270057 | K13: =I13-J13 -> -0.0022506858 | L13: ='OIS DF Log Linear'!J73 -> 0.034662751 | M13: ='Treasury DF Log Linear'!K56 -> 0.0378201 | N13: =L13-M13 -> -0.0031573491
B14: 3 | C14: 0.03466 | D14: =VLOOKUP(B14,'Treasury DF Log Linear'!$G$5:$H$18,2,0) -> 0.0367 | E14: =C14-D14 -> -0.00204 | F14: ='OIS DF Log Linear'!G74 -> 0.90283185 | G14: ='Treasury DF Log Linear'!G57 -> 0.89655317 | H14: =F14-G14 -> 0.0062786796 | I14: ='OIS DF Log Linear'!I74 -> 0.034072986 | J14: ='Treasury DF Log Linear'!I57 -> 0.036399227 | K14: =I14-J14 -> -0.0023262411 | L14: ='OIS DF Log Linear'!J74 -> 0.034662751 | M14: ='Treasury DF Log Linear'!K57 -> 0.0378201 | N14: =L14-M14 -> -0.0031573491
B15: 3.25 | C15: =$C$14 + (B15 - $B$14) * ($C$22 - $C$14) / ($B$22 - $B$14) -> 0.03480125 | D15: {=TREND(CHOOSE({1,2}, D14, D22), CHOOSE({1,2}, B14, B22), B15:B21)} -> 0.0369125 | E15: =C15-D15 -> -0.00211125 | F15: ='OIS DF Log Linear'!G75 -> 0.89447572 | G15: ='Treasury DF Log Linear'!G58 -> 0.88745645 | H15: =F15-G15 -> 0.0070192643 | I15: ='OIS DF Log Linear'!I75 -> 0.034313084 | J15: ='Treasury DF Log Linear'!I58 -> 0.036737177 | K15: =I15-J15 -> -0.0024240932 | L15: ='OIS DF Log Linear'!J75 -> 0.037194253 | M15: ='Treasury DF Log Linear'!K58 -> 0.040792571 | N15: =L15-M15 -> -0.003598318
B16: 3.5 | C16: =$C$14 + (B16 - $B$14) * ($C$22 - $C$14) / ($B$22 - $B$14) -> 0.0349425 | D16: 0.037125 | E16: =C16-D16 -> -0.0021825 | F16: ='OIS DF Log Linear'!G76 -> 0.88619693 | G16: ='Treasury DF Log Linear'!G59 -> 0.87845204 | H16: =F16-G16 -> 0.0077448907 | I16: ='OIS DF Log Linear'!I76 -> 0.034518881 | J16: ='Treasury DF Log Linear'!I59 -> 0.037026848 | K16: =I16-J16 -> -0.0025079664 | L16: ='OIS DF Log Linear'!J76 -> 0.037194253 | M16: ='Treasury DF Log Linear'!K59 -> 0.040792571 | N16: =L16-M16 -> -0.003598318
B17: 3.75 | C17: =$C$14 + (B17 - $B$14) * ($C$22 - $C$14) / ($B$22 - $B$14) -> 0.03508375 | D17: 0.0373375 | E17: =C17-D17 -> -0.00225375 | F17: ='OIS DF Log Linear'!G77 -> 0.87799476 | G17: ='Treasury DF Log Linear'!G60 -> 0.86953898 | H17: =F17-G17 -> 0.0084557796 | I17: ='OIS DF Log Linear'!I77 -> 0.03469724 | J17: ='Treasury DF Log Linear'!I60 -> 0.037277896 | K17: =I17-J17 -> -0.0025806565 | L17: ='OIS DF Log Linear'!J77 -> 0.037194253 | M17: ='Treasury DF Log Linear'!K60 -> 0.040792571 | N17: =L17-M17 -> -0.003598318
B18: 4 | C18: =$C$14 + (B18 - $B$14) * ($C$22 - $C$14) / ($B$22 - $B$14) -> 0.035225 | D18: 0.03755 | E18: =C18-D18 -> -0.002325 | F18: ='OIS DF Log Linear'!G78 -> 0.86986851 | G18: ='Treasury DF Log Linear'!G61 -> 0.86071637 | H18: =F18-G18 -> 0.0091521485 | I18: ='OIS DF Log Linear'!I78 -> 0.034853303 | J18: ='Treasury DF Log Linear'!I61 -> 0.037497563 | K18: =I18-J18 -> -0.0026442603 | L18: ='OIS DF Log Linear'!J78 -> 0.037194253 | M18: ='Treasury DF Log Linear'!K61 -> 0.040792571 | N18: =L18-M18 -> -0.003598318
B19: 4.25 | C19: =$C$14 + (B19 - $B$14) * ($C$22 - $C$14) / ($B$22 - $B$14) -> 0.03536625 | D19: 0.0377625 | E19: =C19-D19 -> -0.00239625 | F19: ='OIS DF Log Linear'!G79 -> 0.86181748 | G19: ='Treasury DF Log Linear'!G62 -> 0.85198326 | H19: =F19-G19 -> 0.0098342127 | I19: ='OIS DF Log Linear'!I79 -> 0.034991006 | J19: ='Treasury DF Log Linear'!I62 -> 0.037691387 | K19: =I19-J19 -> -0.0027003814 | L19: ='OIS DF Log Linear'!J79 -> 0.037194253 | M19: ='Treasury DF Log Linear'!K62 -> 0.040792571 | N19: =L19-M19 -> -0.003598318
B20: 4.5 | C20: =$C$14 + (B20 - $B$14) * ($C$22 - $C$14) / ($B$22 - $B$14) -> 0.0355075 | D20: 0.037975 | E20: =C20-D20 -> -0.0024675 | F20: ='OIS DF Log Linear'!G80 -> 0.85384095 | G20: ='Treasury DF Log Linear'!G63 -> 0.84333877 | H20: =F20-G20 -> 0.010502184 | I20: ='OIS DF Log Linear'!I80 -> 0.035113408 | J20: ='Treasury DF Log Linear'!I63 -> 0.037863675 | K20: =I20-J20 -> -0.0027502667 | L20: ='OIS DF Log Linear'!J80 -> 0.037194253 | M20: ='Treasury DF Log Linear'!K63 -> 0.040792571 | N20: =L20-M20 -> -0.003598318
B21: 4.75 | C21: =$C$14 + (B21 - $B$14) * ($C$22 - $C$14) / ($B$22 - $B$14) -> 0.03564875 | D21: 0.0381875 | E21: =C21-D21 -> -0.00253875 | F21: ='OIS DF Log Linear'!G81 -> 0.84593826 | G21: ='Treasury DF Log Linear'!G64 -> 0.83478199 | H21: =F21-G21 -> 0.011156272 | I21: ='OIS DF Log Linear'!I81 -> 0.035222927 | J21: ='Treasury DF Log Linear'!I64 -> 0.038017828 | K21: =I21-J21 -> -0.002794901 | L21: ='OIS DF Log Linear'!J81 -> 0.037194253 | M21: ='Treasury DF Log Linear'!K64 -> 0.040792571 | N21: =L21-M21 -> -0.003598318
B22: 5 | C22: 0.03579 | D22: =VLOOKUP(B22,'Treasury DF Log Linear'!$G$5:$H$18,2,0) -> 0.0384 | E22: =C22-D22 -> -0.00261 | F22: ='OIS DF Log Linear'!G82 -> 0.83810871 | G22: ='Treasury DF Log Linear'!G65 -> 0.82631202 | H22: =F22-G22 -> 0.011796683 | I22: ='OIS DF Log Linear'!I82 -> 0.035321493 | J22: ='Treasury DF Log Linear'!I65 -> 0.038156565 | K22: =I22-J22 -> -0.0028350719 | L22: ='OIS DF Log Linear'!J82 -> 0.037194253 | M22: ='Treasury DF Log Linear'!K65 -> 0.040792571 | N22: =L22-M22 -> -0.003598318
B23: 5.25 | C23: =$C$22 + (B23 - $B$22) * ($C$30 - $C$22) / ($B$30 - $B$22) -> 0.03595375 | D23: {=TREND(CHOOSE({1,2}, D22, D30), CHOOSE({1,2}, B22, B30), B23:B29)} -> 0.0386375 | E23: =C23-D23 -> -0.00268375 | F23: ='OIS DF Log Linear'!G83 -> 0.8298034 | G23: ='Treasury DF Log Linear'!G66 -> 0.81700996 | H23: =F23-G23 -> 0.01279344 | I23: ='OIS DF Log Linear'!I83 -> 0.035536472 | J23: ='Treasury DF Log Linear'!I66 -> 0.038496 | K23: =I23-J23 -> -0.0029595275 | L23: ='OIS DF Log Linear'!J83 -> 0.039836056 | M23: ='Treasury DF Log Linear'!K66 -> 0.045284697 | N23: =L23-M23 -> -0.0054486409
B24: 5.5 | C24: =$C$22 + (B24 - $B$22) * ($C$30 - $C$22) / ($B$30 - $B$22) -> 0.0361175 | D24: 0.038875 | E24: =C24-D24 -> -0.0027575 | F24: ='OIS DF Log Linear'!G84 -> 0.82158039 | G24: ='Treasury DF Log Linear'!G67 -> 0.8078126 | H24: =F24-G24 -> 0.013767782 | I24: ='OIS DF Log Linear'!I84 -> 0.035731908 | J24: ='Treasury DF Log Linear'!I67 -> 0.038804577 | K24: =I24-J24 -> -0.003072669 | L24: ='OIS DF Log Linear'!J84 -> 0.039836056 | M24: ='Treasury DF Log Linear'!K67 -> 0.045284697 | N24: =L24-M24 -> -0.0054486409
B25: 5.75 | C25: =$C$22 + (B25 - $B$22) * ($C$30 - $C$22) / ($B$30 - $B$22) -> 0.03628125 | D25: 0.0391125 | E25: =C25-D25 -> -0.00283125 | F25: ='OIS DF Log Linear'!G85 -> 0.81343886 | G25: ='Treasury DF Log Linear'!G68 -> 0.79871879 | H25: =F25-G25 -> 0.014720073 | I25: ='OIS DF Log Linear'!I85 -> 0.035910349 | J25: ='Treasury DF Log Linear'!I68 -> 0.039086321 | K25: =I25-J25 -> -0.0031759722 | L25: ='OIS DF Log Linear'!J85 -> 0.039836056 | M25: ='Treasury DF Log Linear'!K68 -> 0.045284697 | N25: =L25-M25 -> -0.0054486409
B26: 6 | C26: =$C$22 + (B26 - $B$22) * ($C$30 - $C$22) / ($B$30 - $B$22) -> 0.036445 | D26: 0.03935 | E26: =C26-D26 -> -0.002905 | F26: ='OIS DF Log Linear'!G86 -> 0.80537802 | G26: ='Treasury DF Log Linear'!G69 -> 0.78972735 | H26: =F26-G26 -> 0.015650672 | I26: ='OIS DF Log Linear'!I86 -> 0.03607392 | J26: ='Treasury DF Log Linear'!I69 -> 0.039344587 | K26: =I26-J26 -> -0.0032706667 | L26: ='OIS DF Log Linear'!J86 -> 0.039836056 | M26: ='Treasury DF Log Linear'!K69 -> 0.045284697 | N26: =L26-M26 -> -0.0054486409
B27: 6.25 | C27: =$C$22 + (B27 - $B$22) * ($C$30 - $C$22) / ($B$30 - $B$22) -> 0.03660875 | D27: 0.0395875 | E27: =C27-D27 -> -0.00297875 | F27: ='OIS DF Log Linear'!G87 -> 0.79739706 | G27: ='Treasury DF Log Linear'!G70 -> 0.78083713 | H27: =F27-G27 -> 0.01655993 | I27: ='OIS DF Log Linear'!I87 -> 0.036224406 | J27: ='Treasury DF Log Linear'!I70 -> 0.039582191 | K27: =I27-J27 -> -0.0033577857 | L27: ='OIS DF Log Linear'!J87 -> 0.039836056 | M27: ='Treasury DF Log Linear'!K70 -> 0.045284697 | N27: =L27-M27 -> -0.0054486409
B28: 6.5 | C28: =$C$22 + (B28 - $B$22) * ($C$30 - $C$22) / ($B$30 - $B$22) -> 0.0367725 | D28: 0.039825 | E28: =C28-D28 -> -0.0030525 | F28: ='OIS DF Log Linear'!G88 -> 0.78949518 | G28: ='Treasury DF Log Linear'!G71 -> 0.77204698 | H28: =F28-G28 -> 0.017448196 | I28: ='OIS DF Log Linear'!I88 -> 0.036363315 | J28: ='Treasury DF Log Linear'!I71 -> 0.039801518 | K28: =I28-J28 -> -0.0034382032 | L28: ='OIS DF Log Linear'!J88 -> 0.039836056 | M28: ='Treasury DF Log Linear'!K71 -> 0.045284697 | N28: =L28-M28 -> -0.0054486409
B29: 6.75 | C29: =$C$22 + (B29 - $B$22) * ($C$30 - $C$22) / ($B$30 - $B$22) -> 0.03693625 | D29: 0.0400625 | E29: =C29-D29 -> -0.00312625 | F29: ='OIS DF Log Linear'!G89 -> 0.78167161 | G29: ='Treasury DF Log Linear'!G72 -> 0.7633558 | H29: =F29-G29 -> 0.018315813 | I29: ='OIS DF Log Linear'!I89 -> 0.036491935 | J29: ='Treasury DF Log Linear'!I72 -> 0.040004599 | K29: =I29-J29 -> -0.0035126638 | L29: ='OIS DF Log Linear'!J89 -> 0.039836056 | M29: ='Treasury DF Log Linear'!K72 -> 0.045284697 | N29: =L29-M29 -> -0.0054486409
B30: 7 | C30: 0.0371 | D30: =VLOOKUP(B30,'Treasury DF Log Linear'!$G$5:$H$18,2,0) -> 0.0403 | E30: =C30-D30 -> -0.0032 | F30: ='OIS DF Log Linear'!G90 -> 0.77392557 | G30: ='Treasury DF Log Linear'!G73 -> 0.75476245 | H30: =F30-G30 -> 0.019163119 | I30: ='OIS DF Log Linear'!I90 -> 0.036611368 | J30: ='Treasury DF Log Linear'!I73 -> 0.040193174 | K30: =I30-J30 -> -0.0035818059 | L30: ='OIS DF Log Linear'!J90 -> 0.039836056 | M30: ='Treasury DF Log Linear'!K73 -> 0.045284697 | N30: =L30-M30 -> -0.0054486409
B31: 7.25 | C31: =$C$30 + (B31 - $B$30) * ($C$42 - $C$30) / ($B$42 - $B$30) -> 0.037244167 | D31: {=TREND(CHOOSE({1,2}, D30, D42), CHOOSE({1,2}, B30, B42), B31:B41)} -> 0.040475 | E31: =C31-D31 -> -0.0032308333 | F31: ='OIS DF Log Linear'!G91 -> 0.7656845 | G31: ='Treasury DF Log Linear'!G74 -> 0.74576815 | H31: =F31-G31 -> 0.019916344 | I31: ='OIS DF Log Linear'!I91 -> 0.036825528 | J31: ='Treasury DF Log Linear'!I74 -> 0.040460761 | K31: =I31-J31 -> -0.0036352326 | L31: ='OIS DF Log Linear'!J91 -> 0.042822008 | M31: ='Treasury DF Log Linear'!K74 -> 0.047953188 | N31: =L31-M31 -> -0.0051311795
B32: 7.5 | C32: =$C$30 + (B32 - $B$30) * ($C$42 - $C$30) / ($B$42 - $B$30) -> 0.037388333 | D32: 0.04065 | E32: =C32-D32 -> -0.0032616667 | F32: ='OIS DF Log Linear'!G92 -> 0.75753118 | G32: ='Treasury DF Log Linear'!G75 -> 0.73688104 | H32: =F32-G32 -> 0.02065014 | I32: ='OIS DF Log Linear'!I92 -> 0.037025411 | J32: ='Treasury DF Log Linear'!I75 -> 0.040710508 | K32: =I32-J32 -> -0.0036850975 | L32: ='OIS DF Log Linear'!J92 -> 0.042822008 | M32: ='Treasury DF Log Linear'!K75 -> 0.047953188 | N32: =L32-M32 -> -0.0051311795
B33: 7.75 | C33: =$C$30 + (B33 - $B$30) * ($C$42 - $C$30) / ($B$42 - $B$30) -> 0.0375325 | D33: 0.040825 | E33: =C33-D33 -> -0.0032925 | F33: ='OIS DF Log Linear'!G93 -> 0.74946468 | G33: ='Treasury DF Log Linear'!G76 -> 0.72809983 | H33: =F33-G33 -> 0.021364852 | I33: ='OIS DF Log Linear'!I93 -> 0.037212398 | J33: ='Treasury DF Log Linear'!I76 -> 0.040944143 | K33: =I33-J33 -> -0.0037317453 | L33: ='OIS DF Log Linear'!J93 -> 0.042822008 | M33: ='Treasury DF Log Linear'!K76 -> 0.047953188 | N33: =L33-M33 -> -0.0051311795
B34: 8 | C34: =$C$30 + (B34 - $B$30) * ($C$42 - $C$30) / ($B$42 - $B$30) -> 0.037676667 | D34: 0.041 | E34: =C34-D34 -> -0.0033233333 | F34: ='OIS DF Log Linear'!G94 -> 0.74148408 | G34: ='Treasury DF Log Linear'!G77 -> 0.71942327 | H34: =F34-G34 -> 0.022060815 | I34: ='OIS DF Log Linear'!I94 -> 0.037387698 | J34: ='Treasury DF Log Linear'!I77 -> 0.041163176 | K34: =I34-J34 -> -0.0037754776 | L34: ='OIS DF Log Linear'!J94 -> 0.042822008 | M34: ='Treasury DF Log Linear'!K77 -> 0.047953188 | N34: =L34-M34 -> -0.0051311795
B35: 8.25 | C35: =$C$30 + (B35 - $B$30) * ($C$42 - $C$30) / ($B$42 - $B$30) -> 0.037820833 | D35: 0.041175 | E35: =C35-D35 -> -0.0033541667 | F35: ='OIS DF Log Linear'!G95 -> 0.73358846 | G35: ='Treasury DF Log Linear'!G78 -> 0.7108501 | H35: =F35-G35 -> 0.022738362 | I35: ='OIS DF Log Linear'!I95 -> 0.037552374 | J35: ='Treasury DF Log Linear'!I78 -> 0.041368934 | K35: =I35-J35 -> -0.0038165595 | L35: ='OIS DF Log Linear'!J95 -> 0.042822008 | M35: ='Treasury DF Log Linear'!K78 -> 0.047953188 | N35: =L35-M35 -> -0.0051311795
B36: 8.5 | C36: =$C$30 + (B36 - $B$30) * ($C$42 - $C$30) / ($B$42 - $B$30) -> 0.037965 | D36: 0.04135 | E36: =C36-D36 -> -0.003385 | F36: ='OIS DF Log Linear'!G96 -> 0.72577692 | G36: ='Treasury DF Log Linear'!G79 -> 0.70237909 | H36: =F36-G36 -> 0.023397821 | I36: ='OIS DF Log Linear'!I96 -> 0.037707364 | J36: ='Treasury DF Log Linear'!I79 -> 0.041562588 | K36: =I36-J36 -> -0.0038552247 | L36: ='OIS DF Log Linear'!J96 -> 0.042822008 | M36: ='Treasury DF Log Linear'!K79 -> 0.047953188 | N36: =L36-M36 -> -0.0051311795
B37: 8.75 | C37: =$C$30 + (B37 - $B$30) * ($C$42 - $C$30) / ($B$42 - $B$30) -> 0.038109167 | D37: 0.041525 | E37: =C37-D37 -> -0.0034158333 | F37: ='OIS DF Log Linear'!G97 -> 0.71804855 | G37: ='Treasury DF Log Linear'!G80 -> 0.69400904 | H37: =F37-G37 -> 0.024039515 | I37: ='OIS DF Log Linear'!I97 -> 0.037853496 | J37: ='Treasury DF Log Linear'!I80 -> 0.041745177 | K37: =I37-J37 -> -0.0038916806 | L37: ='OIS DF Log Linear'!J97 -> 0.042822008 | M37: ='Treasury DF Log Linear'!K80 -> 0.047953188 | N37: =L37-M37 -> -0.0051311795
B38: 9 | C38: =$C$30 + (B38 - $B$30) * ($C$42 - $C$30) / ($B$42 - $B$30) -> 0.038253333 | D38: 0.0417 | E38: =C38-D38 -> -0.0034466667 | F38: ='OIS DF Log Linear'!G98 -> 0.71040248 | G38: ='Treasury DF Log Linear'!G81 -> 0.68573872 | H38: =F38-G38 -> 0.024663759 | I38: ='OIS DF Log Linear'!I98 -> 0.03799151 | J38: ='Treasury DF Log Linear'!I81 -> 0.041917622 | K38: =I38-J38 -> -0.0039261111 | L38: ='OIS DF Log Linear'!J98 -> 0.042822008 | M38: ='Treasury DF Log Linear'!K81 -> 0.047953188 | N38: =L38-M38 -> -0.0051311795
B39: 9.25 | C39: =$C$30 + (B39 - $B$30) * ($C$42 - $C$30) / ($B$42 - $B$30) -> 0.0383975 | D39: 0.041875 | E39: =C39-D39 -> -0.0034775 | F39: ='OIS DF Log Linear'!G99 -> 0.70283783 | G39: ='Treasury DF Log Linear'!G82 -> 0.67756696 | H39: =F39-G39 -> 0.025270866 | I39: ='OIS DF Log Linear'!I99 -> 0.038122064 | J39: ='Treasury DF Log Linear'!I82 -> 0.042080745 | K39: =I39-J39 -> -0.0039586805 | L39: ='OIS DF Log Linear'!J99 -> 0.042822008 | M39: ='Treasury DF Log Linear'!K82 -> 0.047953188 | N39: =L39-M39 -> -0.0051311795
B40: 9.5 | C40: =$C$30 + (B40 - $B$30) * ($C$42 - $C$30) / ($B$42 - $B$30) -> 0.038541667 | D40: 0.04205 | E40: =C40-D40 -> -0.0035083333 | F40: ='OIS DF Log Linear'!G100 -> 0.69535373 | G40: ='Treasury DF Log Linear'!G83 -> 0.66949259 | H40: =F40-G40 -> 0.025861145 | I40: ='OIS DF Log Linear'!I100 -> 0.038245747 | J40: ='Treasury DF Log Linear'!I83 -> 0.042235283 | K40: =I40-J40 -> -0.0039895358 | L40: ='OIS DF Log Linear'!J100 -> 0.042822008 | M40: ='Treasury DF Log Linear'!K83 -> 0.047953188 | N40: =L40-M40 -> -0.0051311795
B41: 9.75 | C41: =$C$30 + (B41 - $B$30) * ($C$42 - $C$30) / ($B$42 - $B$30) -> 0.038685833 | D41: 0.042225 | E41: =C41-D41 -> -0.0035391667 | F41: ='OIS DF Log Linear'!G101 -> 0.68794932 | G41: ='Treasury DF Log Linear'!G84 -> 0.66151443 | H41: =F41-G41 -> 0.026434897 | I41: ='OIS DF Log Linear'!I101 -> 0.038363087 | J41: ='Treasury DF Log Linear'!I84 -> 0.042381896 | K41: =I41-J41 -> -0.0040188087 | L41: ='OIS DF Log Linear'!J101 -> 0.042822008 | M41: ='Treasury DF Log Linear'!K84 -> 0.047953188 | N41: =L41-M41 -> -0.0051311795
...

Sheet SOFR Swap Bootstrap ( <1Y)
A2: x | B2: 1. Fixed SOFR Rates
C4: Refer Historical Data Sheet
A6: x | B6: 2. SR1 Jan: Stub Rates
F8: Value Date | G8: 46045 | H8: << 커브 산출 기준일 입력 (답안은 1월 23일 기준으로 제시될 예정입니다.)
F9: SR1 JAN Price | G9: 96.3275 | H9: << 커브 산출 기준일의 SR1 Jan Price 입력 (종가, CME 참고)
F10: Start of Month | G10: 46024 | H10: << 커브 산출 기준일이 포함된 월의 시작일
F11: End of Month | G11: 46045 | H11: << 커브 산출 기준일이 포함된 월의 마지막 날
F13: Whole Working Days | G13: =NETWORKDAYS(G10,G11) -> 16 | H13: << 해당월의 영업일
F14: Passed Working Days | G14: =NETWORKDAYS(G10,G8-1) -> 15 | H14: << 평가일 기준 경과영업일: SR1은 해당월 실현되는 SOFR의 기간별 가중합으로 주어지기 때문
F15: Remained Working Days | G15: =G13-G14 -> 1 | H15: << 잔여 SOFR 산출일수
F17: SR1 Implied Rate | G17: =(100 - G9) / 100 -> 0.036725 | H17: << SR1의 호가법에 따른 Spot 금리
F18: Realized Avg | G18: =SUMPRODUCT('Market Data'!B3:B17, 'Market Data'!C3:C17) / SUM('Market Data'!C3:C17) / 100 -> 0.036628571 | H18: << 기간별 가중합을 위함 | J18: 만약 AVERAGE 함수를 쓰면, 엑셀은 금요일(3일 치 영향력)과 월요일(1일 치 영향력)을 똑같은 '데이터 1개'로 취급해버림(산술평균). 하지만 영업일을 생각했을때 토요일, 일요일은 쉬기 때문에 금요일 금리가 3일동안 유지됨으로 3일 동안 유지된 금리에 더 큰 무게(가중치)를 둬야 정확함
F19: Forward Rate | G19: =(G17 * G13 - G18 * G14) / G15 -> 0.038171429 | H19: << 그럼 평가기준일 - 월말까지의 금리를 산출할 수 있음
F20: Stub DF(to Jan 31) | G20: =1 / (1 + (G19 * 8 / 360)) -> 0.99915246 | H20: << 위 논리에 기초하여 월말까지의 DF를 산출
A22: x | B22: 3. SR1 FEB&MAR
F24: SR1 FEB Price | G24: 96.335
F25: SR1 MAR Pice | G25: 96.345
F26: Mar IMM Date | G26: 46099
C28: 3.1. 2월 말일 DF 구하기
F30: Feb Rate | G30: =(100 - G24) / 100 -> 0.03665
F31: Feb Days | G31: 28
F32: Feb End DF | G32: =G20 * (1 / (1 + (G30 * G31 / 360))) -> 0.99631242
C34: 3.2. 3월 IMM DF 구하기
D35: >> 월초와 월말 금리가 다를 수 있지만, 선물 가격 하나만 가지고는 알 방법이 없음
D36: >> 금리가 한 달 내내 균등하다(Uniform)고 가정하고 18일치만 뚝 떼어서적용
F38: Mar Rate | G38: =(100 - G25) / 100 -> 0.03655
F39: Bridge Days | G39: =G26-DATE(2026,2,28) -> 18
F40: Mar IMM DF | G40: =G32 * (1 / (1 + (G38 * G39 / 360))) -> 0.99449498
A42: x | B42: 4. SR3
F43: SR3 Mar Price | G43: 96.37
F44: SR3 Jun Price | G44: 96.525
F45: SR3 Sep Price | G45: 96.685
F46: Jun IMM Date | G46: 46190
F47: Sep IMM Date | G47: 46281
F48: Dec IMM Date | G48: 46372
C50: 4.1. SR3 Mar 구간(3/18-6/17)
F52: Mar-Jun Rate | G52: =(100 - G43) / 100 -> 0.0363
F53: Days | G53: =G46-G26 -> 91
F54: Jun IMM DF | G54: =G40 * (1 / (1 + (G52 * G53 / 360))) -> 0.98545263
C56: 4.2. SR3 Jun 구간(6/17-9/16)
...

Sheet OIS DF Log Linear
A2: x | B2: 1. Swap Rates on VD
C3: >> Annual Payment OIS | G3: << Chartham에서 가져온 OIS Data 기준
F5: Value Date | G5: ='SOFR Swap Bootstrap ( <1Y)'!G8 -> 46045
F7: Year | G7: Swap Rates | H7: << Market Data 시트 참조
F8: 1 | H8: 0.03524
F9: 2 | H9: 0.03437
F10: 3 | H10: 0.03466
F11: 5 | H11: 0.03579
F12: 7 | H12: 0.0371
F13: 10 | H13: 0.03883
F14: 15 | H14: 0.0411
F15: 30 | H15: 0.04207
A17: x | B17: 2. Calculate 1Y DF
F19: Year Fraction | G19: DF
F20: 0.25 | G20: ='SOFR Swap Bootstrap ( <1Y)'!H93 -> 0.99090791
F21: 0.5 | G21: ='SOFR Swap Bootstrap ( <1Y)'!H94 -> 0.98204903
F22: 0.75 | G22: ='SOFR Swap Bootstrap ( <1Y)'!H95 -> 0.97356296
F23: 1 | G23: =1 / (1 + H8) -> 0.96595958
A25: x | B25: 3. Construct Annual DF Curve
F27: Year Fraction | G27: DF | H27: LN(DF) | I27: Thoeritic Swap Rate | J27: Market Swap Rate | K27: Error | L27: Spot Curve | M27: Forward Curve(F(t,t+1))
F28: {=_xlfn.SEQUENCE(30,1,1,1)} -> 1 | G28: =G23 -> 0.96595958 | H28: =LN(G28) -> -0.034633284 | K28: =I28-J28 -> 0 | L28: =-H28/F28 -> 0.034633284 | M28: =L28 -> 0.034633284
F29: 2 | G29: =(1 - H9 * G28) / (1 + H9) -> 0.93467518 | H29: =LN(G29) -> -0.067556208 | K29: =I29-J29 -> 0 | L29: =-H29/F29 -> 0.033778104 | M29: =(H28 - H29) / (F29 - F28) -> 0.032922924
F30: 3 | G30: =(1 - H10 * (G28 + G29)) / (1 + H10) -> 0.90283185 | H30: =LN(G30) -> -0.10221896 | K30: =I30-J30 -> 0 | L30: =-H30/F30 -> 0.034072986 | M30: =(H29 - H30) / (F30 - F29) -> 0.034662751
F31: 4 | G31: =$G$30*(G$32/$G$30)^((F31-$F$30)/($F$32-$F$30)) -> 0.86986851 | H31: =LN(G31) -> -0.13941321 | L31: =-H31/F31 -> 0.034853303 | M31: =(H30 - H31) / (F31 - F30) -> 0.037194253
F32: 5 | G32: 0.83810871 | H32: =LN(G32) -> -0.17660746 | I32: =(1-G32)/SUM($G$28:G32) -> 0.035884586 | J32: =$H$11 -> 0.03579 | K32: =I32-J32 -> 9.4585662e-05 | L32: =-H32/F32 -> 0.035321493 | M32: =(H31 - H32) / (F32 - F31) -> 0.037194253
F33: 6 | G33: =$G$32*(G$34/$G$32)^((F33-$F$32)/($F$34-$F$32)) -> 0.80537802 | H33: =LN(G33) -> -0.21644352 | L33: =-H33/F33 -> 0.03607392 | M33: =(H32 - H33) / (F33 - F32) -> 0.039836056
F34: 7 | G34: 0.77392557 | H34: =LN(G34) -> -0.25627958 | I34: =(1-G34)/SUM($G$28:G34) -> 0.037117683 | J34: 0.0371 | K34: =I34-J34 -> 1.7683232e-05 | L34: =-H34/F34 -> 0.036611368 | M34: =(H33 - H34) / (F34 - F33) -> 0.039836056
F35: 8 | G35: =$G$34*(G$37/$G$34)^((F35-$F$34)/($F$37-$F$34)) -> 0.74148408 | H35: =LN(G35) -> -0.29910159 | L35: =-H35/F35 -> 0.037387698 | M35: =(H34 - H35) / (F35 - F34) -> 0.042822008
F36: 9 | G36: =$G$34*(G$37/$G$34)^((F36-$F$34)/($F$37-$F$34)) -> 0.71040248 | H36: =LN(G36) -> -0.34192359 | L36: =-H36/F36 -> 0.03799151 | M36: =(H35 - H36) / (F36 - F35) -> 0.042822008
F37: 10 | G37: 0.68062376 | H37: =LN(G37) -> -0.3847456 | I37: =(1-G37)/SUM($G$28:G37) -> 0.038838164 | J37: 0.03883 | K37: =I37-J37 -> 8.1644598e-06 | L37: =-H37/F37 -> 0.03847456 | M37: =(H36 - H37) / (F37 - F36) -> 0.042822008
F38: 11 | G38: =$G$37*(G$42/$G$37)^((F38-$F$37)/($F$42-$F$37)) -> 0.64960471 | H38: =LN(G38) -> -0.43139124 | L38: =-H38/F38 -> 0.039217385 | M38: =(H37 - H38) / (F38 - F37) -> 0.046645635
F39: 12 | G39: =$G$37*(G$42/$G$37)^((F39-$F$37)/($F$42-$F$37)) -> 0.61999934 | H39: =LN(G39) -> -0.47803687 | L39: =-H39/F39 -> 0.039836406 | M39: =(H38 - H39) / (F39 - F38) -> 0.046645635
F40: 13 | G40: =$G$37*(G$42/$G$37)^((F40-$F$37)/($F$42-$F$37)) -> 0.59174321 | H40: =LN(G40) -> -0.52468251 | L40: =-H40/F40 -> 0.040360193 | M40: =(H39 - H40) / (F40 - F39) -> 0.046645635
F41: 14 | G41: =$G$37*(G$42/$G$37)^((F41-$F$37)/($F$42-$F$37)) -> 0.56477484 | H41: =LN(G41) -> -0.57132814 | L41: =-H41/F41 -> 0.040809153 | M41: =(H40 - H41) / (F41 - F40) -> 0.046645635
F42: 15 | G42: 0.53903554 | H42: =LN(G42) -> -0.61797378 | I42: =(1-G42)/SUM($G$28:G42) -> 0.041200156 | J42: 0.0411 | K42: =I42-J42 -> 0.00010015615 | L42: =-H42/F42 -> 0.041198252 | M42: =(H41 - H42) / (F42 - F41) -> 0.046645635
F43: 16 | G43: =$G$42*(G$57/$G$42)^((F43-$F$42)/($F$57-$F$42)) -> 0.51563616 | H43: =LN(G43) -> -0.66235389 | L43: =-H43/F43 -> 0.041397118 | M43: =(H42 - H43) / (F43 - F42) -> 0.044380112
F44: 17 | G44: =$G$42*(G$57/$G$42)^((F44-$F$42)/($F$57-$F$42)) -> 0.49325253 | H44: =LN(G44) -> -0.706734 | L44: =-H44/F44 -> 0.041572588 | M44: =(H43 - H44) / (F44 - F43) -> 0.044380112
F45: 18 | G45: =$G$42*(G$57/$G$42)^((F45-$F$42)/($F$57-$F$42)) -> 0.47184058 | H45: =LN(G45) -> -0.75111411 | L45: =-H45/F45 -> 0.041728562 | M45: =(H44 - H45) / (F45 - F44) -> 0.044380112
F46: 19 | G46: =$G$42*(G$57/$G$42)^((F46-$F$42)/($F$57-$F$42)) -> 0.45135811 | H46: =LN(G46) -> -0.79549422 | L46: =-H46/F46 -> 0.041868117 | M46: =(H45 - H46) / (F46 - F45) -> 0.044380112
F47: 20 | G47: =$G$42*(G$57/$G$42)^((F47-$F$42)/($F$57-$F$42)) -> 0.43176478 | H47: =LN(G47) -> -0.83987434 | L47: =-H47/F47 -> 0.041993717 | M47: =(H46 - H47) / (F47 - F46) -> 0.044380112
...

Sheet Market Data
A1: Historical SOFR | E1: SR1 (CME / VD: 2026.1.23) | H1: * Close Price
A2: Date | B2: SOFR(%) | C2: Days | E2: MONTH/YEAR | F2: PRICE
A3: 46024 | B3: 3.75 | C3: =A4-A3 -> 3 | E3: JAN | F3: 96.3275
A4: 46027 | B4: 3.7 | C4: =A5-A4 -> 1 | E4: FEB | F4: 96.335
A5: 46028 | B5: 3.66 | C5: =A6-A5 -> 1 | E5: MAR | F5: 96.345
A6: 46029 | B6: 3.65 | C6: =A7-A6 -> 1
A7: 46030 | B7: 3.64 | C7: =A8-A7 -> 1 | E7: SR3 (CME / VD: 2026.1.23)
A8: 46031 | B8: 3.64 | C8: =A9-A8 -> 3 | E8: MAR | F8: 96.37
A9: 46034 | B9: 3.64 | C9: =A10-A9 -> 1 | E9: JUN | F9: 96.525
A10: 46035 | B10: 3.65 | C10: =A11-A10 -> 1 | E10: SEP | F10: 96.685
A11: 46036 | B11: 3.64 | C11: =A12-A11 -> 1
A12: 46037 | B12: 3.66 | C12: =A13-A12 -> 1 | E12: SOFR OIS Swap Rate (Chatham / VD: 2026.1.23)
A13: 46038 | B13: 3.65 | C13: =A14-A13 -> 4 | E13: 1Y | F13: 0.03524
A14: 46042 | B14: 3.64 | C14: =A15-A14 -> 1 | E14: 2Y | F14: 0.03437
A15: 46043 | B15: 3.63 | C15: =A16-A15 -> 1 | E15: 3Y | F15: 0.03466
A16: 46044 | B16: 3.64 | C16: =A17-A16 -> 1 | E16: 5Y | F16: 0.03579
A17: 46045 | B17: 3.65 | E17: 7Y | F17: 0.0371
E18: 10Y | F18: 0.03883
E19: 15Y | F19: 0.0411
E20: 30Y | F20: 0.04207

Sheet Treasury DF Log Linear
A2: x | B2: 1. Input
C3: Treasury Par Yield Curve Rates
F4: Tenor | G4: Year Fraction | H4: Value | I4: Effective Date | J4: 01/23/2026
F5: 1 Mo | G5: =1/12 -> 0.083333333 | H5: 0.0378
F6: 1.5 Mo | G6: =1.5/12 -> 0.125 | H6: 0.0371
F7: 2 Mo | G7: =2/12 -> 0.16666667 | H7: 0.0372
F8: 3 Mo | G8: =3/12 -> 0.25 | H8: 0.037
F9: 4 Mo | G9: =4/12 -> 0.33333333 | H9: 0.0367
F10: 6 Mo | G10: =6/12 -> 0.5 | H10: 0.0361
F11: 1 Yr | G11: 1 | H11: 0.0353
F12: 2 Yr | G12: 2 | H12: 0.036
F13: 3 Yr | G13: 3 | H13: 0.0367
F14: 5 Yr | G14: 5 | H14: 0.0384
F15: 7 Yr | G15: 7 | H15: 0.0403
F16: 10 Yr | G16: 10 | H16: 0.0424
F17: 20 Yr | G17: 20 | H17: 0.0478
F18: 30 Yr | G18: 30 | H18: 0.0482
O19: * 계단식 Forward Rate
O20: > 해당 구간 수준의 선도 금리가 다음 만기까지 쭉 유지된다고 봄
A21: x | B21: 2. (primary) Discount Factor (6m)
F22: T | G22: Discount Factor | H22: Par | I22: Spot(Continuously Compounded) | J22: Spot(Semi Annually Compounded) | K22: Forward Rate | L22: Price | M22: Error
F23: 0.5 | G23: =1/(1+VLOOKUP(F23,$G$5:$H$18,2,0)*F23) -> 0.98227003 | H23: =_xlfn.XLOOKUP(F23,$G$5:$G$18,$H$5:$H$18,"",0) -> 0.0361 | I23: =-LN(G23)/F23 -> 0.035778066 | J23: =2*(G23^(-1/(2*F23))-1) -> 0.0361 | K23: =I23 -> 0.035778066
F24: 1 | G24: 0.96561975 | H24: =_xlfn.XLOOKUP(F24,$G$5:$G$18,$H$5:$H$18,"",0) -> 0.0353 | I24: =-LN(G24)/F24 -> 0.03498516 | J24: =2*(G24^(-1/(2*F24))-1) -> 0.035292943 | K24: =(I24*F24-I23*F23)/(F24-F23) -> 0.034192255 | L24: =100*H24/2*SUM($G$23:G24)+100*G24 -> 100 | M24: =L24-100 -> 0
F25: 1.5 | G25: =EXP((F26-F25)/(F26-F24)*LN(G24)+(F25-F24)/(F26-F24)*LN(G26)) -> 0.94820802 | H25: =AVERAGE(H24,H26) -> 0.03565 | I25: =-LN(G25)/F25 -> 0.035454248 | J25: =2*(G25^(-1/(2*F25))-1) -> 0.035770364 | K25: =(I25*F25-I24*F24)/(F25-F24) -> 0.036392422
F26: 2 | G26: 0.93111026 | H26: =_xlfn.XLOOKUP(F26,$G$5:$G$18,$H$5:$H$18,"",0) -> 0.036 | I26: =-LN(G26)/F26 -> 0.035688791 | J26: =2*(G26^(-1/(2*F26))-1) -> 0.036009116 | K26: =(I26*F26-I25*F25)/(F26-F25) -> 0.036392422 | L26: =100*H26/2*SUM($G$23:G26)+100*G26 -> 100 | M26: =L26-100 -> -1.9468871e-12
F27: 2.5 | G27: =EXP((F28-F27)/(F28-F26)*LN(G26)+(F27-F26)/(F28-F26)*LN(G28)) -> 0.91366835 | H27: =AVERAGE(H28,H26) -> 0.03635 | I27: =-LN(G27)/F27 -> 0.036115053 | J27: =2*(G27^(-1/(2*F27))-1) -> 0.036443099 | K27: =(I27*F27-I26*F26)/(F27-F26) -> 0.0378201
F28: 3 | G28: 0.89655317 | H28: =_xlfn.XLOOKUP(F28,$G$5:$G$18,$H$5:$H$18,"",0) -> 0.0367 | I28: =-LN(G28)/F28 -> 0.036399227 | J28: =2*(G28^(-1/(2*F28))-1) -> 0.036732472 | K28: =(I28*F28-I27*F27)/(F28-F27) -> 0.0378201 | L28: =100*H28/2*SUM($G$23:G28)+100*G28 -> 100 | M28: =L28-100 -> 0
F29: 3.5 | G29: =EXP(($F$32-F29)/($F$32-$F$28)*LN($G$28)+(F29-$F$28)/($F$32-$F$28)*LN($G$32)) -> 0.87845204 | H29: =($F$32-F29)/($F$32-$F$28)*$H$28+(F29-$F$28)/($F$32-$F$28)*$H$32 -> 0.037125 | I29: =-LN(G29)/F29 -> 0.037026848 | J29: =2*(G29^(-1/(2*F29))-1) -> 0.03737172 | K29: =(I29*F29-I28*F28)/(F29-F28) -> 0.040792571
F30: 4 | G30: =EXP(($F$32-F30)/($F$32-$F$28)*LN($G$28)+(F30-$F$28)/($F$32-$F$28)*LN($G$32)) -> 0.86071637 | H30: =($F$32-F30)/($F$32-$F$28)*$H$28+(F30-$F$28)/($F$32-$F$28)*$H$32 -> 0.03755 | I30: =-LN(G30)/F30 -> 0.037497563 | J30: =2*(G30^(-1/(2*F30))-1) -> 0.037851287 | K30: =(I30*F30-I29*F29)/(F30-F29) -> 0.040792571
F31: 4.5 | G31: =EXP(($F$32-F31)/($F$32-$F$28)*LN($G$28)+(F31-$F$28)/($F$32-$F$28)*LN($G$32)) -> 0.84333877 | H31: =($F$32-F31)/($F$32-$F$28)*$H$28+(F31-$F$28)/($F$32-$F$28)*$H$32 -> 0.037975 | I31: =-LN(G31)/F31 -> 0.037863675 | J31: =2*(G31^(-1/(2*F31))-1) -> 0.038224362 | K31: =(I31*F31-I30*F30)/(F31-F30) -> 0.040792571
F32: 5 | G32: 0.82631202 | H32: =_xlfn.XLOOKUP(F32,$G$5:$G$18,$H$5:$H$18,"",0) -> 0.0384 | I32: =-LN(G32)/F32 -> 0.038156565 | J32: =2*(G32^(-1/(2*F32))-1) -> 0.038522871 | K32: =(I32*F32-I31*F31)/(F32-F31) -> 0.040792571 | L32: =100*H32/2*SUM($G$23:G32)+100*G32 -> 100 | M32: =L32-100 -> -3.3401193e-10
F33: 5.5 | G33: =EXP(($F$36-F33)/($F$36-$F$32)*LN($G$32)+(F33-$F$32)/($F$36-$F$32)*LN($G$36)) -> 0.8078126 | H33: =($F$36-F33)/($F$36-$F$32)*$H$32+(F33-$F$32)/($F$36-$F$32)*$H$36 -> 0.038875 | I33: =-LN(G33)/F33 -> 0.038804577 | J33: =2*(G33^(-1/(2*F33))-1) -> 0.039183472 | K33: =(I33*F33-I32*F32)/(F33-F32) -> 0.045284697
F34: 6 | G34: =EXP(($F$36-F34)/($F$36-$F$32)*LN($G$32)+(F34-$F$32)/($F$36-$F$32)*LN($G$36)) -> 0.78972735 | H34: =($F$36-F34)/($F$36-$F$32)*$H$32+(F34-$F$32)/($F$36-$F$32)*$H$36 -> 0.03935 | I34: =-LN(G34)/F34 -> 0.039344587 | J34: =2*(G34^(-1/(2*F34))-1) -> 0.039734136 | K34: =(I34*F34-I33*F33)/(F34-F33) -> 0.045284697
F35: 6.5 | G35: =EXP(($F$36-F35)/($F$36-$F$32)*LN($G$32)+(F35-$F$32)/($F$36-$F$32)*LN($G$36)) -> 0.77204698 | H35: =($F$36-F35)/($F$36-$F$32)*$H$32+(F35-$F$32)/($F$36-$F$32)*$H$36 -> 0.039825 | I35: =-LN(G35)/F35 -> 0.039801518 | J35: =2*(G35^(-1/(2*F35))-1) -> 0.040200199 | K35: =(I35*F35-I34*F34)/(F35-F34) -> 0.045284697
F36: 7 | G36: 0.75476245 | H36: =_xlfn.XLOOKUP(F36,$G$5:$G$18,$H$5:$H$18,"",0) -> 0.0403 | I36: =-LN(G36)/F36 -> 0.040193174 | J36: =2*(G36^(-1/(2*F36))-1) -> 0.040599766 | K36: =(I36*F36-I35*F35)/(F36-F35) -> 0.045284697 | L36: =100*H36/2*SUM($G$23:G36)+100*G36 -> 100 | M36: =L36-100 -> -1.4418333e-10
F37: 7.5 | G37: =EXP(($F$42-F37)/($F$42-$F$36)*LN($G$36)+(F37-$F$36)/($F$42-$F$36)*LN($G$42)) -> 0.73688104 | H37: =($F$42-F37)/($F$42-$F$36)*$H$36+(F37-$F$36)/($F$42-$F$36)*$H$42 -> 0.04065 | I37: =-LN(G37)/F37 -> 0.040710508 | J37: =2*(G37^(-1/(2*F37))-1) -> 0.04112767 | K37: =(I37*F37-I36*F36)/(F37-F36) -> 0.047953188
F38: 8 | G38: =EXP(($F$42-F38)/($F$42-$F$36)*LN($G$36)+(F38-$F$36)/($F$42-$F$36)*LN($G$42)) -> 0.71942327 | H38: =($F$42-F38)/($F$42-$F$36)*$H$36+(F38-$F$36)/($F$42-$F$36)*$H$42 -> 0.041 | I38: =-LN(G38)/F38 -> 0.041163176 | J38: =2*(G38^(-1/(2*F38))-1) -> 0.041589699 | K38: =(I38*F38-I37*F37)/(F38-F37) -> 0.047953188
F39: 8.5 | G39: =EXP(($F$42-F39)/($F$42-$F$36)*LN($G$36)+(F39-$F$36)/($F$42-$F$36)*LN($G$42)) -> 0.70237909 | H39: =($F$42-F39)/($F$42-$F$36)*$H$36+(F39-$F$36)/($F$42-$F$36)*$H$42 -> 0.04135 | I39: =-LN(G39)/F39 -> 0.041562588 | J39: =2*(G39^(-1/(2*F39))-1) -> 0.041997458 | K39: =(I39*F39-I38*F38)/(F39-F38) -> 0.047953188
F40: 9 | G40: =EXP(($F$42-F40)/($F$42-$F$36)*LN($G$36)+(F40-$F$36)/($F$42-$F$36)*LN($G$42)) -> 0.68573872 | H40: =($F$42-F40)/($F$42-$F$36)*$H$36+(F40-$F$36)/($F$42-$F$36)*$H$42 -> 0.0417 | I40: =-LN(G40)/F40 -> 0.041917622 | J40: =2*(G40^(-1/(2*F40))-1) -> 0.042359978 | K40: =(I40*F40-I39*F39)/(F40-F39) -> 0.047953188
F41: 9.5 | G41: =EXP(($F$42-F41)/($F$42-$F$36)*LN($G$36)+(F41-$F$36)/($F$42-$F$36)*LN($G$42)) -> 0.66949259 | H41: =($F$42-F41)/($F$42-$F$36)*$H$36+(F41-$F$36)/($F$42-$F$36)*$H$42 -> 0.04205 | I41: =-LN(G41)/F41 -> 0.042235283 | J41: =2*(G41^(-1/(2*F41))-1) -> 0.042684394 | K41: =(I41*F41-I40*F40)/(F41-F40) -> 0.047953188
...
