Workbook

Sheet Sheet1
A1: IRS tenor | C1: http://www.smbs.biz/Exchange/IRS.jsp | G1: 3개월=CD
A2: 0.25 | B2: 2.8 | D2: 1. 위의 링크와 CD금리를 통해 앞의 tenor를 채워주세요
A3: 1 | B3: 2.9175 | D3: > 2월 26일 기준 금리로 답안이 게시될 예정입니다.
A4: 2 | B4: 3.0875 | T4: S
A5: 3 | B5: 3.2 | D5: 2. 10년 만기 fixed rate 3.7%를 지급하는 IRS가 있다고 할때 해당 상품의 값을 구해주세요.
A6: 4 | B6: 3.27 | D6: > Bootstrap sheet에서 각 leg의 CashFlow를 구한 후 차이를 구해주시면 됩니다!
A7: 5 | B7: 3.325 | D7: Notional | E7: 10000000000
A8: 7 | B8: 3.4025 | D8: Value | E8: =(Bootstrap!N43-Bootstrap!M43)*E7 -> -1.9878791e+08
A9: 10 | B9: 3.465
A10: 12 | B10: 3.4875
A11: 15 | B11: 3.4975
A12: 20 | B12: 3.4125
B13: 1bp | C13: 0.01 | D13: > 1bp만큼 원래 값에서 전체 tenor의 금리 or key rate을 변화시켜주세요
A14: IRS parallel shift | D14: 1Y change | G14: 2Y change | J14: 3Y change | M14: 4Y change | P14: 5Y change | S14: 7Y change | V14: 10Y change
A15: 0.25 | B15: =B2+$C$13 -> 2.81 | D15: 0.25 | E15: =B2 -> 2.8 | G15: 0.25 | H15: =B2 -> 2.8 | J15: 0.25 | K15: =B2 -> 2.8 | M15: 0.25 | N15: =B2 -> 2.8 | P15: 0.25 | Q15: =B2 -> 2.8 | S15: 0.25 | T15: =B2 -> 2.8 | V15: 0.25 | W15: =B2 -> 2.8
A16: 1 | B16: =B3+$C$13 -> 2.9275 | D16: 1 | E16: =B3+C13 -> 2.9275 | G16: 1 | H16: =B3 -> 2.9175 | J16: 1 | K16: =B3 -> 2.9175 | M16: 1 | N16: =B3 -> 2.9175 | P16: 1 | Q16: =B3 -> 2.9175 | S16: 1 | T16: =B3 -> 2.9175 | V16: 1 | W16: =B3 -> 2.9175
A17: 2 | B17: =B4+$C$13 -> 3.0975 | D17: 2 | E17: =B4 -> 3.0875 | G17: 2 | H17: =B4+C13 -> 3.0975 | J17: 2 | K17: =B4 -> 3.0875 | M17: 2 | N17: =B4 -> 3.0875 | P17: 2 | Q17: =B4 -> 3.0875 | S17: 2 | T17: =B4 -> 3.0875 | V17: 2 | W17: =B4 -> 3.0875
A18: 3 | B18: =B5+$C$13 -> 3.21 | D18: 3 | E18: =B5 -> 3.2 | G18: 3 | H18: =B5 -> 3.2 | J18: 3 | K18: =B5+C13 -> 3.21 | M18: 3 | N18: =B5 -> 3.2 | P18: 3 | Q18: =B5 -> 3.2 | S18: 3 | T18: =B5 -> 3.2 | V18: 3 | W18: =B5 -> 3.2
A19: 4 | B19: =B6+$C$13 -> 3.28 | D19: 4 | E19: =B6 -> 3.27 | G19: 4 | H19: =B6 -> 3.27 | J19: 4 | K19: =B6 -> 3.27 | M19: 4 | N19: =B6+C13 -> 3.28 | P19: 4 | Q19: =B6 -> 3.27 | S19: 4 | T19: =B6 -> 3.27 | V19: 4 | W19: =B6 -> 3.27
A20: 5 | B20: =B7+$C$13 -> 3.335 | D20: 5 | E20: =B7 -> 3.325 | G20: 5 | H20: =B7 -> 3.325 | J20: 5 | K20: =B7 -> 3.325 | M20: 5 | N20: =B7 -> 3.325 | P20: 5 | Q20: =B7+C13 -> 3.335 | S20: 5 | T20: =B7 -> 3.325 | V20: 5 | W20: =B7 -> 3.325
A21: 7 | B21: =B8+$C$13 -> 3.4125 | D21: 7 | E21: =B8 -> 3.4025 | G21: 7 | H21: =B8 -> 3.4025 | J21: 7 | K21: =B8 -> 3.4025 | M21: 7 | N21: =B8 -> 3.4025 | P21: 7 | Q21: =B8 -> 3.4025 | S21: 7 | T21: =B8+C13 -> 3.4125 | V21: 7 | W21: =B8 -> 3.4025
A22: 10 | B22: =B9+$C$13 -> 3.475 | D22: 10 | E22: =B9 -> 3.465 | G22: 10 | H22: =B9 -> 3.465 | J22: 10 | K22: =B9 -> 3.465 | M22: 10 | N22: =B9 -> 3.465 | P22: 10 | Q22: =B9 -> 3.465 | S22: 10 | T22: =B9 -> 3.465 | V22: 10 | W22: =B9+C13 -> 3.475
A23: 12 | B23: =B10+$C$13 -> 3.4975 | D23: 12 | E23: =B10 -> 3.4875 | G23: 12 | H23: =B10 -> 3.4875 | J23: 12 | K23: =B10 -> 3.4875 | M23: 12 | N23: =B10 -> 3.4875 | P23: 12 | Q23: =B10 -> 3.4875 | S23: 12 | T23: =B10 -> 3.4875 | V23: 12 | W23: =B10 -> 3.4875
A24: 15 | B24: =B11+$C$13 -> 3.5075 | D24: 15 | E24: =B11 -> 3.4975 | G24: 15 | H24: =B11 -> 3.4975 | J24: 15 | K24: =B11 -> 3.4975 | M24: 15 | N24: =B11 -> 3.4975 | P24: 15 | Q24: =B11 -> 3.4975 | S24: 15 | T24: =B11 -> 3.4975 | V24: 15 | W24: =B11 -> 3.4975
A25: 20 | B25: =B12+$C$13 -> 3.4225 | D25: 20 | E25: =B12 -> 3.4125 | G25: 20 | H25: =B12 -> 3.4125 | J25: 20 | K25: =B12 -> 3.4125 | M25: 20 | N25: =B12 -> 3.4125 | P25: 20 | Q25: =B12 -> 3.4125 | S25: 20 | T25: =B12 -> 3.4125 | V25: 20 | W25: =B12 -> 3.4125
A27: value change | B27: =Duration!J43-Duration!K43 -> -0.00084549912 | E27: ='1Y duration'!J43-'1Y duration'!K43 -> 4.9960036e-16 | H27: ='2Y duration'!J43-'2Y duration'!K43 -> 0 | K27: ='3Y duration'!J43-'3Y duration'!K43 -> -7.2164497e-16 | N27: ='4Y duration'!J43-'4Y duration'!K43 -> 0 | Q27: ='5Y duration'!J43-'5Y duration'!K43 -> 0 | T27: ='7Y duration'!J43-'7Y duration'!K43 -> 0 | W27: ='10Y duration'!J43-'10Y duration'!K43 -> -0.00084577167
A28: Duration | B28: =-B27/0.0001 -> 8.4549912
A29: Notional | B29: 1000000
A33: 8Y swap rate | C33: =(1-Bootstrap!B34) / SUM(Bootstrap!B3:B34)/ 0.25 -> 0.034285954
A34: value change | B34: =Duration!N35-Duration!O35 -> -0.00069968315 | E34: ='1Y duration'!N35-'1Y duration'!O35 -> -3.9898984e-09 | H34: ='2Y duration'!N35-'2Y duration'!O35 -> -9.2413309e-09 | K34: ='3Y duration'!N35-'3Y duration'!O35 -> -1.4074049e-08 | N34: ='4Y duration'!N35-'4Y duration'!O35 -> -1.9060761e-08 | Q34: ='5Y duration'!N35-'5Y duration'!O35 -> -3.6484017e-08 | T34: ='7Y duration'!N35-'7Y duration'!O35 -> -0.00040721391 | W34: ='10Y duration'!N35-'10Y duration'!O35 -> -0.00029273443
A35: Duration | B35: =-B34/0.0001 -> 6.9968315 | E35: =E34/$B$34 -> 5.702436e-06 | H35: =H34/$B$34 -> 1.320788e-05 | K35: =K34/$B$34 -> 2.0114889e-05 | N35: =N34/$B$34 -> 2.7241989e-05 | Q35: =Q34/$B$34 -> 5.2143627e-05 | T35: =T34/$B$34 -> 0.58199759 | W35: =W34/$B$34 -> 0.41838141
A37: > 아래의 CF를 확인하고 왜 이런 결과가 나왔을지에 대해 생각해보시면 좋겠습니다!
A38: 10Y 기준 CF 확인 | E38: 1Y | F38: difference | H38: 2Y | I38: difference | K38: 3Y | L38: difference | N38: 4Y | O38: difference | Q38: 5Y | R38: difference | T38: 7Y | U38: difference | W38: 10Y | X38: difference
B39: fixed | C39: floating | E39: fixed | F39: floating | H39: fixed | I39: floating | K39: fixed | L39: floating | N39: fixed | O39: floating | Q39: fixed | R39: floating | T39: fixed | U39: floating | W39: fixed | X39: floating
A40: {=_xlfn.SEQUENCE(40,,0.25,0.25)} -> 0.25 | B40: =Bootstrap!J3 *$B$29 -> 8602.284 | C40: =Bootstrap!K3*$B$29 -> 6951.3406 | E40: ='1Y duration'!J3*$B$29 -> 8602.284 | F40: ='1Y duration'!K3*$B$29 -> 6951.3406 | H40: ='2Y duration'!J3*$B$29 -> 8602.284 | I40: ='2Y duration'!K3*$B$29 -> 6951.3406 | K40: ='3Y duration'!J3*$B$29 -> 8602.284 | L40: ='3Y duration'!K3*$B$29 -> 6951.3406 | N40: ='4Y duration'!J3*$B$29 -> 8602.284 | O40: ='4Y duration'!K3*$B$29 -> 6951.3406 | Q40: ='5Y duration'!J3*$B$29 -> 8602.284 | R40: ='5Y duration'!K3*$B$29 -> 6951.3406 | T40: ='7Y duration'!J3*$B$29 -> 8602.284 | U40: ='7Y duration'!K3*$B$29 -> 6951.3406 | W40: ='10Y duration'!J3*$B$29 -> 8602.284 | X40: ='10Y duration'!K3*$B$29 -> 6951.3406
A41: 0.5 | B41: =Bootstrap!J4 *$B$29 -> 8539.153 | C41: =Bootstrap!K4*$B$29 -> 7287.8461 | E41: ='1Y duration'!J4*$B$29 -> 8538.8694 | F41: ='1Y duration'!K4*$B$29 -> 7320.5904 | H41: ='2Y duration'!J4*$B$29 -> 8539.153 | I41: ='2Y duration'!K4*$B$29 -> 7287.8461 | K41: ='3Y duration'!J4*$B$29 -> 8539.153 | L41: ='3Y duration'!K4*$B$29 -> 7287.8461 | N41: ='4Y duration'!J4*$B$29 -> 8539.153 | O41: ='4Y duration'!K4*$B$29 -> 7287.8461 | Q41: ='5Y duration'!J4*$B$29 -> 8539.153 | R41: ='5Y duration'!K4*$B$29 -> 7287.8461 | T41: ='7Y duration'!J4*$B$29 -> 8539.153 | U41: ='7Y duration'!K4*$B$29 -> 7287.8461 | W41: ='10Y duration'!J4*$B$29 -> 8539.153 | X41: ='10Y duration'!K4*$B$29 -> 7287.8461
A42: 0.75 | B42: =Bootstrap!J5 *$B$29 -> 8476.4854 | C42: =Bootstrap!K5*$B$29 -> 7234.3616 | E42: ='1Y duration'!J5*$B$29 -> 8475.9223 | F42: ='1Y duration'!K5*$B$29 -> 7266.6242 | H42: ='2Y duration'!J5*$B$29 -> 8476.4854 | I42: ='2Y duration'!K5*$B$29 -> 7234.3616 | K42: ='3Y duration'!J5*$B$29 -> 8476.4854 | L42: ='3Y duration'!K5*$B$29 -> 7234.3616 | N42: ='4Y duration'!J5*$B$29 -> 8476.4854 | O42: ='4Y duration'!K5*$B$29 -> 7234.3616 | Q42: ='5Y duration'!J5*$B$29 -> 8476.4854 | R42: ='5Y duration'!K5*$B$29 -> 7234.3616 | T42: ='7Y duration'!J5*$B$29 -> 8476.4854 | U42: ='7Y duration'!K5*$B$29 -> 7234.3616 | W42: ='10Y duration'!J5*$B$29 -> 8476.4854 | X42: ='10Y duration'!K5*$B$29 -> 7234.3616
A43: 1 | B43: =Bootstrap!J6 *$B$29 -> 8414.2776 | C43: =Bootstrap!K6*$B$29 -> 7181.2696 | E43: ='1Y duration'!J6*$B$29 -> 8413.4392 | F43: ='1Y duration'!K6*$B$29 -> 7213.0558 | H43: ='2Y duration'!J6*$B$29 -> 8414.2776 | I43: ='2Y duration'!K6*$B$29 -> 7181.2696 | K43: ='3Y duration'!J6*$B$29 -> 8414.2776 | L43: ='3Y duration'!K6*$B$29 -> 7181.2696 | N43: ='4Y duration'!J6*$B$29 -> 8414.2776 | O43: ='4Y duration'!K6*$B$29 -> 7181.2696 | Q43: ='5Y duration'!J6*$B$29 -> 8414.2776 | R43: ='5Y duration'!K6*$B$29 -> 7181.2696 | T43: ='7Y duration'!J6*$B$29 -> 8414.2776 | U43: ='7Y duration'!K6*$B$29 -> 7181.2696 | W43: ='10Y duration'!J6*$B$29 -> 8414.2776 | X43: ='10Y duration'!K6*$B$29 -> 7181.2696
A44: 1.25 | B44: =Bootstrap!J7 *$B$29 -> 8346.1953 | C44: =Bootstrap!K7*$B$29 -> 7859.4286 | E44: ='1Y duration'!J7*$B$29 -> 8345.5772 | F44: ='1Y duration'!K7*$B$29 -> 7833.9887 | H44: ='2Y duration'!J7*$B$29 -> 8345.7744 | I44: ='2Y duration'!K7*$B$29 -> 7908.0273 | K44: ='3Y duration'!J7*$B$29 -> 8346.1953 | L44: ='3Y duration'!K7*$B$29 -> 7859.4286 | N44: ='4Y duration'!J7*$B$29 -> 8346.1953 | O44: ='4Y duration'!K7*$B$29 -> 7859.4286 | Q44: ='5Y duration'!J7*$B$29 -> 8346.1953 | R44: ='5Y duration'!K7*$B$29 -> 7859.4286 | T44: ='7Y duration'!J7*$B$29 -> 8346.1953 | U44: ='7Y duration'!K7*$B$29 -> 7859.4286 | W44: ='10Y duration'!J7*$B$29 -> 8346.1953 | X44: ='10Y duration'!K7*$B$29 -> 7859.4286
A45: 1.5 | B45: =Bootstrap!J8 *$B$29 -> 8278.6639 | C45: =Bootstrap!K8*$B$29 -> 7795.8357 | E45: ='1Y duration'!J8*$B$29 -> 8278.2627 | F45: ='1Y duration'!K8*$B$29 -> 7770.8005 | H45: ='2Y duration'!J8*$B$29 -> 8277.8288 | I45: ='2Y duration'!K8*$B$29 -> 7843.6455 | K45: ='3Y duration'!J8*$B$29 -> 8278.6639 | L45: ='3Y duration'!K8*$B$29 -> 7795.8357 | N45: ='4Y duration'!J8*$B$29 -> 8278.6639 | O45: ='4Y duration'!K8*$B$29 -> 7795.8357 | Q45: ='5Y duration'!J8*$B$29 -> 8278.6639 | R45: ='5Y duration'!K8*$B$29 -> 7795.8357 | T45: ='7Y duration'!J8*$B$29 -> 8278.6639 | U45: ='7Y duration'!K8*$B$29 -> 7795.8357 | W45: ='10Y duration'!J8*$B$29 -> 8278.6639 | X45: ='10Y duration'!K8*$B$29 -> 7795.8357
...

Sheet Bootstrap
A1: Bootstraping | I1: Swap rate | J1: =Sheet1!B9/100 -> 0.03465 | L1: Swap rate | M1: 0.037 | P1: 8Y swap | Q1: =Sheet1!C33 -> 0.034285954
A2: Maturity | B2: DF | C2: LN(DF) | D2: 이론 rate | E2: 실제 rate | F2: error | G2: spot curve | H2: forward curve | J2: fixed leg | K2: floating leg | M2: fixed leg | N2: floating leg | Q2: fixed leg | R2: floating leg
A3: {=_xlfn.SEQUENCE(40,,0.25,0.25)} -> 0.25 | B3: =1/(1+Sheet1!B2/100*0.25) -> 0.99304866 | C3: =LN(B3) -> -0.0069756137 | G3: =-C3/A3 -> 0.027902455 | H3: =(1/B3-1)/0.25 -> 0.028 | J3: =$J$1*0.25*B3 -> 0.008602284 | K3: =H3*0.25*B3 -> 0.0069513406 | M3: =$M$1*0.25*B3 -> 0.0091857001 | N3: =H3*0.25*B3 -> 0.0069513406 | Q3: =$Q$1*0.25*B3 -> 0.0085119051 | R3: =H3*0.25*B3 -> 0.0069513406
A4: 0.5 | B4: =EXP(C4) -> 0.98576081 | C4: =$C$3+($C$6-$C$3)*(A4-$A$3)/($A$6-$A$3) -> -0.014341537 | G4: =-C4/A4 -> 0.028683073 | H4: =(B3/B4-1)/0.25 -> 0.029572472 | J4: =$J$1*0.25*B4 -> 0.008539153 | K4: =H4*0.25*B4 -> 0.0072878461 | M4: =$M$1*0.25*B4 -> 0.0091182875 | N4: =H4*0.25*B4 -> 0.0072878461 | Q4: =$Q$1*0.25*B4 -> 0.0084494374 | R4: =H4*0.25*B4 -> 0.0072878461
A5: 0.75 | B5: =EXP(C5) -> 0.97852645 | C5: =$C$3+($C$6-$C$3)*(A5-$A$3)/($A$6-$A$3) -> -0.02170746 | G5: =-C5/A5 -> 0.028943279 | H5: =(B4/B5-1)/0.25 -> 0.029572472 | J5: =$J$1*0.25*B5 -> 0.0084764854 | K5: =H5*0.25*B5 -> 0.0072343616 | M5: =$M$1*0.25*B5 -> 0.0090513697 | N5: =H5*0.25*B5 -> 0.0072343616 | Q5: =$Q$1*0.25*B5 -> 0.0083874282 | R5: =H5*0.25*B5 -> 0.0072343616
A6: 1 | B6: 0.97134518 | C6: =LN(B6) -> -0.029073382 | D6: =(1-B6)/(SUM($B$3:B6) *0.25) -> 0.029175 | E6: =VLOOKUP(A6,Sheet1!$A$2:$B$12,2)/100 -> 0.029175 | F6: =D6-E6 -> 4.510281e-17 | G6: =-C6/A6 -> 0.029073382 | H6: =(B5/B6-1)/0.25 -> 0.029572472 | J6: =$J$1*0.25*B6 -> 0.0084142776 | K6: =H6*0.25*B6 -> 0.0071812696 | M6: =$M$1*0.25*B6 -> 0.0089849429 | N6: =H6*0.25*B6 -> 0.0071812696 | Q6: =$Q$1*0.25*B6 -> 0.008325874 | R6: =H6*0.25*B6 -> 0.0071812696
A7: 1.25 | B7: =EXP(C7) -> 0.96348575 | C7: =$C$6+($C$10-$C$6)*(A7-$A$6)/($A$10-$A$6) -> -0.037197577 | G7: =-C7/A7 -> 0.029758062 | H7: =(B6/B7-1)/0.25 -> 0.032629143 | J7: =$J$1*0.25*B7 -> 0.0083461953 | K7: =H7*0.25*B7 -> 0.0078594286 | M7: =$M$1*0.25*B7 -> 0.0089122432 | N7: =H7*0.25*B7 -> 0.0078594286 | Q7: =$Q$1*0.25*B7 -> 0.008258507 | R7: =H7*0.25*B7 -> 0.0078594286
A8: 1.5 | B8: =EXP(C8) -> 0.95568992 | C8: =$C$6+($C$10-$C$6)*(A8-$A$6)/($A$10-$A$6) -> -0.045321772 | G8: =-C8/A8 -> 0.030214515 | H8: =(B7/B8-1)/0.25 -> 0.032629143 | J8: =$J$1*0.25*B8 -> 0.0082786639 | K8: =H8*0.25*B8 -> 0.0077958357 | M8: =$M$1*0.25*B8 -> 0.0088401317 | N8: =H8*0.25*B8 -> 0.0077958357 | Q8: =$Q$1*0.25*B8 -> 0.0081916851 | R8: =H8*0.25*B8 -> 0.0077958357
A9: 1.75 | B9: =EXP(C9) -> 0.94795716 | C9: =$C$6+($C$10-$C$6)*(A9-$A$6)/($A$10-$A$6) -> -0.053445967 | G9: =-C9/A9 -> 0.030540553 | H9: =(B8/B9-1)/0.25 -> 0.032629143 | J9: =$J$1*0.25*B9 -> 0.0082116789 | K9: =H9*0.25*B9 -> 0.0077327574 | M9: =$M$1*0.25*B9 -> 0.0087686037 | N9: =H9*0.25*B9 -> 0.0077327574 | Q9: =$Q$1*0.25*B9 -> 0.0081254039 | R9: =H9*0.25*B9 -> 0.0077327574
A10: 2 | B10: 0.94028697 | C10: =LN(B10) -> -0.061570162 | D10: =(1-B10)/(SUM($B$3:B10) *0.25) -> 0.030875 | E10: =VLOOKUP(A10,Sheet1!$A$2:$B$12,2)/100 -> 0.030875 | F10: =D10-E10 -> 0 | G10: =-C10/A10 -> 0.030785081 | H10: =(B9/B10-1)/0.25 -> 0.032629143 | J10: =$J$1*0.25*B10 -> 0.0081452359 | K10: =H10*0.25*B10 -> 0.0076701895 | M10: =$M$1*0.25*B10 -> 0.0086976545 | N10: =H10*0.25*B10 -> 0.0076701895 | Q10: =$Q$1*0.25*B10 -> 0.0080596589 | R10: =H10*0.25*B10 -> 0.0076701895
A11: 2.25 | B11: =EXP(C11) -> 0.9322778 | C11: =$C$10+($C$14-$C$10)*(A11-$A$10)/($A$14-$A$10) -> -0.070124435 | G11: =-C11/A11 -> 0.031166416 | H11: =(B10/B11-1)/0.25 -> 0.034363862 | J11: =$J$1*0.25*B11 -> 0.0080758565 | K11: =H11*0.25*B11 -> 0.0080091664 | M11: =$M$1*0.25*B11 -> 0.0086235697 | N11: =H11*0.25*B11 -> 0.0080091664 | Q11: =$Q$1*0.25*B11 -> 0.0079910085 | R11: =H11*0.25*B11 -> 0.0080091664
A12: 2.5 | B12: =EXP(C12) -> 0.92433686 | C12: =$C$10+($C$14-$C$10)*(A12-$A$10)/($A$14-$A$10) -> -0.078678708 | G12: =-C12/A12 -> 0.031471483 | H12: =(B11/B12-1)/0.25 -> 0.034363862 | J12: =$J$1*0.25*B12 -> 0.008007068 | K12: =H12*0.25*B12 -> 0.007940946 | M12: =$M$1*0.25*B12 -> 0.0085501159 | N12: =H12*0.25*B12 -> 0.007940946 | Q12: =$Q$1*0.25*B12 -> 0.0079229427 | R12: =H12*0.25*B12 -> 0.007940946
A13: 2.75 | B13: =EXP(C13) -> 0.91646355 | C13: =$C$10+($C$14-$C$10)*(A13-$A$10)/($A$14-$A$10) -> -0.087232981 | G13: =-C13/A13 -> 0.031721084 | H13: =(B12/B13-1)/0.25 -> 0.034363862 | J13: =$J$1*0.25*B13 -> 0.0079388655 | K13: =H13*0.25*B13 -> 0.0078733067 | M13: =$M$1*0.25*B13 -> 0.0084772879 | N13: =H13*0.25*B13 -> 0.0078733067 | Q13: =$Q$1*0.25*B13 -> 0.0078554568 | R13: =H13*0.25*B13 -> 0.0078733067
A14: 3 | B14: 0.90865731 | C14: =LN(B14) -> -0.095787254 | D14: =(1-B14)/(SUM($B$3:B14) *0.25) -> 0.032 | E14: =VLOOKUP(A14,Sheet1!$A$2:$B$12,2)/100 -> 0.032 | F14: =D14-E14 -> 0 | G14: =-C14/A14 -> 0.031929085 | H14: =(B13/B14-1)/0.25 -> 0.034363862 | J14: =$J$1*0.25*B14 -> 0.0078712439 | K14: =H14*0.25*B14 -> 0.0078062435 | M14: =$M$1*0.25*B14 -> 0.0084050801 | N14: =H14*0.25*B14 -> 0.0078062435 | Q14: =$Q$1*0.25*B14 -> 0.0077885456 | R14: =H14*0.25*B14 -> 0.0078062435
A15: 3.25 | B15: =EXP(C15) -> 0.90078731 | C15: =$C$14+($C$18-$C$14)*(A15-$A$14)/($A$18-$A$14) -> -0.10448611 | G15: =-C15/A15 -> 0.032149574 | H15: =(B14/B15-1)/0.25 -> 0.034947221 | J15: =$J$1*0.25*B15 -> 0.00780307 | K15: =H15*0.25*B15 -> 0.0078700034 | M15: =$M$1*0.25*B15 -> 0.0083322826 | N15: =H15*0.25*B15 -> 0.0078700034 | Q15: =$Q$1*0.25*B15 -> 0.007721088 | R15: =H15*0.25*B15 -> 0.0078700034
A16: 3.5 | B16: =EXP(C16) -> 0.89298546 | C16: =$C$14+($C$18-$C$14)*(A16-$A$14)/($A$18-$A$14) -> -0.11318497 | G16: =-C16/A16 -> 0.032338564 | H16: =(B15/B16-1)/0.25 -> 0.034947221 | J16: =$J$1*0.25*B16 -> 0.0077354866 | K16: =H16*0.25*B16 -> 0.0078018402 | M16: =$M$1*0.25*B16 -> 0.0082601156 | N16: =H16*0.25*B16 -> 0.0078018402 | Q16: =$Q$1*0.25*B16 -> 0.0076542146 | R16: =H16*0.25*B16 -> 0.0078018402
A17: 3.75 | B17: =EXP(C17) -> 0.8852512 | C17: =$C$14+($C$18-$C$14)*(A17-$A$14)/($A$18-$A$14) -> -0.12188384 | G17: =-C17/A17 -> 0.032502356 | H17: =(B16/B17-1)/0.25 -> 0.034947221 | J17: =$J$1*0.25*B17 -> 0.0076684885 | K17: =H17*0.25*B17 -> 0.0077342674 | M17: =$M$1*0.25*B17 -> 0.0081885736 | N17: =H17*0.25*B17 -> 0.0077342674 | Q17: =$Q$1*0.25*B17 -> 0.0075879204 | R17: =H17*0.25*B17 -> 0.0077342674
A18: 4 | B18: 0.87758392 | C18: =LN(B18) -> -0.1305827 | D18: =(1-B18)/(SUM($B$3:B18) *0.25) -> 0.0327 | E18: =VLOOKUP(A18,Sheet1!$A$2:$B$12,2)/100 -> 0.0327 | F18: =D18-E18 -> 0 | G18: =-C18/A18 -> 0.032645674 | H18: =(B17/B18-1)/0.25 -> 0.034947221 | J18: =$J$1*0.25*B18 -> 0.0076020707 | K18: =H18*0.25*B18 -> 0.0076672799 | M18: =$M$1*0.25*B18 -> 0.0081176512 | N18: =H18*0.25*B18 -> 0.0076672799 | Q18: =$Q$1*0.25*B18 -> 0.0075222004 | R18: =H18*0.25*B18 -> 0.0076672799
A19: 4.25 | B19: =EXP(C19) -> 0.86983182 | C19: =$C$18+($C$22-$C$18)*(A19-$A$18)/($A$22-$A$18) -> -0.13945539 | G19: =-C19/A19 -> 0.032813034 | H19: =(B18/B19-1)/0.25 -> 0.035648705 | J19: =$J$1*0.25*B19 -> 0.0075349182 | K19: =H19*0.25*B19 -> 0.0077520945 | M19: =$M$1*0.25*B19 -> 0.0080459444 | N19: =H19*0.25*B19 -> 0.0077520945 | Q19: =$Q$1*0.25*B19 -> 0.0074557534 | R19: =H19*0.25*B19 -> 0.0077520945
A20: 4.5 | B20: =EXP(C20) -> 0.86214821 | C20: =$C$18+($C$22-$C$18)*(A20-$A$18)/($A$22-$A$18) -> -0.14832809 | G20: =-C20/A20 -> 0.032961798 | H20: =(B19/B20-1)/0.25 -> 0.035648705 | J20: =$J$1*0.25*B20 -> 0.0074683588 | K20: =H20*0.25*B20 -> 0.0076836167 | M20: =$M$1*0.25*B20 -> 0.0079748709 | N20: =H20*0.25*B20 -> 0.0076836167 | Q20: =$Q$1*0.25*B20 -> 0.0073898934 | R20: =H20*0.25*B20 -> 0.0076836167
A21: 4.75 | B21: =EXP(C21) -> 0.85453246 | C21: =$C$18+($C$22-$C$18)*(A21-$A$18)/($A$22-$A$18) -> -0.15720079 | G21: =-C21/A21 -> 0.033094903 | H21: =(B20/B21-1)/0.25 -> 0.035648705 | J21: =$J$1*0.25*B21 -> 0.0074023875 | K21: =H21*0.25*B21 -> 0.0076157439 | M21: =$M$1*0.25*B21 -> 0.0079044253 | N21: =H21*0.25*B21 -> 0.0076157439 | Q21: =$Q$1*0.25*B21 -> 0.0073246152 | R21: =H21*0.25*B21 -> 0.0076157439
A22: 5 | B22: 0.84698399 | C22: =LN(B22) -> -0.16607348 | D22: =(1-B22)/(SUM($B$3:B22) *0.25) -> 0.03325 | E22: =VLOOKUP(A22,Sheet1!$A$2:$B$12,2)/100 -> 0.03325 | F22: =D22-E22 -> 0 | G22: =-C22/A22 -> 0.033214697 | H22: =(B21/B22-1)/0.25 -> 0.035648705 | J22: =$J$1*0.25*B22 -> 0.0073369988 | K22: =H22*0.25*B22 -> 0.0075484706 | M22: =$M$1*0.25*B22 -> 0.0078346019 | N22: =H22*0.25*B22 -> 0.0075484706 | Q22: =$Q$1*0.25*B22 -> 0.0072599135 | R22: =H22*0.25*B22 -> 0.0075484706
A23: 5.25 | B23: =EXP(C23) -> 0.83938397 | C23: =$C$22+($C$30-$C$22)*(A23-$A$22)/($A$30-$A$22) -> -0.17508702 | G23: =-C23/A23 -> 0.033349909 | H23: =(B22/B23-1)/0.25 -> 0.036217121 | J23: =$J$1*0.25*B23 -> 0.0072711637 | K23: =H23*0.25*B23 -> 0.0076000177 | M23: =$M$1*0.25*B23 -> 0.0077643018 | N23: =H23*0.25*B23 -> 0.0076000177 | Q23: =$Q$1*0.25*B23 -> 0.0071947701 | R23: =H23*0.25*B23 -> 0.0076000177
A24: 5.5 | B24: =EXP(C24) -> 0.83185215 | C24: =$C$22+($C$30-$C$22)*(A24-$A$22)/($A$30-$A$22) -> -0.18410056 | G24: =-C24/A24 -> 0.033472828 | H24: =(B23/B24-1)/0.25 -> 0.036217121 | J24: =$J$1*0.25*B24 -> 0.0072059193 | K24: =H24*0.25*B24 -> 0.0075318225 | M24: =$M$1*0.25*B24 -> 0.0076946324 | N24: =H24*0.25*B24 -> 0.0075318225 | Q24: =$Q$1*0.25*B24 -> 0.0071302111 | R24: =H24*0.25*B24 -> 0.0075318225
A25: 5.75 | B25: =EXP(C25) -> 0.82438791 | C25: =$C$22+($C$30-$C$22)*(A25-$A$22)/($A$30-$A$22) -> -0.19311409 | G25: =-C25/A25 -> 0.033585059 | H25: =(B24/B25-1)/0.25 -> 0.036217121 | J25: =$J$1*0.25*B25 -> 0.0071412603 | K25: =H25*0.25*B25 -> 0.0074642392 | M25: =$M$1*0.25*B25 -> 0.0076255882 | N25: =H25*0.25*B25 -> 0.0074642392 | Q25: =$Q$1*0.25*B25 -> 0.0070662315 | R25: =H25*0.25*B25 -> 0.0074642392
A26: 6 | B26: =EXP(C26) -> 0.81699065 | C26: =$C$22+($C$30-$C$22)*(A26-$A$22)/($A$30-$A$22) -> -0.20212763 | G26: =-C26/A26 -> 0.033687938 | H26: =(B25/B26-1)/0.25 -> 0.036217121 | J26: =$J$1*0.25*B26 -> 0.0070771815 | K26: =H26*0.25*B26 -> 0.0073972623 | M26: =$M$1*0.25*B26 -> 0.0075571635 | N26: =H26*0.25*B26 -> 0.0073972623 | Q26: =$Q$1*0.25*B26 -> 0.0070028259 | R26: =H26*0.25*B26 -> 0.0073972623
A27: 6.25 | B27: =EXP(C27) -> 0.80965976 | C27: =$C$22+($C$30-$C$22)*(A27-$A$22)/($A$30-$A$22) -> -0.21114116 | G27: =-C27/A27 -> 0.033782586 | H27: =(B26/B27-1)/0.25 -> 0.036217121 | J27: =$J$1*0.25*B27 -> 0.0070136777 | K27: =H27*0.25*B27 -> 0.0073308864 | M27: =$M$1*0.25*B27 -> 0.0074893528 | N27: =H27*0.25*B27 -> 0.0073308864 | Q27: =$Q$1*0.25*B27 -> 0.0069399893 | R27: =H27*0.25*B27 -> 0.0073308864
A28: 6.5 | B28: =EXP(C28) -> 0.80239466 | C28: =$C$22+($C$30-$C$22)*(A28-$A$22)/($A$30-$A$22) -> -0.2201547 | G28: =-C28/A28 -> 0.033869954 | H28: =(B27/B28-1)/0.25 -> 0.036217121 | J28: =$J$1*0.25*B28 -> 0.0069507437 | K28: =H28*0.25*B28 -> 0.0072651061 | M28: =$M$1*0.25*B28 -> 0.0074221506 | N28: =H28*0.25*B28 -> 0.0072651061 | Q28: =$Q$1*0.25*B28 -> 0.0068777166 | R28: =H28*0.25*B28 -> 0.0072651061
A29: 6.75 | B29: =EXP(C29) -> 0.79519474 | C29: =$C$22+($C$30-$C$22)*(A29-$A$22)/($A$30-$A$22) -> -0.22916824 | G29: =-C29/A29 -> 0.03395085 | H29: =(B28/B29-1)/0.25 -> 0.036217121 | J29: =$J$1*0.25*B29 -> 0.0068883745 | K29: =H29*0.25*B29 -> 0.007199916 | M29: =$M$1*0.25*B29 -> 0.0073555514 | N29: =H29*0.25*B29 -> 0.007199916 | Q29: =$Q$1*0.25*B29 -> 0.0068160026 | R29: =H29*0.25*B29 -> 0.007199916
A30: 7 | B30: 0.78805943 | C30: =LN(B30) -> -0.23818177 | D30: =(1-B30)/(SUM($B$3:B30) *0.25) -> 0.034025 | E30: =VLOOKUP(A30,Sheet1!$A$2:$B$12,2)/100 -> 0.034025 | F30: =D30-E30 -> 0 | G30: =-C30/A30 -> 0.034025967 | H30: =(B29/B30-1)/0.25 -> 0.036217121 | J30: =$J$1*0.25*B30 -> 0.0068265648 | K30: =H30*0.25*B30 -> 0.0071353109 | M30: =$M$1*0.25*B30 -> 0.0072895497 | N30: =H30*0.25*B30 -> 0.0071353109 | Q30: =$Q$1*0.25*B30 -> 0.0067548423 | R30: =H30*0.25*B30 -> 0.0071353109
A31: 7.25 | B31: =EXP(C31) -> 0.78095359 | C31: =$C$30+($C$42-$C$30)*(A31-$A$30)/($A$42-$A$30) -> -0.24723955 | G31: =-C31/A31 -> 0.034102007 | H31: =(B30/B31-1)/0.25 -> 0.036395713 | J31: =$J$1*0.25*B31 -> 0.0067650105 | K31: =H31*0.25*B31 -> 0.0071058407 | M31: =$M$1*0.25*B31 -> 0.0072238207 | N31: =H31*0.25*B31 -> 0.0071058407 | Q31: =$Q$1*0.25*B31 -> 0.0066939347 | R31: =H31*0.25*B31 -> 0.0071058407
A32: 7.5 | B32: =EXP(C32) -> 0.77391182 | C32: =$C$30+($C$42-$C$30)*(A32-$A$30)/($A$42-$A$30) -> -0.25629734 | G32: =-C32/A32 -> 0.034172978 | H32: =(B31/B32-1)/0.25 -> 0.036395713 | J32: =$J$1*0.25*B32 -> 0.0067040112 | K32: =H32*0.25*B32 -> 0.0070417681 | M32: =$M$1*0.25*B32 -> 0.0071586844 | N32: =H32*0.25*B32 -> 0.0070417681 | Q32: =$Q$1*0.25*B32 -> 0.0066335763 | R32: =H32*0.25*B32 -> 0.0070417681
A33: 7.75 | B33: =EXP(C33) -> 0.76693355 | C33: =$C$30+($C$42-$C$30)*(A33-$A$30)/($A$42-$A$30) -> -0.26535512 | G33: =-C33/A33 -> 0.03423937 | H33: =(B32/B33-1)/0.25 -> 0.036395713 | J33: =$J$1*0.25*B33 -> 0.0066435619 | K33: =H33*0.25*B33 -> 0.0069782733 | M33: =$M$1*0.25*B33 -> 0.0070941353 | N33: =H33*0.25*B33 -> 0.0069782733 | Q33: =$Q$1*0.25*B33 -> 0.0065737621 | R33: =H33*0.25*B33 -> 0.0069782733
A34: 8 | B34: =EXP(C34) -> 0.7600182 | C34: =$C$30+($C$42-$C$30)*(A34-$A$30)/($A$42-$A$30) -> -0.2744129 | G34: =-C34/A34 -> 0.034301613 | H34: =(B33/B34-1)/0.25 -> 0.036395713 | J34: =$J$1*0.25*B34 -> 0.0065836576 | K34: =H34*0.25*B34 -> 0.006915351 | M34: =$M$1*0.25*B34 -> 0.0070301683 | N34: =H34*0.25*B34 -> 0.006915351 | Q34: =$Q$1*0.25*B34 -> 0.0065144872 | R34: =H34*0.25*B34 -> 0.006915351
A35: 8.25 | B35: =EXP(C35) -> 0.7531652 | C35: =$C$30+($C$42-$C$30)*(A35-$A$30)/($A$42-$A$30) -> -0.28347068 | G35: =-C35/A35 -> 0.034360083 | H35: =(B34/B35-1)/0.25 -> 0.036395713 | J35: =$J$1*0.25*B35 -> 0.0065242936 | K35: =H35*0.25*B35 -> 0.0068529961 | M35: =$M$1*0.25*B35 -> 0.0069667781 | N35: =H35*0.25*B35 -> 0.0068529961 | P35: Total | Q35: =SUM(Q3:Q34) -> 0.2399818 | R35: =SUM(R3:R34) -> 0.2399818
A36: 8.5 | B36: =EXP(C36) -> 0.746374 | C36: =$C$30+($C$42-$C$30)*(A36-$A$30)/($A$42-$A$30) -> -0.29252847 | G36: =-C36/A36 -> 0.034415114 | H36: =(B35/B36-1)/0.25 -> 0.036395713 | J36: =$J$1*0.25*B36 -> 0.0064654648 | K36: =H36*0.25*B36 -> 0.0067912034 | M36: =$M$1*0.25*B36 -> 0.0069039595 | N36: =H36*0.25*B36 -> 0.0067912034 | Q36: =Q35-R35 -> 0 | R36: > Swap rate를 올바르게 구했는지 leg의 차이를 계산함으로써 구하기
A37: 8.75 | B37: =EXP(C37) -> 0.73964403 | C37: =$C$30+($C$42-$C$30)*(A37-$A$30)/($A$42-$A$30) -> -0.30158625 | G37: =-C37/A37 -> 0.034467 | H37: =(B36/B37-1)/0.25 -> 0.036395713 | J37: =$J$1*0.25*B37 -> 0.0064071664 | K37: =H37*0.25*B37 -> 0.0067299679 | M37: =$M$1*0.25*B37 -> 0.0068417073 | N37: =H37*0.25*B37 -> 0.0067299679
A38: 9 | B38: =EXP(C38) -> 0.73297475 | C38: =$C$30+($C$42-$C$30)*(A38-$A$30)/($A$42-$A$30) -> -0.31064403 | G38: =-C38/A38 -> 0.034516003 | H38: =(B37/B38-1)/0.25 -> 0.036395713 | J38: =$J$1*0.25*B38 -> 0.0063493937 | K38: =H38*0.25*B38 -> 0.0066692846 | M38: =$M$1*0.25*B38 -> 0.0067800164 | N38: =H38*0.25*B38 -> 0.0066692846
A39: 9.25 | B39: =EXP(C39) -> 0.7263656 | C39: =$C$30+($C$42-$C$30)*(A39-$A$30)/($A$42-$A$30) -> -0.31970181 | G39: =-C39/A39 -> 0.034562358 | H39: =(B38/B39-1)/0.25 -> 0.036395713 | J39: =$J$1*0.25*B39 -> 0.006292142 | K39: =H39*0.25*B39 -> 0.0066091484 | M39: =$M$1*0.25*B39 -> 0.0067188818 | N39: =H39*0.25*B39 -> 0.0066091484
A40: 9.5 | B40: =EXP(C40) -> 0.71981604 | C40: =$C$30+($C$42-$C$30)*(A40-$A$30)/($A$42-$A$30) -> -0.3287596 | G40: =-C40/A40 -> 0.034606273 | H40: =(B39/B40-1)/0.25 -> 0.036395713 | J40: =$J$1*0.25*B40 -> 0.0062354065 | K40: =H40*0.25*B40 -> 0.0065495545 | M40: =$M$1*0.25*B40 -> 0.0066582984 | N40: =H40*0.25*B40 -> 0.0065495545
...

Sheet Duration
A1: Bootstraping | I1: Swap rate | J1: =Sheet1!B9/100 -> 0.03465 | M1: 8Y swap | N1: =Sheet1!C33 -> 0.034285954
A2: Maturity | B2: DF | C2: LN(DF) | D2: 이론 rate | E2: 실제 rate | F2: error | G2: spot curve | H2: forward curve | J2: fixed leg | K2: floating leg | N2: fixed | O2: floating
A3: {=_xlfn.SEQUENCE(40,,0.25,0.25)} -> 0.25 | B3: =1/(1+Sheet1!B15/100*0.25) -> 0.99302401 | C3: =LN(B3) -> -0.0070004396 | G3: =-C3/A3 -> 0.028001759 | H3: =(1/B3-1)/0.25 -> 0.0281 | J3: =$J$1*0.25*B3 -> 0.0086020705 | K3: =H3*0.25*B3 -> 0.0069759936 | N3: =$N$1*0.25*B3 -> 0.0085116938 | O3: =B3*0.25*H3 -> 0.0069759936
A4: 0.5 | B4: =EXP(C4) -> 0.98571187 | C4: =$C$3+($C$6-$C$3)*(A4-$A$3)/($A$6-$A$3) -> -0.014391184 | G4: =-C4/A4 -> 0.028782367 | H4: =(B3/B4-1)/0.25 -> 0.029672492 | J4: =$J$1*0.25*B4 -> 0.0085387291 | K4: =H4*0.25*B4 -> 0.0073121319 | N4: =$N$1*0.25*B4 -> 0.008449018 | O4: =B4*0.25*H4 -> 0.0073121319
A5: 0.75 | B5: =EXP(C5) -> 0.97845359 | C5: =$C$3+($C$6-$C$3)*(A5-$A$3)/($A$6-$A$3) -> -0.021781928 | G5: =-C5/A5 -> 0.02904257 | H5: =(B4/B5-1)/0.25 -> 0.029672492 | J5: =$J$1*0.25*B5 -> 0.0084758542 | K5: =H5*0.25*B5 -> 0.007258289 | N5: =$N$1*0.25*B5 -> 0.0083868036 | O5: =B5*0.25*H5 -> 0.007258289
A6: 1 | B6: 0.97124874 | C6: =LN(B6) -> -0.029172672 | D6: =(1-B6)/(SUM($B$3:B6) *0.25) -> 0.029275 | E6: =VLOOKUP(A6,Sheet1!$A$15:$B$25,2)/100 -> 0.029275 | F6: =D6-E6 -> 3.469447e-17 | G6: =-C6/A6 -> 0.029172672 | H6: =(B5/B6-1)/0.25 -> 0.029672492 | J6: =$J$1*0.25*B6 -> 0.0084134422 | K6: =H6*0.25*B6 -> 0.0072048426 | N6: =$N$1*0.25*B6 -> 0.0083250474 | O6: =B6*0.25*H6 -> 0.0072048426
A7: 1.25 | B7: =EXP(C7) -> 0.96336616 | C7: =$C$6+($C$10-$C$6)*(A7-$A$6)/($A$10-$A$6) -> -0.037321707 | G7: =-C7/A7 -> 0.029857366 | H7: =(B6/B7-1)/0.25 -> 0.032729317 | J7: =$J$1*0.25*B7 -> 0.0083451594 | K7: =H7*0.25*B7 -> 0.0078825791 | N7: =$N$1*0.25*B7 -> 0.008257482 | O7: =B7*0.25*H7 -> 0.0078825791
A8: 1.5 | B8: =EXP(C8) -> 0.95554756 | C8: =$C$6+($C$10-$C$6)*(A8-$A$6)/($A$10-$A$6) -> -0.045470743 | G8: =-C8/A8 -> 0.030313828 | H8: =(B7/B8-1)/0.25 -> 0.032729317 | J8: =$J$1*0.25*B8 -> 0.0082774307 | K8: =H8*0.25*B8 -> 0.0078186047 | N8: =$N$1*0.25*B8 -> 0.0081904649 | O8: =B8*0.25*H8 -> 0.0078186047
A9: 1.75 | B9: =EXP(C9) -> 0.94779241 | C9: =$C$6+($C$10-$C$6)*(A9-$A$6)/($A$10-$A$6) -> -0.053619778 | G9: =-C9/A9 -> 0.030639873 | H9: =(B8/B9-1)/0.25 -> 0.032729317 | J9: =$J$1*0.25*B9 -> 0.0082102517 | K9: =H9*0.25*B9 -> 0.0077551495 | N9: =$N$1*0.25*B9 -> 0.0081239917 | O9: =B9*0.25*H9 -> 0.0077551495
A10: 2 | B10: 0.9401002 | C10: =LN(B10) -> -0.061768814 | D10: =(1-B10)/(SUM($B$3:B10) *0.25) -> 0.030975 | E10: =VLOOKUP(A10,Sheet1!$A$15:$B$25,2)/100 -> 0.030975 | F10: =D10-E10 -> 0 | G10: =-C10/A10 -> 0.030884407 | H10: =(B9/B10-1)/0.25 -> 0.032729317 | J10: =$J$1*0.25*B10 -> 0.008143618 | K10: =H10*0.25*B10 -> 0.0076922094 | N10: =$N$1*0.25*B10 -> 0.008058058 | O10: =B10*0.25*H10 -> 0.0076922094
A11: 2.25 | B11: =EXP(C11) -> 0.93206944 | C11: =$C$10+($C$14-$C$10)*(A11-$A$10)/($A$14-$A$10) -> -0.070347961 | G11: =-C11/A11 -> 0.031265761 | H11: =(B10/B11-1)/0.25 -> 0.034464216 | J11: =$J$1*0.25*B11 -> 0.0080740515 | K11: =H11*0.25*B11 -> 0.0080307606 | N11: =$N$1*0.25*B11 -> 0.0079892225 | O11: =B11*0.25*H11 -> 0.0080307606
A12: 2.5 | B12: =EXP(C12) -> 0.92410728 | C12: =$C$10+($C$14-$C$10)*(A12-$A$10)/($A$14-$A$10) -> -0.078927109 | G12: =-C12/A12 -> 0.031570844 | H12: =(B11/B12-1)/0.25 -> 0.034464216 | J12: =$J$1*0.25*B12 -> 0.0080050793 | K12: =H12*0.25*B12 -> 0.0079621582 | N12: =$N$1*0.25*B12 -> 0.0079209749 | O12: =B12*0.25*H12 -> 0.0079621582
A13: 2.75 | B13: =EXP(C13) -> 0.91621314 | C13: =$C$10+($C$14-$C$10)*(A13-$A$10)/($A$14-$A$10) -> -0.087506256 | G13: =-C13/A13 -> 0.031820457 | H13: =(B12/B13-1)/0.25 -> 0.034464216 | J13: =$J$1*0.25*B13 -> 0.0079366963 | K13: =H13*0.25*B13 -> 0.0078941419 | N13: =$N$1*0.25*B13 -> 0.0078533104 | O13: =B13*0.25*H13 -> 0.0078941419
A14: 3 | B14: 0.90838643 | C14: =LN(B14) -> -0.096085404 | D14: =(1-B14)/(SUM($B$3:B14) *0.25) -> 0.0321 | E14: =VLOOKUP(A14,Sheet1!$A$15:$B$25,2)/100 -> 0.0321 | F14: =D14-E14 -> 0 | G14: =-C14/A14 -> 0.032028468 | H14: =(B13/B14-1)/0.25 -> 0.034464216 | J14: =$J$1*0.25*B14 -> 0.0078688975 | K14: =H14*0.25*B14 -> 0.0078267066 | N14: =$N$1*0.25*B14 -> 0.0077862238 | O14: =B14*0.25*H14 -> 0.0078267066
A15: 3.25 | B15: =EXP(C15) -> 0.90049636 | C15: =$C$14+($C$18-$C$14)*(A15-$A$14)/($A$18-$A$14) -> -0.10480916 | G15: =-C15/A15 -> 0.032248972 | H15: =(B14/B15-1)/0.25 -> 0.035047673 | J15: =$J$1*0.25*B15 -> 0.0078005497 | K15: =H15*0.25*B15 -> 0.0078900756 | N15: =$N$1*0.25*B15 -> 0.0077185941 | O15: =B15*0.25*H15 -> 0.0078900756
A16: 3.5 | B16: =EXP(C16) -> 0.89267481 | C16: =$C$14+($C$18-$C$14)*(A16-$A$14)/($A$18-$A$14) -> -0.11353292 | G16: =-C16/A16 -> 0.032437976 | H16: =(B15/B16-1)/0.25 -> 0.035047673 | J16: =$J$1*0.25*B16 -> 0.0077327956 | K16: =H16*0.25*B16 -> 0.0078215438 | N16: =$N$1*0.25*B16 -> 0.0076515519 | O16: =B16*0.25*H16 -> 0.0078215438
A17: 3.75 | B17: =EXP(C17) -> 0.88492121 | C17: =$C$14+($C$18-$C$14)*(A17-$A$14)/($A$18-$A$14) -> -0.12225667 | G17: =-C17/A17 -> 0.032601779 | H17: =(B16/B17-1)/0.25 -> 0.035047673 | J17: =$J$1*0.25*B17 -> 0.0076656299 | K17: =H17*0.25*B17 -> 0.0077536073 | N17: =$N$1*0.25*B17 -> 0.0075850919 | O17: =B17*0.25*H17 -> 0.0077536073
A18: 4 | B18: 0.87723495 | C18: =LN(B18) -> -0.13098043 | D18: =(1-B18)/(SUM($B$3:B18) *0.25) -> 0.0328 | E18: =VLOOKUP(A18,Sheet1!$A$15:$B$25,2)/100 -> 0.0328 | F18: =D18-E18 -> 0 | G18: =-C18/A18 -> 0.032745107 | H18: =(B17/B18-1)/0.25 -> 0.035047673 | J18: =$J$1*0.25*B18 -> 0.0075990477 | K18: =H18*0.25*B18 -> 0.007686261 | N18: =$N$1*0.25*B18 -> 0.0075192092 | O18: =B18*0.25*H18 -> 0.007686261
A19: 4.25 | B19: =EXP(C19) -> 0.86946426 | C19: =$C$18+($C$22-$C$18)*(A19-$A$18)/($A$22-$A$18) -> -0.13987805 | G19: =-C19/A19 -> 0.032912483 | H19: =(B18/B19-1)/0.25 -> 0.035749312 | J19: =$J$1*0.25*B19 -> 0.0075317341 | K19: =H19*0.25*B19 -> 0.0077706872 | N19: =$N$1*0.25*B19 -> 0.0074526029 | O19: =B19*0.25*H19 -> 0.0077706872
A20: 4.5 | B20: =EXP(C20) -> 0.8617624 | C20: =$C$18+($C$22-$C$18)*(A20-$A$18)/($A$22-$A$18) -> -0.14877568 | G20: =-C20/A20 -> 0.033061262 | H20: =(B19/B20-1)/0.25 -> 0.035749312 | J20: =$J$1*0.25*B20 -> 0.0074650168 | K20: =H20*0.25*B20 -> 0.0077018532 | N20: =$N$1*0.25*B20 -> 0.0073865865 | O20: =B20*0.25*H20 -> 0.0077018532
A21: 4.75 | B21: =EXP(C21) -> 0.85412878 | C21: =$C$18+($C$22-$C$18)*(A21-$A$18)/($A$22-$A$18) -> -0.15767331 | G21: =-C21/A21 -> 0.03319438 | H21: =(B20/B21-1)/0.25 -> 0.035749312 | J21: =$J$1*0.25*B21 -> 0.0073988905 | K21: =H21*0.25*B21 -> 0.007633629 | N21: =$N$1*0.25*B21 -> 0.007321155 | O21: =B21*0.25*H21 -> 0.007633629
A22: 5 | B22: 0.84656277 | C22: =LN(B22) -> -0.16657093 | D22: =(1-B22)/(SUM($B$3:B22) *0.25) -> 0.03335 | E22: =VLOOKUP(A22,Sheet1!$A$15:$B$25,2)/100 -> 0.03335 | F22: =D22-E22 -> 0 | G22: =-C22/A22 -> 0.033314186 | H22: =(B21/B22-1)/0.25 -> 0.035749312 | J22: =$J$1*0.25*B22 -> 0.00733335 | K22: =H22*0.25*B22 -> 0.0075660091 | N22: =$N$1*0.25*B22 -> 0.007256303 | O22: =B22*0.25*H22 -> 0.0075660091
A23: 5.25 | B23: =EXP(C23) -> 0.83894558 | C23: =$C$22+($C$30-$C$22)*(A23-$A$22)/($A$30-$A$22) -> -0.17560944 | G23: =-C23/A23 -> 0.033449416 | H23: =(B22/B23-1)/0.25 -> 0.036317898 | J23: =$J$1*0.25*B23 -> 0.0072673661 | K23: =H23*0.25*B23 -> 0.0076171851 | N23: =$N$1*0.25*B23 -> 0.0071910124 | O23: =B23*0.25*H23 -> 0.0076171851
A24: 5.5 | B24: =EXP(C24) -> 0.83139693 | C24: =$C$22+($C$30-$C$22)*(A24-$A$22)/($A$30-$A$22) -> -0.18464794 | G24: =-C24/A24 -> 0.033572353 | H24: =(B23/B24-1)/0.25 -> 0.036317898 | J24: =$J$1*0.25*B24 -> 0.0072019759 | K24: =H24*0.25*B24 -> 0.0075486473 | N24: =$N$1*0.25*B24 -> 0.0071263092 | O24: =B24*0.25*H24 -> 0.0075486473
A25: 5.75 | B25: =EXP(C25) -> 0.82391621 | C25: =$C$22+($C$30-$C$22)*(A25-$A$22)/($A$30-$A$22) -> -0.19368644 | G25: =-C25/A25 -> 0.033684599 | H25: =(B24/B25-1)/0.25 -> 0.036317898 | J25: =$J$1*0.25*B25 -> 0.0071371742 | K25: =H25*0.25*B25 -> 0.0074807263 | N25: =$N$1*0.25*B25 -> 0.0070621883 | O25: =B25*0.25*H25 -> 0.0074807263
A26: 6 | B26: =EXP(C26) -> 0.81650279 | C26: =$C$22+($C$30-$C$22)*(A26-$A$22)/($A$30-$A$22) -> -0.20272495 | G26: =-C26/A26 -> 0.033787491 | H26: =(B25/B26-1)/0.25 -> 0.036317898 | J26: =$J$1*0.25*B26 -> 0.0070729554 | K26: =H26*0.25*B26 -> 0.0074134164 | N26: =$N$1*0.25*B26 -> 0.0069986443 | O26: =B26*0.25*H26 -> 0.0074134164
A27: 6.25 | B27: =EXP(C27) -> 0.80915608 | C27: =$C$22+($C$30-$C$22)*(A27-$A$22)/($A$30-$A$22) -> -0.21176345 | G27: =-C27/A27 -> 0.033882152 | H27: =(B26/B27-1)/0.25 -> 0.036317898 | J27: =$J$1*0.25*B27 -> 0.0070093145 | K27: =H27*0.25*B27 -> 0.0073467121 | N27: =$N$1*0.25*B27 -> 0.006935672 | O27: =B27*0.25*H27 -> 0.0073467121
A28: 6.5 | B28: =EXP(C28) -> 0.80187547 | C28: =$C$22+($C$30-$C$22)*(A28-$A$22)/($A$30-$A$22) -> -0.22080196 | G28: =-C28/A28 -> 0.033969532 | H28: =(B27/B28-1)/0.25 -> 0.036317898 | J28: =$J$1*0.25*B28 -> 0.0069462463 | K28: =H28*0.25*B28 -> 0.007280608 | N28: =$N$1*0.25*B28 -> 0.0068732664 | O28: =B28*0.25*H28 -> 0.007280608
A29: 6.75 | B29: =EXP(C29) -> 0.79466037 | C29: =$C$22+($C$30-$C$22)*(A29-$A$22)/($A$30-$A$22) -> -0.22984046 | G29: =-C29/A29 -> 0.034050438 | H29: =(B28/B29-1)/0.25 -> 0.036317898 | J29: =$J$1*0.25*B29 -> 0.0068837455 | K29: =H29*0.25*B29 -> 0.0072150987 | N29: =$N$1*0.25*B29 -> 0.0068114222 | O29: =B29*0.25*H29 -> 0.0072150987
A30: 7 | B30: 0.78751019 | C30: =LN(B30) -> -0.23887896 | D30: =(1-B30)/(SUM($B$3:B30) *0.25) -> 0.034125 | E30: =VLOOKUP(A30,Sheet1!$A$15:$B$25,2)/100 -> 0.034125 | F30: =D30-E30 -> 0 | G30: =-C30/A30 -> 0.034125566 | H30: =(B29/B30-1)/0.25 -> 0.036317898 | J30: =$J$1*0.25*B30 -> 0.0068218071 | K30: =H30*0.25*B30 -> 0.0071501788 | N30: =$N$1*0.25*B30 -> 0.0067501345 | O30: =B30*0.25*H30 -> 0.0071501788
A31: 7.25 | B31: =EXP(C31) -> 0.7803898 | C31: =$C$30+($C$42-$C$30)*(A31-$A$30)/($A$42-$A$30) -> -0.24796174 | G31: =-C31/A31 -> 0.034201619 | H31: =(B30/B31-1)/0.25 -> 0.036496604 | J31: =$J$1*0.25*B31 -> 0.0067601266 | K31: =H31*0.25*B31 -> 0.0071203944 | N31: =$N$1*0.25*B31 -> 0.0066891022 | O31: =B31*0.25*H31 -> 0.0071203944
A32: 7.5 | B32: =EXP(C32) -> 0.77333379 | C32: =$C$30+($C$42-$C$30)*(A32-$A$30)/($A$42-$A$30) -> -0.25704452 | G32: =-C32/A32 -> 0.034272602 | H32: =(B31/B32-1)/0.25 -> 0.036496604 | J32: =$J$1*0.25*B32 -> 0.0066990039 | K32: =H32*0.25*B32 -> 0.0070560142 | N32: =$N$1*0.25*B32 -> 0.0066286216 | O32: =B32*0.25*H32 -> 0.0070560142
A33: 7.75 | B33: =EXP(C33) -> 0.76634157 | C33: =$C$30+($C$42-$C$30)*(A33-$A$30)/($A$42-$A$30) -> -0.2661273 | G33: =-C33/A33 -> 0.034339006 | H33: =(B32/B33-1)/0.25 -> 0.036496604 | J33: =$J$1*0.25*B33 -> 0.0066384338 | K33: =H33*0.25*B33 -> 0.0069922162 | N33: =$N$1*0.25*B33 -> 0.0065686879 | O33: =B33*0.25*H33 -> 0.0069922162
A34: 8 | B34: =EXP(C34) -> 0.75941257 | C34: =$C$30+($C$42-$C$30)*(A34-$A$30)/($A$42-$A$30) -> -0.27521007 | G34: =-C34/A34 -> 0.034401259 | H34: =(B33/B34-1)/0.25 -> 0.036496604 | J34: =$J$1*0.25*B34 -> 0.0065784114 | K34: =H34*0.25*B34 -> 0.006928995 | N34: =$N$1*0.25*B34 -> 0.0065092961 | O34: =B34*0.25*H34 -> 0.006928995
A35: 8.25 | B35: =EXP(C35) -> 0.75254623 | C35: =$C$30+($C$42-$C$30)*(A35-$A$30)/($A$42-$A$30) -> -0.28429285 | G35: =-C35/A35 -> 0.034459739 | H35: =(B34/B35-1)/0.25 -> 0.036496604 | J35: =$J$1*0.25*B35 -> 0.0065189317 | K35: =H35*0.25*B35 -> 0.0068663454 | M35: Total | N35: =SUM(N3:N34) -> 0.23988774 | O35: =SUM(O3:O34) -> 0.24058743
A36: 8.5 | B36: =EXP(C36) -> 0.74574197 | C36: =$C$30+($C$42-$C$30)*(A36-$A$30)/($A$42-$A$30) -> -0.29337563 | G36: =-C36/A36 -> 0.03451478 | H36: =(B35/B36-1)/0.25 -> 0.036496604 | J36: =$J$1*0.25*B36 -> 0.0064599898 | K36: =H36*0.25*B36 -> 0.0068042623
A37: 8.75 | B37: =EXP(C37) -> 0.73899923 | C37: =$C$30+($C$42-$C$30)*(A37-$A$30)/($A$42-$A$30) -> -0.30245841 | G37: =-C37/A37 -> 0.034566675 | H37: =(B36/B37-1)/0.25 -> 0.036496604 | J37: =$J$1*0.25*B37 -> 0.0064015808 | K37: =H37*0.25*B37 -> 0.0067427405
A38: 9 | B38: =EXP(C38) -> 0.73231745 | C38: =$C$30+($C$42-$C$30)*(A38-$A$30)/($A$42-$A$30) -> -0.31154118 | G38: =-C38/A38 -> 0.034615687 | H38: =(B37/B38-1)/0.25 -> 0.036496604 | J38: =$J$1*0.25*B38 -> 0.0063436999 | K38: =H38*0.25*B38 -> 0.006681775
A39: 9.25 | B39: =EXP(C39) -> 0.72569609 | C39: =$C$30+($C$42-$C$30)*(A39-$A$30)/($A$42-$A$30) -> -0.32062396 | G39: =-C39/A39 -> 0.03466205 | H39: =(B38/B39-1)/0.25 -> 0.036496604 | J39: =$J$1*0.25*B39 -> 0.0062863424 | K39: =H39*0.25*B39 -> 0.0066213607
A40: 9.5 | B40: =EXP(C40) -> 0.7191346 | C40: =$C$30+($C$42-$C$30)*(A40-$A$30)/($A$42-$A$30) -> -0.32970674 | G40: =-C40/A40 -> 0.034705972 | H40: =(B39/B40-1)/0.25 -> 0.036496604 | J40: =$J$1*0.25*B40 -> 0.0062295035 | K40: =H40*0.25*B40 -> 0.0065614927
...

Sheet 1Y duration
A1: Bootstraping | I1: Swap rate | J1: =Sheet1!B9/100 -> 0.03465 | M1: 8Y swap | N1: =Sheet1!C33 -> 0.034285954
A2: Maturity | B2: DF | C2: LN(DF) | D2: 이론 rate | E2: 실제 rate | F2: error | G2: spot curve | H2: forward curve | J2: fixed leg | K2: floating leg | N2: fixed | O2: floating
A3: {=_xlfn.SEQUENCE(40,,0.25,0.25)} -> 0.25 | B3: =1/(1+Sheet1!B2/100*0.25) -> 0.99304866 | C3: =LN(B3) -> -0.0069756137 | G3: =-C3/A3 -> 0.027902455 | H3: =(1/B3-1)/0.25 -> 0.028 | J3: =$J$1*0.25*B3 -> 0.008602284 | K3: =H3*0.25*B3 -> 0.0069513406 | N3: =$N$1*0.25*B3 -> 0.0085119051 | O3: =B3*0.25*H3 -> 0.0069513406
A4: 0.5 | B4: =EXP(C4) -> 0.98572807 | C4: =$C$3+($C$6-$C$3)*(A4-$A$3)/($A$6-$A$3) -> -0.014374754 | G4: =-C4/A4 -> 0.028749509 | H4: =(B3/B4-1)/0.25 -> 0.029706328 | J4: =$J$1*0.25*B4 -> 0.0085388694 | K4: =H4*0.25*B4 -> 0.0073205904 | N4: =$N$1*0.25*B4 -> 0.0084491568 | O4: =B4*0.25*H4 -> 0.0073205904
A5: 0.75 | B5: =EXP(C5) -> 0.97846144 | C5: =$C$3+($C$6-$C$3)*(A5-$A$3)/($A$6-$A$3) -> -0.021773895 | G5: =-C5/A5 -> 0.02903186 | H5: =(B4/B5-1)/0.25 -> 0.029706328 | J5: =$J$1*0.25*B5 -> 0.0084759223 | K5: =H5*0.25*B5 -> 0.0072666242 | N5: =$N$1*0.25*B5 -> 0.008386871 | O5: =B5*0.25*H5 -> 0.0072666242
A6: 1 | B6: 0.97124839 | C6: =LN(B6) -> -0.029173036 | D6: =(1-B6)/(SUM($B$3:B6) *0.25) -> 0.029275 | E6: =VLOOKUP(A6,Sheet1!$D$15:$E$25,2)/100 -> 0.029275 | F6: =D6-E6 -> 0 | G6: =-C6/A6 -> 0.029173036 | H6: =(B5/B6-1)/0.25 -> 0.029706328 | J6: =$J$1*0.25*B6 -> 0.0084134392 | K6: =H6*0.25*B6 -> 0.0072130558 | N6: =$N$1*0.25*B6 -> 0.0083250444 | O6: =B6*0.25*H6 -> 0.0072130558
A7: 1.25 | B7: =EXP(C7) -> 0.9634144 | C7: =$C$6+($C$10-$C$6)*(A7-$A$6)/($A$10-$A$6) -> -0.037271638 | G7: =-C7/A7 -> 0.02981731 | H7: =(B6/B7-1)/0.25 -> 0.032525935 | J7: =$J$1*0.25*B7 -> 0.0083455772 | K7: =H7*0.25*B7 -> 0.0078339887 | N7: =$N$1*0.25*B7 -> 0.0082578954 | O7: =B7*0.25*H7 -> 0.0078339887
A8: 1.5 | B8: =EXP(C8) -> 0.9556436 | C8: =$C$6+($C$10-$C$6)*(A8-$A$6)/($A$10-$A$6) -> -0.045370239 | G8: =-C8/A8 -> 0.030246826 | H8: =(B7/B8-1)/0.25 -> 0.032525935 | J8: =$J$1*0.25*B8 -> 0.0082782627 | K8: =H8*0.25*B8 -> 0.0077708005 | N8: =$N$1*0.25*B8 -> 0.0081912881 | O8: =B8*0.25*H8 -> 0.0077708005
A9: 1.75 | B9: =EXP(C9) -> 0.94793548 | C9: =$C$6+($C$10-$C$6)*(A9-$A$6)/($A$10-$A$6) -> -0.05346884 | G9: =-C9/A9 -> 0.030553623 | H9: =(B8/B9-1)/0.25 -> 0.032525935 | J9: =$J$1*0.25*B9 -> 0.0082114911 | K9: =H9*0.25*B9 -> 0.007708122 | N9: =$N$1*0.25*B9 -> 0.008125218 | O9: =B9*0.25*H9 -> 0.007708122
A10: 2 | B10: 0.94028953 | C10: =LN(B10) -> -0.061567442 | D10: =(1-B10)/(SUM($B$3:B10) *0.25) -> 0.030875 | E10: =VLOOKUP(A10,Sheet1!$D$15:$E$25,2)/100 -> 0.030875 | F10: =D10-E10 -> 0 | G10: =-C10/A10 -> 0.030783721 | H10: =(B9/B10-1)/0.25 -> 0.032525935 | J10: =$J$1*0.25*B10 -> 0.008145258 | K10: =H10*0.25*B10 -> 0.0076459491 | N10: =$N$1*0.25*B10 -> 0.0080596809 | O10: =B10*0.25*H10 -> 0.0076459491
A11: 2.25 | B11: =EXP(C11) -> 0.93228037 | C11: =$C$10+($C$14-$C$10)*(A11-$A$10)/($A$14-$A$10) -> -0.070121688 | G11: =-C11/A11 -> 0.031165195 | H11: =(B10/B11-1)/0.25 -> 0.034363754 | J11: =$J$1*0.25*B11 -> 0.0080758787 | K11: =H11*0.25*B11 -> 0.0080091632 | N11: =$N$1*0.25*B11 -> 0.0079910304 | O11: =B11*0.25*H11 -> 0.0080091632
A12: 2.5 | B12: =EXP(C12) -> 0.92433942 | C12: =$C$10+($C$14-$C$10)*(A12-$A$10)/($A$14-$A$10) -> -0.078675935 | G12: =-C12/A12 -> 0.031470374 | H12: =(B11/B12-1)/0.25 -> 0.034363754 | J12: =$J$1*0.25*B12 -> 0.0080070902 | K12: =H12*0.25*B12 -> 0.0079409431 | N12: =$N$1*0.25*B12 -> 0.0079229647 | O12: =B12*0.25*H12 -> 0.0079409431
A13: 2.75 | B13: =EXP(C13) -> 0.91646612 | C13: =$C$10+($C$14-$C$10)*(A13-$A$10)/($A$14-$A$10) -> -0.087230181 | G13: =-C13/A13 -> 0.031720066 | H13: =(B12/B13-1)/0.25 -> 0.034363754 | J13: =$J$1*0.25*B13 -> 0.0079388877 | K13: =H13*0.25*B13 -> 0.007873304 | N13: =$N$1*0.25*B13 -> 0.0078554788 | O13: =B13*0.25*H13 -> 0.007873304
A14: 3 | B14: 0.90865988 | C14: =LN(B14) -> -0.095784427 | D14: =(1-B14)/(SUM($B$3:B14) *0.25) -> 0.032 | E14: =VLOOKUP(A14,Sheet1!$D$15:$E$25,2)/100 -> 0.032 | F14: =D14-E14 -> 0 | G14: =-C14/A14 -> 0.031928142 | H14: =(B13/B14-1)/0.25 -> 0.034363754 | J14: =$J$1*0.25*B14 -> 0.0078712662 | K14: =H14*0.25*B14 -> 0.0078062411 | N14: =$N$1*0.25*B14 -> 0.0077885677 | O14: =B14*0.25*H14 -> 0.0078062411
A15: 3.25 | B15: =EXP(C15) -> 0.90078987 | C15: =$C$14+($C$18-$C$14)*(A15-$A$14)/($A$18-$A$14) -> -0.10448327 | G15: =-C15/A15 -> 0.032148699 | H15: =(B14/B15-1)/0.25 -> 0.034947152 | J15: =$J$1*0.25*B15 -> 0.0078030922 | K15: =H15*0.25*B15 -> 0.0078700101 | N15: =$N$1*0.25*B15 -> 0.00772111 | O15: =B15*0.25*H15 -> 0.0078700101
A16: 3.5 | B16: =EXP(C16) -> 0.89298802 | C16: =$C$14+($C$18-$C$14)*(A16-$A$14)/($A$18-$A$14) -> -0.11318211 | G16: =-C16/A16 -> 0.032337747 | H16: =(B15/B16-1)/0.25 -> 0.034947152 | J16: =$J$1*0.25*B16 -> 0.0077355087 | K16: =H16*0.25*B16 -> 0.007801847 | N16: =$N$1*0.25*B16 -> 0.0076542365 | O16: =B16*0.25*H16 -> 0.007801847
A17: 3.75 | B17: =EXP(C17) -> 0.88525375 | C17: =$C$14+($C$18-$C$14)*(A17-$A$14)/($A$18-$A$14) -> -0.12188096 | G17: =-C17/A17 -> 0.032501588 | H17: =(B16/B17-1)/0.25 -> 0.034947152 | J17: =$J$1*0.25*B17 -> 0.0076685106 | K17: =H17*0.25*B17 -> 0.0077342743 | N17: =$N$1*0.25*B17 -> 0.0075879423 | O17: =B17*0.25*H17 -> 0.0077342743
A18: 4 | B18: 0.87758646 | C18: =LN(B18) -> -0.1305798 | D18: =(1-B18)/(SUM($B$3:B18) *0.25) -> 0.0327 | E18: =VLOOKUP(A18,Sheet1!$D$15:$E$25,2)/100 -> 0.0327 | F18: =D18-E18 -> 0 | G18: =-C18/A18 -> 0.03264495 | H18: =(B17/B18-1)/0.25 -> 0.034947152 | J18: =$J$1*0.25*B18 -> 0.0076020927 | K18: =H18*0.25*B18 -> 0.0076672868 | N18: =$N$1*0.25*B18 -> 0.0075222222 | O18: =B18*0.25*H18 -> 0.0076672868
A19: 4.25 | B19: =EXP(C19) -> 0.86983435 | C19: =$C$18+($C$22-$C$18)*(A19-$A$18)/($A$22-$A$18) -> -0.13945248 | G19: =-C19/A19 -> 0.032812349 | H19: =(B18/B19-1)/0.25 -> 0.035648648 | J19: =$J$1*0.25*B19 -> 0.0075349401 | K19: =H19*0.25*B19 -> 0.0077521047 | N19: =$N$1*0.25*B19 -> 0.0074557751 | O19: =B19*0.25*H19 -> 0.0077521047
A20: 4.5 | B20: =EXP(C20) -> 0.86215073 | C20: =$C$18+($C$22-$C$18)*(A20-$A$18)/($A$22-$A$18) -> -0.14832517 | G20: =-C20/A20 -> 0.032961148 | H20: =(B19/B20-1)/0.25 -> 0.035648648 | J20: =$J$1*0.25*B20 -> 0.0074683807 | K20: =H20*0.25*B20 -> 0.0076836269 | N20: =$N$1*0.25*B20 -> 0.007389915 | O20: =B20*0.25*H20 -> 0.0076836269
A21: 4.75 | B21: =EXP(C21) -> 0.85453497 | C21: =$C$18+($C$22-$C$18)*(A21-$A$18)/($A$22-$A$18) -> -0.15719785 | G21: =-C21/A21 -> 0.033094284 | H21: =(B20/B21-1)/0.25 -> 0.035648648 | J21: =$J$1*0.25*B21 -> 0.0074024092 | K21: =H21*0.25*B21 -> 0.0076157541 | N21: =$N$1*0.25*B21 -> 0.0073246367 | O21: =B21*0.25*H21 -> 0.0076157541
A22: 5 | B22: 0.84698649 | C22: =LN(B22) -> -0.16607053 | D22: =(1-B22)/(SUM($B$3:B22) *0.25) -> 0.03325 | E22: =VLOOKUP(A22,Sheet1!$D$15:$E$25,2)/100 -> 0.03325 | F22: =D22-E22 -> 0 | G22: =-C22/A22 -> 0.033214106 | H22: =(B21/B22-1)/0.25 -> 0.035648648 | J22: =$J$1*0.25*B22 -> 0.0073370205 | K22: =H22*0.25*B22 -> 0.0075484808 | N22: =$N$1*0.25*B22 -> 0.007259935 | O22: =B22*0.25*H22 -> 0.0075484808
A23: 5.25 | B23: =EXP(C23) -> 0.83938646 | C23: =$C$22+($C$30-$C$22)*(A23-$A$22)/($A$30-$A$22) -> -0.17508406 | G23: =-C23/A23 -> 0.033349344 | H23: =(B22/B23-1)/0.25 -> 0.036217078 | J23: =$J$1*0.25*B23 -> 0.0072711852 | K23: =H23*0.25*B23 -> 0.0076000313 | N23: =$N$1*0.25*B23 -> 0.0071947914 | O23: =B23*0.25*H23 -> 0.0076000313
A24: 5.5 | B24: =EXP(C24) -> 0.83185463 | C24: =$C$22+($C$30-$C$22)*(A24-$A$22)/($A$30-$A$22) -> -0.18409758 | G24: =-C24/A24 -> 0.033472288 | H24: =(B23/B24-1)/0.25 -> 0.036217078 | J24: =$J$1*0.25*B24 -> 0.0072059407 | K24: =H24*0.25*B24 -> 0.007531836 | N24: =$N$1*0.25*B24 -> 0.0071302323 | O24: =B24*0.25*H24 -> 0.007531836
A25: 5.75 | B25: =EXP(C25) -> 0.82439037 | C25: =$C$22+($C$30-$C$22)*(A25-$A$22)/($A$30-$A$22) -> -0.19311111 | G25: =-C25/A25 -> 0.033584541 | H25: =(B24/B25-1)/0.25 -> 0.036217078 | J25: =$J$1*0.25*B25 -> 0.0071412816 | K25: =H25*0.25*B25 -> 0.0074642527 | N25: =$N$1*0.25*B25 -> 0.0070662526 | O25: =B25*0.25*H25 -> 0.0074642527
A26: 6 | B26: =EXP(C26) -> 0.8169931 | C26: =$C$22+($C$30-$C$22)*(A26-$A$22)/($A$30-$A$22) -> -0.20212463 | G26: =-C26/A26 -> 0.033687439 | H26: =(B25/B26-1)/0.25 -> 0.036217078 | J26: =$J$1*0.25*B26 -> 0.0070772027 | K26: =H26*0.25*B26 -> 0.0073972758 | N26: =$N$1*0.25*B26 -> 0.0070028469 | O26: =B26*0.25*H26 -> 0.0073972758
A27: 6.25 | B27: =EXP(C27) -> 0.8096622 | C27: =$C$22+($C$30-$C$22)*(A27-$A$22)/($A$30-$A$22) -> -0.21113816 | G27: =-C27/A27 -> 0.033782105 | H27: =(B26/B27-1)/0.25 -> 0.036217078 | J27: =$J$1*0.25*B27 -> 0.0070136988 | K27: =H27*0.25*B27 -> 0.0073308998 | N27: =$N$1*0.25*B27 -> 0.0069400102 | O27: =B27*0.25*H27 -> 0.0073308998
A28: 6.5 | B28: =EXP(C28) -> 0.80239708 | C28: =$C$22+($C$30-$C$22)*(A28-$A$22)/($A$30-$A$22) -> -0.22015168 | G28: =-C28/A28 -> 0.03386949 | H28: =(B27/B28-1)/0.25 -> 0.036217078 | J28: =$J$1*0.25*B28 -> 0.0069507647 | K28: =H28*0.25*B28 -> 0.0072651195 | N28: =$N$1*0.25*B28 -> 0.0068777373 | O28: =B28*0.25*H28 -> 0.0072651195
A29: 6.75 | B29: =EXP(C29) -> 0.79519715 | C29: =$C$22+($C$30-$C$22)*(A29-$A$22)/($A$30-$A$22) -> -0.22916521 | G29: =-C29/A29 -> 0.033950401 | H29: =(B28/B29-1)/0.25 -> 0.036217078 | J29: =$J$1*0.25*B29 -> 0.0068883953 | K29: =H29*0.25*B29 -> 0.0071999294 | N29: =$N$1*0.25*B29 -> 0.0068160232 | O29: =B29*0.25*H29 -> 0.0071999294
A30: 7 | B30: 0.78806182 | C30: =LN(B30) -> -0.23817874 | D30: =(1-B30)/(SUM($B$3:B30) *0.25) -> 0.034025 | E30: =VLOOKUP(A30,Sheet1!$D$15:$E$25,2)/100 -> 0.034025 | F30: =D30-E30 -> 0 | G30: =-C30/A30 -> 0.034025534 | H30: =(B29/B30-1)/0.25 -> 0.036217078 | J30: =$J$1*0.25*B30 -> 0.0068265855 | K30: =H30*0.25*B30 -> 0.0071353242 | N30: =$N$1*0.25*B30 -> 0.0067548628 | O30: =B30*0.25*H30 -> 0.0071353242
A31: 7.25 | B31: =EXP(C31) -> 0.78095597 | C31: =$C$30+($C$42-$C$30)*(A31-$A$30)/($A$42-$A$30) -> -0.24723651 | G31: =-C31/A31 -> 0.034101588 | H31: =(B30/B31-1)/0.25 -> 0.036395688 | J31: =$J$1*0.25*B31 -> 0.0067650311 | K31: =H31*0.25*B31 -> 0.0071058574 | N31: =$N$1*0.25*B31 -> 0.0066939551 | O31: =B31*0.25*H31 -> 0.0071058574
A32: 7.5 | B32: =EXP(C32) -> 0.77391418 | C32: =$C$30+($C$42-$C$30)*(A32-$A$30)/($A$42-$A$30) -> -0.25629429 | G32: =-C32/A32 -> 0.034172572 | H32: =(B31/B32-1)/0.25 -> 0.036395688 | J32: =$J$1*0.25*B32 -> 0.0067040316 | K32: =H32*0.25*B32 -> 0.0070417847 | N32: =$N$1*0.25*B32 -> 0.0066335965 | O32: =B32*0.25*H32 -> 0.0070417847
A33: 7.75 | B33: =EXP(C33) -> 0.76693589 | C33: =$C$30+($C$42-$C$30)*(A33-$A$30)/($A$42-$A$30) -> -0.26535206 | G33: =-C33/A33 -> 0.034238976 | H33: =(B32/B33-1)/0.25 -> 0.036395688 | J33: =$J$1*0.25*B33 -> 0.0066435822 | K33: =H33*0.25*B33 -> 0.0069782898 | N33: =$N$1*0.25*B33 -> 0.0065737822 | O33: =B33*0.25*H33 -> 0.0069782898
A34: 8 | B34: =EXP(C34) -> 0.76002052 | C34: =$C$30+($C$42-$C$30)*(A34-$A$30)/($A$42-$A$30) -> -0.27440984 | G34: =-C34/A34 -> 0.03430123 | H34: =(B33/B34-1)/0.25 -> 0.036395688 | J34: =$J$1*0.25*B34 -> 0.0065836778 | K34: =H34*0.25*B34 -> 0.0069153674 | N34: =$N$1*0.25*B34 -> 0.0065145072 | O34: =B34*0.25*H34 -> 0.0069153674
A35: 8.25 | B35: =EXP(C35) -> 0.75316751 | C35: =$C$30+($C$42-$C$30)*(A35-$A$30)/($A$42-$A$30) -> -0.28346762 | G35: =-C35/A35 -> 0.034359711 | H35: =(B34/B35-1)/0.25 -> 0.036395688 | J35: =$J$1*0.25*B35 -> 0.0065243136 | K35: =H35*0.25*B35 -> 0.0068530124 | M35: Total | N35: =SUM(N3:N34) -> 0.23997947 | O35: =SUM(O3:O34) -> 0.23997948
A36: 8.5 | B36: =EXP(C36) -> 0.74637629 | C36: =$C$30+($C$42-$C$30)*(A36-$A$30)/($A$42-$A$30) -> -0.29252539 | G36: =-C36/A36 -> 0.034414752 | H36: =(B35/B36-1)/0.25 -> 0.036395688 | J36: =$J$1*0.25*B36 -> 0.0064654846 | K36: =H36*0.25*B36 -> 0.0067912196
A37: 8.75 | B37: =EXP(C37) -> 0.73964631 | C37: =$C$30+($C$42-$C$30)*(A37-$A$30)/($A$42-$A$30) -> -0.30158317 | G37: =-C37/A37 -> 0.034466648 | H37: =(B36/B37-1)/0.25 -> 0.036395688 | J37: =$J$1*0.25*B37 -> 0.0064071861 | K37: =H37*0.25*B37 -> 0.006729984
A38: 9 | B38: =EXP(C38) -> 0.73297701 | C38: =$C$30+($C$42-$C$30)*(A38-$A$30)/($A$42-$A$30) -> -0.31064094 | G38: =-C38/A38 -> 0.034515661 | H38: =(B37/B38-1)/0.25 -> 0.036395688 | J38: =$J$1*0.25*B38 -> 0.0063494133 | K38: =H38*0.25*B38 -> 0.0066693006
A39: 9.25 | B39: =EXP(C39) -> 0.72636784 | C39: =$C$30+($C$42-$C$30)*(A39-$A$30)/($A$42-$A$30) -> -0.31969872 | G39: =-C39/A39 -> 0.034562024 | H39: =(B38/B39-1)/0.25 -> 0.036395688 | J39: =$J$1*0.25*B39 -> 0.0062921614 | K39: =H39*0.25*B39 -> 0.0066091643
A40: 9.5 | B40: =EXP(C40) -> 0.71981827 | C40: =$C$30+($C$42-$C$30)*(A40-$A$30)/($A$42-$A$30) -> -0.3287565 | G40: =-C40/A40 -> 0.034605947 | H40: =(B39/B40-1)/0.25 -> 0.036395688 | J40: =$J$1*0.25*B40 -> 0.0062354258 | K40: =H40*0.25*B40 -> 0.0065495703
...

Sheet 2Y duration
A1: Bootstraping | I1: Swap rate | J1: =Sheet1!B9/100 -> 0.03465 | M1: 8Y swap | N1: =Sheet1!C33 -> 0.034285954
A2: Maturity | B2: DF | C2: LN(DF) | D2: 이론 rate | E2: 실제 rate | F2: error | G2: spot curve | H2: forward curve | J2: fixed leg | K2: floating leg | N2: fixed | O2: floating
A3: {=_xlfn.SEQUENCE(40,,0.25,0.25)} -> 0.25 | B3: =1/(1+Sheet1!B2/100*0.25) -> 0.99304866 | C3: =LN(B3) -> -0.0069756137 | G3: =-C3/A3 -> 0.027902455 | H3: =(1/B3-1)/0.25 -> 0.028 | J3: =$J$1*0.25*B3 -> 0.008602284 | K3: =H3*0.25*B3 -> 0.0069513406 | N3: =$N$1*0.25*B3 -> 0.0085119051 | O3: =B3*0.25*H3 -> 0.0069513406
A4: 0.5 | B4: =EXP(C4) -> 0.98576081 | C4: =$C$3+($C$6-$C$3)*(A4-$A$3)/($A$6-$A$3) -> -0.014341537 | G4: =-C4/A4 -> 0.028683073 | H4: =(B3/B4-1)/0.25 -> 0.029572472 | J4: =$J$1*0.25*B4 -> 0.008539153 | K4: =H4*0.25*B4 -> 0.0072878461 | N4: =$N$1*0.25*B4 -> 0.0084494374 | O4: =B4*0.25*H4 -> 0.0072878461
A5: 0.75 | B5: =EXP(C5) -> 0.97852645 | C5: =$C$3+($C$6-$C$3)*(A5-$A$3)/($A$6-$A$3) -> -0.02170746 | G5: =-C5/A5 -> 0.028943279 | H5: =(B4/B5-1)/0.25 -> 0.029572472 | J5: =$J$1*0.25*B5 -> 0.0084764854 | K5: =H5*0.25*B5 -> 0.0072343616 | N5: =$N$1*0.25*B5 -> 0.0083874282 | O5: =B5*0.25*H5 -> 0.0072343616
A6: 1 | B6: 0.97134518 | C6: =LN(B6) -> -0.029073382 | D6: =(1-B6)/(SUM($B$3:B6) *0.25) -> 0.029175 | E6: =VLOOKUP(A6,Sheet1!$G$15:$H$25,2)/100 -> 0.029175 | F6: =D6-E6 -> 4.510281e-17 | G6: =-C6/A6 -> 0.029073382 | H6: =(B5/B6-1)/0.25 -> 0.029572472 | J6: =$J$1*0.25*B6 -> 0.0084142776 | K6: =H6*0.25*B6 -> 0.0071812696 | N6: =$N$1*0.25*B6 -> 0.008325874 | O6: =B6*0.25*H6 -> 0.0071812696
A7: 1.25 | B7: =EXP(C7) -> 0.96343715 | C7: =$C$6+($C$10-$C$6)*(A7-$A$6)/($A$10-$A$6) -> -0.037248019 | G7: =-C7/A7 -> 0.029798415 | H7: =(B6/B7-1)/0.25 -> 0.032832561 | J7: =$J$1*0.25*B7 -> 0.0083457744 | K7: =H7*0.25*B7 -> 0.0079080273 | N7: =$N$1*0.25*B7 -> 0.0082580905 | O7: =B7*0.25*H7 -> 0.0079080273
A8: 1.5 | B8: =EXP(C8) -> 0.95559351 | C8: =$C$6+($C$10-$C$6)*(A8-$A$6)/($A$10-$A$6) -> -0.045422656 | G8: =-C8/A8 -> 0.03028177 | H8: =(B7/B8-1)/0.25 -> 0.032832561 | J8: =$J$1*0.25*B8 -> 0.0082778288 | K8: =H8*0.25*B8 -> 0.0078436455 | N8: =$N$1*0.25*B8 -> 0.0081908587 | O8: =B8*0.25*H8 -> 0.0078436455
A9: 1.75 | B9: =EXP(C9) -> 0.94781372 | C9: =$C$6+($C$10-$C$6)*(A9-$A$6)/($A$10-$A$6) -> -0.053597292 | G9: =-C9/A9 -> 0.030627024 | H9: =(B8/B9-1)/0.25 -> 0.032832561 | J9: =$J$1*0.25*B9 -> 0.0082104364 | K9: =H9*0.25*B9 -> 0.0077797879 | N9: =$N$1*0.25*B9 -> 0.0081241744 | O9: =B9*0.25*H9 -> 0.0077797879
A10: 2 | B10: 0.94009727 | C10: =LN(B10) -> -0.061771929 | D10: =(1-B10)/(SUM($B$3:B10) *0.25) -> 0.030975 | E10: =VLOOKUP(A10,Sheet1!$G$15:$H$25,2)/100 -> 0.030975 | F10: =D10-E10 -> 0 | G10: =-C10/A10 -> 0.030885965 | H10: =(B9/B10-1)/0.25 -> 0.032832561 | J10: =$J$1*0.25*B10 -> 0.0081435926 | K10: =H10*0.25*B10 -> 0.0077164502 | N10: =$N$1*0.25*B10 -> 0.0080580329 | O10: =B10*0.25*H10 -> 0.0077164502
A11: 2.25 | B11: =EXP(C11) -> 0.93213826 | C11: =$C$10+($C$14-$C$10)*(A11-$A$10)/($A$14-$A$10) -> -0.070274123 | G11: =-C11/A11 -> 0.031232944 | H11: =(B10/B11-1)/0.25 -> 0.034153763 | J11: =$J$1*0.25*B11 -> 0.0080746477 | K11: =H11*0.25*B11 -> 0.0079590073 | N11: =$N$1*0.25*B11 -> 0.0079898124 | O11: =B11*0.25*H11 -> 0.0079590073
A12: 2.5 | B12: =EXP(C12) -> 0.92424664 | C12: =$C$10+($C$14-$C$10)*(A12-$A$10)/($A$14-$A$10) -> -0.078776318 | G12: =-C12/A12 -> 0.031510527 | H12: =(B11/B12-1)/0.25 -> 0.034153763 | J12: =$J$1*0.25*B12 -> 0.0080062865 | K12: =H12*0.25*B12 -> 0.0078916251 | N12: =$N$1*0.25*B12 -> 0.0079221694 | O12: =B12*0.25*H12 -> 0.0078916251
A13: 2.75 | B13: =EXP(C13) -> 0.91642183 | C13: =$C$10+($C$14-$C$10)*(A13-$A$10)/($A$14-$A$10) -> -0.087278512 | G13: =-C13/A13 -> 0.031737641 | H13: =(B12/B13-1)/0.25 -> 0.034153763 | J13: =$J$1*0.25*B13 -> 0.0079385041 | K13: =H13*0.25*B13 -> 0.0078248134 | N13: =$N$1*0.25*B13 -> 0.0078550991 | O13: =B13*0.25*H13 -> 0.0078248134
A14: 3 | B14: 0.90866326 | C14: =LN(B14) -> -0.095780707 | D14: =(1-B14)/(SUM($B$3:B14) *0.25) -> 0.032 | E14: =VLOOKUP(A14,Sheet1!$G$15:$H$25,2)/100 -> 0.032 | F14: =D14-E14 -> 0 | G14: =-C14/A14 -> 0.031926902 | H14: =(B13/B14-1)/0.25 -> 0.034153763 | J14: =$J$1*0.25*B14 -> 0.0078712955 | K14: =H14*0.25*B14 -> 0.0077585674 | N14: =$N$1*0.25*B14 -> 0.0077885966 | O14: =B14*0.25*H14 -> 0.0077585674
A15: 3.25 | B15: =EXP(C15) -> 0.90079324 | C15: =$C$14+($C$18-$C$14)*(A15-$A$14)/($A$18-$A$14) -> -0.10447953 | G15: =-C15/A15 -> 0.032147547 | H15: =(B14/B15-1)/0.25 -> 0.03494706 | J15: =$J$1*0.25*B15 -> 0.0078031214 | K15: =H15*0.25*B15 -> 0.0078700189 | N15: =$N$1*0.25*B15 -> 0.0077211389 | O15: =B15*0.25*H15 -> 0.0078700189
A16: 3.5 | B16: =EXP(C16) -> 0.89299138 | C16: =$C$14+($C$18-$C$14)*(A16-$A$14)/($A$18-$A$14) -> -0.11317835 | G16: =-C16/A16 -> 0.032336671 | H16: =(B15/B16-1)/0.25 -> 0.03494706 | J16: =$J$1*0.25*B16 -> 0.0077355379 | K16: =H16*0.25*B16 -> 0.0078018559 | N16: =$N$1*0.25*B16 -> 0.0076542653 | O16: =B16*0.25*H16 -> 0.0078018559
A17: 3.75 | B17: =EXP(C17) -> 0.8852571 | C17: =$C$14+($C$18-$C$14)*(A17-$A$14)/($A$18-$A$14) -> -0.12187717 | G17: =-C17/A17 -> 0.032500578 | H17: =(B16/B17-1)/0.25 -> 0.03494706 | J17: =$J$1*0.25*B17 -> 0.0076685396 | K17: =H17*0.25*B17 -> 0.0077342833 | N17: =$N$1*0.25*B17 -> 0.007587971 | O17: =B17*0.25*H17 -> 0.0077342833
A18: 4 | B18: 0.8775898 | C18: =LN(B18) -> -0.13057599 | D18: =(1-B18)/(SUM($B$3:B18) *0.25) -> 0.0327 | E18: =VLOOKUP(A18,Sheet1!$G$15:$H$25,2)/100 -> 0.0327 | F18: =D18-E18 -> 0 | G18: =-C18/A18 -> 0.032643997 | H18: =(B17/B18-1)/0.25 -> 0.03494706 | J18: =$J$1*0.25*B18 -> 0.0076021217 | K18: =H18*0.25*B18 -> 0.0076672959 | N18: =$N$1*0.25*B18 -> 0.0075222509 | O18: =B18*0.25*H18 -> 0.0076672959
A19: 4.25 | B19: =EXP(C19) -> 0.86983769 | C19: =$C$18+($C$22-$C$18)*(A19-$A$18)/($A$22-$A$18) -> -0.13944865 | G19: =-C19/A19 -> 0.032811448 | H19: =(B18/B19-1)/0.25 -> 0.035648573 | J19: =$J$1*0.25*B19 -> 0.007534969 | K19: =H19*0.25*B19 -> 0.0077521181 | N19: =$N$1*0.25*B19 -> 0.0074558037 | O19: =B19*0.25*H19 -> 0.0077521181
A20: 4.5 | B20: =EXP(C20) -> 0.86215405 | C20: =$C$18+($C$22-$C$18)*(A20-$A$18)/($A$22-$A$18) -> -0.14832132 | G20: =-C20/A20 -> 0.032960293 | H20: =(B19/B20-1)/0.25 -> 0.035648573 | J20: =$J$1*0.25*B20 -> 0.0074684094 | K20: =H20*0.25*B20 -> 0.0076836404 | N20: =$N$1*0.25*B20 -> 0.0073899435 | O20: =B20*0.25*H20 -> 0.0076836404
A21: 4.75 | B21: =EXP(C21) -> 0.85453828 | C21: =$C$18+($C$22-$C$18)*(A21-$A$18)/($A$22-$A$18) -> -0.15719398 | G21: =-C21/A21 -> 0.03309347 | H21: =(B20/B21-1)/0.25 -> 0.035648573 | J21: =$J$1*0.25*B21 -> 0.0074024378 | K21: =H21*0.25*B21 -> 0.0076157676 | N21: =$N$1*0.25*B21 -> 0.007324665 | O21: =B21*0.25*H21 -> 0.0076157676
A22: 5 | B22: 0.84698978 | C22: =LN(B22) -> -0.16606665 | D22: =(1-B22)/(SUM($B$3:B22) *0.25) -> 0.03325 | E22: =VLOOKUP(A22,Sheet1!$G$15:$H$25,2)/100 -> 0.03325 | F22: =D22-E22 -> 0 | G22: =-C22/A22 -> 0.033213329 | H22: =(B21/B22-1)/0.25 -> 0.035648573 | J22: =$J$1*0.25*B22 -> 0.007337049 | K22: =H22*0.25*B22 -> 0.0075484943 | N22: =$N$1*0.25*B22 -> 0.0072599632 | O22: =B22*0.25*H22 -> 0.0075484943
A23: 5.25 | B23: =EXP(C23) -> 0.83938973 | C23: =$C$22+($C$30-$C$22)*(A23-$A$22)/($A$30-$A$22) -> -0.17508016 | G23: =-C23/A23 -> 0.033348601 | H23: =(B22/B23-1)/0.25 -> 0.036217023 | J23: =$J$1*0.25*B23 -> 0.0072712136 | K23: =H23*0.25*B23 -> 0.0076000493 | N23: =$N$1*0.25*B23 -> 0.0071948194 | O23: =B23*0.25*H23 -> 0.0076000493
A24: 5.5 | B24: =EXP(C24) -> 0.83185788 | C24: =$C$22+($C$30-$C$22)*(A24-$A$22)/($A$30-$A$22) -> -0.18409367 | G24: =-C24/A24 -> 0.033471576 | H24: =(B23/B24-1)/0.25 -> 0.036217023 | J24: =$J$1*0.25*B24 -> 0.0072059689 | K24: =H24*0.25*B24 -> 0.0075318539 | N24: =$N$1*0.25*B24 -> 0.0071302602 | O24: =B24*0.25*H24 -> 0.0075318539
A25: 5.75 | B25: =EXP(C25) -> 0.82439361 | C25: =$C$22+($C$30-$C$22)*(A25-$A$22)/($A$30-$A$22) -> -0.19310718 | G25: =-C25/A25 -> 0.033583858 | H25: =(B24/B25-1)/0.25 -> 0.036217023 | J25: =$J$1*0.25*B25 -> 0.0071413096 | K25: =H25*0.25*B25 -> 0.0074642705 | N25: =$N$1*0.25*B25 -> 0.0070662803 | O25: =B25*0.25*H25 -> 0.0074642705
A26: 6 | B26: =EXP(C26) -> 0.81699632 | C26: =$C$22+($C$30-$C$22)*(A26-$A$22)/($A$30-$A$22) -> -0.20212069 | G26: =-C26/A26 -> 0.033686782 | H26: =(B25/B26-1)/0.25 -> 0.036217023 | J26: =$J$1*0.25*B26 -> 0.0070772306 | K26: =H26*0.25*B26 -> 0.0073972935 | N26: =$N$1*0.25*B26 -> 0.0070028745 | O26: =B26*0.25*H26 -> 0.0073972935
A27: 6.25 | B27: =EXP(C27) -> 0.8096654 | C27: =$C$22+($C$30-$C$22)*(A27-$A$22)/($A$30-$A$22) -> -0.2111342 | G27: =-C27/A27 -> 0.033781473 | H27: =(B26/B27-1)/0.25 -> 0.036217023 | J27: =$J$1*0.25*B27 -> 0.0070137265 | K27: =H27*0.25*B27 -> 0.0073309175 | N27: =$N$1*0.25*B27 -> 0.0069400376 | O27: =B27*0.25*H27 -> 0.0073309175
