Workbook

Sheet Sheet1
A1: IRS tenor | C1: http://www.smbs.biz/Exchange/IRS.jsp | G1: 3개월=CD
A2: 0.25 | D2: 1. 위의 링크와 CD금리를 통해 앞의 tenor를 채워주세요
A3: 1 | D3: > 2월 26일 기준 금리로 답안이 게시될 예정입니다.
A4: 2 | T4: S
A5: 3 | D5: 2. 10년 만기 fixed rate 3.7%를 지급하는 IRS가 있다고 할때 해당 상품의 값을 구해주세요.
A6: 4 | D6: > Bootstrap sheet에서 각 leg의 CashFlow를 구한 후 차이를 구해주시면 됩니다!
A7: 5 | D7: Notional | E7: 10000000000
A8: 7 | D8: Value | F8: > Notional * value
A9: 10
B13: 1bp | C13: 0.01 | D13: 3. 1bp만큼 원래 값에서 전체 tenor의 금리 or key rate을 변화시켜주세요
A14: parallel shift | D14: 1Y change | G14: 2Y change | J14: 3Y change | M14: 4Y change | P14: 5Y change | S14: 7Y change | V14: 10Y change
A15: 0.25 | D15: 0.25 | G15: 0.25 | J15: 0.25 | M15: 0.25 | P15: 0.25 | S15: 0.25 | V15: 0.25
A16: 1 | D16: 1 | F16: > 여기만 상승 | G16: 1 | J16: 1 | M16: 1 | P16: 1 | S16: 1 | V16: 1
A17: 2 | D17: 2 | G17: 2 | I17: > 여기만 상승 | J17: 2 | M17: 2 | P17: 2 | S17: 2 | V17: 2
A18: 3 | D18: 3 | G18: 3 | J18: 3 | L18: > 여기만 상승 | M18: 3 | P18: 3 | S18: 3 | V18: 3
A19: 4 | D19: 4 | G19: 4 | J19: 4 | M19: 4 | O19: > 여기만 상승 | P19: 4 | S19: 4 | V19: 4
A20: 5 | D20: 5 | G20: 5 | J20: 5 | M20: 5 | P20: 5 | R20: > 여기만 상승 | S20: 5 | V20: 5
A21: 7 | D21: 7 | G21: 7 | J21: 7 | M21: 7 | P21: 7 | S21: 7 | U21: > 여기만 상승 | V21: 7
A22: 10 | D22: 10 | G22: 10 | J22: 10 | M22: 10 | P22: 10 | S22: 10 | V22: 10 | X22: > 여기만 상승
A24: 3-1. 8년 swap 금리를 구하고 Bootstrap sheet를 통해 값이 맞는지 fixed/floating leg를 구하고 값을 비교해 확인해주세요
A25: bootstrap한 이후 값을 통해 value만 구해주시기만 하면 됩니다!
A26: > 각 tenor에 맞게 bootstrap한 값을 통해 Duration, key rate duration을 구하고 key rate duration의 경우 전체 duration 대비 얼마만큼 영향을 미쳤는지 %로 나타내주세요
A27: 8Y swap rate
A28: value change
A29: Duration

Sheet Bootstrap
A1: Bootstraping | I1: Swap rate | J1: =Sheet1!B9/100 -> 0 | M1: 8Y swap
A2: Maturity | B2: DF | C2: LN(DF) | D2: 이론 rate | E2: 실제 rate | F2: error | G2: spot curve | H2: forward curve | J2: fixed leg | K2: floating leg | N2: fixed leg | O2: floating leg
A3: {=_xlfn.SEQUENCE(40,,0.25,0.25)} -> 0.25 | G3: =-C3/A3 -> 0 | H3: =(1/B3-1)/0.25 -> #DIV/0! | J3: =$J$1*0.25*B3 -> 0 | K3: =H3*0.25*B3 -> #DIV/0!
A4: 0.5 | G4: =-C4/A4 -> 0 | H4: =(B3/B4-1)/0.25 -> #DIV/0! | J4: =$J$1*0.25*B4 -> 0 | K4: =H4*0.25*B4 -> #DIV/0!
A5: 0.75 | G5: =-C5/A5 -> 0 | H5: =(B4/B5-1)/0.25 -> #DIV/0! | J5: =$J$1*0.25*B5 -> 0 | K5: =H5*0.25*B5 -> #DIV/0!
A6: 1 | D6: =(1-B6)/(SUM($B$3:B6) *0.25) -> #DIV/0! | E6: =VLOOKUP(A6,Sheet1!$A$2:$B$12,2)/100 -> 0 | F6: =D6-E6 -> #DIV/0! | G6: =-C6/A6 -> 0 | H6: =(B5/B6-1)/0.25 -> #DIV/0! | J6: =$J$1*0.25*B6 -> 0 | K6: =H6*0.25*B6 -> #DIV/0!
A7: 1.25 | G7: =-C7/A7 -> 0 | H7: =(B6/B7-1)/0.25 -> #DIV/0! | J7: =$J$1*0.25*B7 -> 0 | K7: =H7*0.25*B7 -> #DIV/0!
A8: 1.5 | G8: =-C8/A8 -> 0 | H8: =(B7/B8-1)/0.25 -> #DIV/0! | J8: =$J$1*0.25*B8 -> 0 | K8: =H8*0.25*B8 -> #DIV/0!
A9: 1.75 | G9: =-C9/A9 -> 0 | H9: =(B8/B9-1)/0.25 -> #DIV/0! | J9: =$J$1*0.25*B9 -> 0 | K9: =H9*0.25*B9 -> #DIV/0!
A10: 2 | D10: =(1-B10)/(SUM($B$3:B10) *0.25) -> #DIV/0! | E10: =VLOOKUP(A10,Sheet1!$A$2:$B$12,2)/100 -> 0 | F10: =D10-E10 -> #DIV/0! | G10: =-C10/A10 -> 0 | H10: =(B9/B10-1)/0.25 -> #DIV/0! | J10: =$J$1*0.25*B10 -> 0 | K10: =H10*0.25*B10 -> #DIV/0!
A11: 2.25 | G11: =-C11/A11 -> 0 | H11: =(B10/B11-1)/0.25 -> #DIV/0! | J11: =$J$1*0.25*B11 -> 0 | K11: =H11*0.25*B11 -> #DIV/0!
A12: 2.5 | G12: =-C12/A12 -> 0 | H12: =(B11/B12-1)/0.25 -> #DIV/0! | J12: =$J$1*0.25*B12 -> 0 | K12: =H12*0.25*B12 -> #DIV/0!
A13: 2.75 | G13: =-C13/A13 -> 0 | H13: =(B12/B13-1)/0.25 -> #DIV/0! | J13: =$J$1*0.25*B13 -> 0 | K13: =H13*0.25*B13 -> #DIV/0!
A14: 3 | D14: =(1-B14)/(SUM($B$3:B14) *0.25) -> #DIV/0! | E14: =VLOOKUP(A14,Sheet1!$A$2:$B$12,2)/100 -> 0 | F14: =D14-E14 -> #DIV/0! | G14: =-C14/A14 -> 0 | H14: =(B13/B14-1)/0.25 -> #DIV/0! | J14: =$J$1*0.25*B14 -> 0 | K14: =H14*0.25*B14 -> #DIV/0!
A15: 3.25 | G15: =-C15/A15 -> 0 | H15: =(B14/B15-1)/0.25 -> #DIV/0! | J15: =$J$1*0.25*B15 -> 0 | K15: =H15*0.25*B15 -> #DIV/0!
A16: 3.5 | G16: =-C16/A16 -> 0 | H16: =(B15/B16-1)/0.25 -> #DIV/0! | J16: =$J$1*0.25*B16 -> 0 | K16: =H16*0.25*B16 -> #DIV/0!
A17: 3.75 | G17: =-C17/A17 -> 0 | H17: =(B16/B17-1)/0.25 -> #DIV/0! | J17: =$J$1*0.25*B17 -> 0 | K17: =H17*0.25*B17 -> #DIV/0!
A18: 4 | D18: =(1-B18)/(SUM($B$3:B18) *0.25) -> #DIV/0! | E18: =VLOOKUP(A18,Sheet1!$A$2:$B$12,2)/100 -> 0 | F18: =D18-E18 -> #DIV/0! | G18: =-C18/A18 -> 0 | H18: =(B17/B18-1)/0.25 -> #DIV/0! | J18: =$J$1*0.25*B18 -> 0 | K18: =H18*0.25*B18 -> #DIV/0!
A19: 4.25 | G19: =-C19/A19 -> 0 | H19: =(B18/B19-1)/0.25 -> #DIV/0! | J19: =$J$1*0.25*B19 -> 0 | K19: =H19*0.25*B19 -> #DIV/0!
A20: 4.5 | G20: =-C20/A20 -> 0 | H20: =(B19/B20-1)/0.25 -> #DIV/0! | J20: =$J$1*0.25*B20 -> 0 | K20: =H20*0.25*B20 -> #DIV/0!
A21: 4.75 | G21: =-C21/A21 -> 0 | H21: =(B20/B21-1)/0.25 -> #DIV/0! | J21: =$J$1*0.25*B21 -> 0 | K21: =H21*0.25*B21 -> #DIV/0!
A22: 5 | D22: =(1-B22)/(SUM($B$3:B22) *0.25) -> #DIV/0! | E22: =VLOOKUP(A22,Sheet1!$A$2:$B$12,2)/100 -> 0 | F22: =D22-E22 -> #DIV/0! | G22: =-C22/A22 -> 0 | H22: =(B21/B22-1)/0.25 -> #DIV/0! | J22: =$J$1*0.25*B22 -> 0 | K22: =H22*0.25*B22 -> #DIV/0!
A23: 5.25 | G23: =-C23/A23 -> 0 | H23: =(B22/B23-1)/0.25 -> #DIV/0! | J23: =$J$1*0.25*B23 -> 0 | K23: =H23*0.25*B23 -> #DIV/0!
A24: 5.5 | G24: =-C24/A24 -> 0 | H24: =(B23/B24-1)/0.25 -> #DIV/0! | J24: =$J$1*0.25*B24 -> 0 | K24: =H24*0.25*B24 -> #DIV/0!
A25: 5.75 | G25: =-C25/A25 -> 0 | H25: =(B24/B25-1)/0.25 -> #DIV/0! | J25: =$J$1*0.25*B25 -> 0 | K25: =H25*0.25*B25 -> #DIV/0!
A26: 6 | G26: =-C26/A26 -> 0 | H26: =(B25/B26-1)/0.25 -> #DIV/0! | J26: =$J$1*0.25*B26 -> 0 | K26: =H26*0.25*B26 -> #DIV/0!
A27: 6.25 | G27: =-C27/A27 -> 0 | H27: =(B26/B27-1)/0.25 -> #DIV/0! | J27: =$J$1*0.25*B27 -> 0 | K27: =H27*0.25*B27 -> #DIV/0!
A28: 6.5 | G28: =-C28/A28 -> 0 | H28: =(B27/B28-1)/0.25 -> #DIV/0! | J28: =$J$1*0.25*B28 -> 0 | K28: =H28*0.25*B28 -> #DIV/0!
A29: 6.75 | G29: =-C29/A29 -> 0 | H29: =(B28/B29-1)/0.25 -> #DIV/0! | J29: =$J$1*0.25*B29 -> 0 | K29: =H29*0.25*B29 -> #DIV/0!
A30: 7 | D30: =(1-B30)/(SUM($B$3:B30) *0.25) -> #DIV/0! | E30: =VLOOKUP(A30,Sheet1!$A$2:$B$12,2)/100 -> 0 | F30: =D30-E30 -> #DIV/0! | G30: =-C30/A30 -> 0 | H30: =(B29/B30-1)/0.25 -> #DIV/0! | J30: =$J$1*0.25*B30 -> 0 | K30: =H30*0.25*B30 -> #DIV/0!
A31: 7.25 | G31: =-C31/A31 -> 0 | H31: =(B30/B31-1)/0.25 -> #DIV/0! | J31: =$J$1*0.25*B31 -> 0 | K31: =H31*0.25*B31 -> #DIV/0!
A32: 7.5 | G32: =-C32/A32 -> 0 | H32: =(B31/B32-1)/0.25 -> #DIV/0! | J32: =$J$1*0.25*B32 -> 0 | K32: =H32*0.25*B32 -> #DIV/0!
A33: 7.75 | G33: =-C33/A33 -> 0 | H33: =(B32/B33-1)/0.25 -> #DIV/0! | J33: =$J$1*0.25*B33 -> 0 | K33: =H33*0.25*B33 -> #DIV/0!
A34: 8 | G34: =-C34/A34 -> 0 | H34: =(B33/B34-1)/0.25 -> #DIV/0! | J34: =$J$1*0.25*B34 -> 0 | K34: =H34*0.25*B34 -> #DIV/0!
A35: 8.25 | G35: =-C35/A35 -> 0 | H35: =(B34/B35-1)/0.25 -> #DIV/0! | J35: =$J$1*0.25*B35 -> 0 | K35: =H35*0.25*B35 -> #DIV/0! | M35: Total
A36: 8.5 | G36: =-C36/A36 -> 0 | H36: =(B35/B36-1)/0.25 -> #DIV/0! | J36: =$J$1*0.25*B36 -> 0 | K36: =H36*0.25*B36 -> #DIV/0! | N36: =N35-O35 -> 0 | O36: > Swap rate를 올바르게 구했는지 leg의 차이를 계산함으로써 구하기
A37: 8.75 | G37: =-C37/A37 -> 0 | H37: =(B36/B37-1)/0.25 -> #DIV/0! | J37: =$J$1*0.25*B37 -> 0 | K37: =H37*0.25*B37 -> #DIV/0!
A38: 9 | G38: =-C38/A38 -> 0 | H38: =(B37/B38-1)/0.25 -> #DIV/0! | J38: =$J$1*0.25*B38 -> 0 | K38: =H38*0.25*B38 -> #DIV/0!
A39: 9.25 | G39: =-C39/A39 -> 0 | H39: =(B38/B39-1)/0.25 -> #DIV/0! | J39: =$J$1*0.25*B39 -> 0 | K39: =H39*0.25*B39 -> #DIV/0!
A40: 9.5 | G40: =-C40/A40 -> 0 | H40: =(B39/B40-1)/0.25 -> #DIV/0! | J40: =$J$1*0.25*B40 -> 0 | K40: =H40*0.25*B40 -> #DIV/0!
...

Sheet Duration
A1: Bootstraping | J1: 8Y swap | K1: =Sheet1!C27 -> 0
A2: Maturity | B2: DF | C2: LN(DF) | D2: 이론 rate | E2: 실제 rate | F2: error | G2: spot curve | H2: forward curve | K2: fixed | L2: floating
A3: {=_xlfn.SEQUENCE(40,,0.25,0.25)} -> 0.25 | G3: =-C3/A3 -> 0 | H3: =(1/B3-1)/0.25 -> #DIV/0!
A4: 0.5 | G4: =-C4/A4 -> 0 | H4: =(B3/B4-1)/0.25 -> #DIV/0!
A5: 0.75 | G5: =-C5/A5 -> 0 | H5: =(B4/B5-1)/0.25 -> #DIV/0!
A6: 1 | D6: =(1-B6)/(SUM($B$3:B6) *0.25) -> #DIV/0! | E6: =VLOOKUP(A6,Sheet1!$A$15:$B$23,2)/100 -> 0 | F6: =D6-E6 -> #DIV/0! | G6: =-C6/A6 -> 0 | H6: =(B5/B6-1)/0.25 -> #DIV/0!
A7: 1.25 | G7: =-C7/A7 -> 0 | H7: =(B6/B7-1)/0.25 -> #DIV/0!
A8: 1.5 | G8: =-C8/A8 -> 0 | H8: =(B7/B8-1)/0.25 -> #DIV/0!
A9: 1.75 | G9: =-C9/A9 -> 0 | H9: =(B8/B9-1)/0.25 -> #DIV/0!
A10: 2 | D10: =(1-B10)/(SUM($B$3:B10) *0.25) -> #DIV/0! | E10: =VLOOKUP(A10,Sheet1!$A$15:$B$23,2)/100 -> 0 | F10: =D10-E10 -> #DIV/0! | G10: =-C10/A10 -> 0 | H10: =(B9/B10-1)/0.25 -> #DIV/0!
A11: 2.25 | G11: =-C11/A11 -> 0 | H11: =(B10/B11-1)/0.25 -> #DIV/0!
A12: 2.5 | G12: =-C12/A12 -> 0 | H12: =(B11/B12-1)/0.25 -> #DIV/0!
A13: 2.75 | G13: =-C13/A13 -> 0 | H13: =(B12/B13-1)/0.25 -> #DIV/0!
A14: 3 | D14: =(1-B14)/(SUM($B$3:B14) *0.25) -> #DIV/0! | E14: =VLOOKUP(A14,Sheet1!$A$15:$B$23,2)/100 -> 0 | F14: =D14-E14 -> #DIV/0! | G14: =-C14/A14 -> 0 | H14: =(B13/B14-1)/0.25 -> #DIV/0!
A15: 3.25 | G15: =-C15/A15 -> 0 | H15: =(B14/B15-1)/0.25 -> #DIV/0!
A16: 3.5 | G16: =-C16/A16 -> 0 | H16: =(B15/B16-1)/0.25 -> #DIV/0!
A17: 3.75 | G17: =-C17/A17 -> 0 | H17: =(B16/B17-1)/0.25 -> #DIV/0!
A18: 4 | D18: =(1-B18)/(SUM($B$3:B18) *0.25) -> #DIV/0! | E18: =VLOOKUP(A18,Sheet1!$A$15:$B$23,2)/100 -> 0 | F18: =D18-E18 -> #DIV/0! | G18: =-C18/A18 -> 0 | H18: =(B17/B18-1)/0.25 -> #DIV/0!
A19: 4.25 | G19: =-C19/A19 -> 0 | H19: =(B18/B19-1)/0.25 -> #DIV/0!
A20: 4.5 | G20: =-C20/A20 -> 0 | H20: =(B19/B20-1)/0.25 -> #DIV/0!
A21: 4.75 | G21: =-C21/A21 -> 0 | H21: =(B20/B21-1)/0.25 -> #DIV/0!
A22: 5 | D22: =(1-B22)/(SUM($B$3:B22) *0.25) -> #DIV/0! | E22: =VLOOKUP(A22,Sheet1!$A$15:$B$23,2)/100 -> 0 | F22: =D22-E22 -> #DIV/0! | G22: =-C22/A22 -> 0 | H22: =(B21/B22-1)/0.25 -> #DIV/0!
A23: 5.25 | G23: =-C23/A23 -> 0 | H23: =(B22/B23-1)/0.25 -> #DIV/0!
A24: 5.5 | G24: =-C24/A24 -> 0 | H24: =(B23/B24-1)/0.25 -> #DIV/0!
A25: 5.75 | G25: =-C25/A25 -> 0 | H25: =(B24/B25-1)/0.25 -> #DIV/0!
A26: 6 | G26: =-C26/A26 -> 0 | H26: =(B25/B26-1)/0.25 -> #DIV/0!
A27: 6.25 | G27: =-C27/A27 -> 0 | H27: =(B26/B27-1)/0.25 -> #DIV/0!
A28: 6.5 | G28: =-C28/A28 -> 0 | H28: =(B27/B28-1)/0.25 -> #DIV/0!
A29: 6.75 | G29: =-C29/A29 -> 0 | H29: =(B28/B29-1)/0.25 -> #DIV/0!
A30: 7 | D30: =(1-B30)/(SUM($B$3:B30) *0.25) -> #DIV/0! | E30: =VLOOKUP(A30,Sheet1!$A$15:$B$23,2)/100 -> 0 | F30: =D30-E30 -> #DIV/0! | G30: =-C30/A30 -> 0 | H30: =(B29/B30-1)/0.25 -> #DIV/0!
A31: 7.25 | G31: =-C31/A31 -> 0 | H31: =(B30/B31-1)/0.25 -> #DIV/0!
A32: 7.5 | G32: =-C32/A32 -> 0 | H32: =(B31/B32-1)/0.25 -> #DIV/0!
A33: 7.75 | G33: =-C33/A33 -> 0 | H33: =(B32/B33-1)/0.25 -> #DIV/0!
A34: 8 | G34: =-C34/A34 -> 0 | H34: =(B33/B34-1)/0.25 -> #DIV/0!
A35: 8.25 | G35: =-C35/A35 -> 0 | H35: =(B34/B35-1)/0.25 -> #DIV/0! | J35: Total | K35: =SUM(K3:K34) -> 0 | L35: =SUM(L3:L34) -> 0
A36: 8.5 | G36: =-C36/A36 -> 0 | H36: =(B35/B36-1)/0.25 -> #DIV/0!
A37: 8.75 | G37: =-C37/A37 -> 0 | H37: =(B36/B37-1)/0.25 -> #DIV/0!
A38: 9 | G38: =-C38/A38 -> 0 | H38: =(B37/B38-1)/0.25 -> #DIV/0!
A39: 9.25 | G39: =-C39/A39 -> 0 | H39: =(B38/B39-1)/0.25 -> #DIV/0!
A40: 9.5 | G40: =-C40/A40 -> 0 | H40: =(B39/B40-1)/0.25 -> #DIV/0!
...

Sheet 1Y duration
A1: Bootstraping | J1: 8Y swap | K1: =Sheet1!C27 -> 0
A2: Maturity | B2: DF | C2: LN(DF) | D2: 이론 rate | E2: 실제 rate | F2: error | G2: spot curve | H2: forward curve | K2: fixed | L2: floating
A3: {=_xlfn.SEQUENCE(40,,0.25,0.25)} -> 0.25 | G3: =-C3/A3 -> 0 | H3: =(1/B3-1)/0.25 -> #DIV/0!
A4: 0.5 | G4: =-C4/A4 -> 0 | H4: =(B3/B4-1)/0.25 -> #DIV/0!
A5: 0.75 | G5: =-C5/A5 -> 0 | H5: =(B4/B5-1)/0.25 -> #DIV/0!
A6: 1 | D6: =(1-B6)/(SUM($B$3:B6) *0.25) -> #DIV/0! | E6: =VLOOKUP(A6,Sheet1!$D$15:$E$23,2)/100 -> 0 | F6: =D6-E6 -> #DIV/0! | G6: =-C6/A6 -> 0 | H6: =(B5/B6-1)/0.25 -> #DIV/0!
A7: 1.25 | G7: =-C7/A7 -> 0 | H7: =(B6/B7-1)/0.25 -> #DIV/0!
A8: 1.5 | G8: =-C8/A8 -> 0 | H8: =(B7/B8-1)/0.25 -> #DIV/0!
A9: 1.75 | G9: =-C9/A9 -> 0 | H9: =(B8/B9-1)/0.25 -> #DIV/0!
A10: 2 | D10: =(1-B10)/(SUM($B$3:B10) *0.25) -> #DIV/0! | E10: =VLOOKUP(A10,Sheet1!$D$15:$E$23,2)/100 -> 0 | F10: =D10-E10 -> #DIV/0! | G10: =-C10/A10 -> 0 | H10: =(B9/B10-1)/0.25 -> #DIV/0!
A11: 2.25 | G11: =-C11/A11 -> 0 | H11: =(B10/B11-1)/0.25 -> #DIV/0!
A12: 2.5 | G12: =-C12/A12 -> 0 | H12: =(B11/B12-1)/0.25 -> #DIV/0!
A13: 2.75 | G13: =-C13/A13 -> 0 | H13: =(B12/B13-1)/0.25 -> #DIV/0!
A14: 3 | D14: =(1-B14)/(SUM($B$3:B14) *0.25) -> #DIV/0! | E14: =VLOOKUP(A14,Sheet1!$D$15:$E$23,2)/100 -> 0 | F14: =D14-E14 -> #DIV/0! | G14: =-C14/A14 -> 0 | H14: =(B13/B14-1)/0.25 -> #DIV/0!
A15: 3.25 | G15: =-C15/A15 -> 0 | H15: =(B14/B15-1)/0.25 -> #DIV/0!
A16: 3.5 | G16: =-C16/A16 -> 0 | H16: =(B15/B16-1)/0.25 -> #DIV/0!
A17: 3.75 | G17: =-C17/A17 -> 0 | H17: =(B16/B17-1)/0.25 -> #DIV/0!
A18: 4 | D18: =(1-B18)/(SUM($B$3:B18) *0.25) -> #DIV/0! | E18: =VLOOKUP(A18,Sheet1!$D$15:$E$23,2)/100 -> 0 | F18: =D18-E18 -> #DIV/0! | G18: =-C18/A18 -> 0 | H18: =(B17/B18-1)/0.25 -> #DIV/0!
A19: 4.25 | G19: =-C19/A19 -> 0 | H19: =(B18/B19-1)/0.25 -> #DIV/0!
A20: 4.5 | G20: =-C20/A20 -> 0 | H20: =(B19/B20-1)/0.25 -> #DIV/0!
A21: 4.75 | G21: =-C21/A21 -> 0 | H21: =(B20/B21-1)/0.25 -> #DIV/0!
A22: 5 | D22: =(1-B22)/(SUM($B$3:B22) *0.25) -> #DIV/0! | E22: =VLOOKUP(A22,Sheet1!$D$15:$E$23,2)/100 -> 0 | F22: =D22-E22 -> #DIV/0! | G22: =-C22/A22 -> 0 | H22: =(B21/B22-1)/0.25 -> #DIV/0!
A23: 5.25 | G23: =-C23/A23 -> 0 | H23: =(B22/B23-1)/0.25 -> #DIV/0!
A24: 5.5 | G24: =-C24/A24 -> 0 | H24: =(B23/B24-1)/0.25 -> #DIV/0!
A25: 5.75 | G25: =-C25/A25 -> 0 | H25: =(B24/B25-1)/0.25 -> #DIV/0!
A26: 6 | G26: =-C26/A26 -> 0 | H26: =(B25/B26-1)/0.25 -> #DIV/0!
A27: 6.25 | G27: =-C27/A27 -> 0 | H27: =(B26/B27-1)/0.25 -> #DIV/0!
A28: 6.5 | G28: =-C28/A28 -> 0 | H28: =(B27/B28-1)/0.25 -> #DIV/0!
A29: 6.75 | G29: =-C29/A29 -> 0 | H29: =(B28/B29-1)/0.25 -> #DIV/0!
A30: 7 | D30: =(1-B30)/(SUM($B$3:B30) *0.25) -> #DIV/0! | E30: =VLOOKUP(A30,Sheet1!$D$15:$E$23,2)/100 -> 0 | F30: =D30-E30 -> #DIV/0! | G30: =-C30/A30 -> 0 | H30: =(B29/B30-1)/0.25 -> #DIV/0!
A31: 7.25 | G31: =-C31/A31 -> 0 | H31: =(B30/B31-1)/0.25 -> #DIV/0!
A32: 7.5 | G32: =-C32/A32 -> 0 | H32: =(B31/B32-1)/0.25 -> #DIV/0!
A33: 7.75 | G33: =-C33/A33 -> 0 | H33: =(B32/B33-1)/0.25 -> #DIV/0!
A34: 8 | G34: =-C34/A34 -> 0 | H34: =(B33/B34-1)/0.25 -> #DIV/0!
A35: 8.25 | G35: =-C35/A35 -> 0 | H35: =(B34/B35-1)/0.25 -> #DIV/0! | J35: Total | K35: =SUM(K3:K34) -> 0 | L35: =SUM(L3:L34) -> 0
A36: 8.5 | G36: =-C36/A36 -> 0 | H36: =(B35/B36-1)/0.25 -> #DIV/0!
A37: 8.75 | G37: =-C37/A37 -> 0 | H37: =(B36/B37-1)/0.25 -> #DIV/0!
A38: 9 | G38: =-C38/A38 -> 0 | H38: =(B37/B38-1)/0.25 -> #DIV/0!
A39: 9.25 | G39: =-C39/A39 -> 0 | H39: =(B38/B39-1)/0.25 -> #DIV/0!
A40: 9.5 | G40: =-C40/A40 -> 0 | H40: =(B39/B40-1)/0.25 -> #DIV/0!
...

Sheet 2Y duration
A1: Bootstraping | J1: 8Y swap | K1: =Sheet1!C27 -> 0
A2: Maturity | B2: DF | C2: LN(DF) | D2: 이론 rate | E2: 실제 rate | F2: error | G2: spot curve | H2: forward curve | K2: fixed | L2: floating
A3: {=_xlfn.SEQUENCE(40,,0.25,0.25)} -> 0.25 | G3: =-C3/A3 -> 0 | H3: =(1/B3-1)/0.25 -> #DIV/0!
A4: 0.5 | G4: =-C4/A4 -> 0 | H4: =(B3/B4-1)/0.25 -> #DIV/0!
A5: 0.75 | G5: =-C5/A5 -> 0 | H5: =(B4/B5-1)/0.25 -> #DIV/0!
A6: 1 | D6: =(1-B6)/(SUM($B$3:B6) *0.25) -> #DIV/0! | E6: =VLOOKUP(A6,Sheet1!$G$15:$H$23,2)/100 -> 0 | F6: =D6-E6 -> #DIV/0! | G6: =-C6/A6 -> 0 | H6: =(B5/B6-1)/0.25 -> #DIV/0!
A7: 1.25 | G7: =-C7/A7 -> 0 | H7: =(B6/B7-1)/0.25 -> #DIV/0!
A8: 1.5 | G8: =-C8/A8 -> 0 | H8: =(B7/B8-1)/0.25 -> #DIV/0!
A9: 1.75 | G9: =-C9/A9 -> 0 | H9: =(B8/B9-1)/0.25 -> #DIV/0!
A10: 2 | D10: =(1-B10)/(SUM($B$3:B10) *0.25) -> #DIV/0! | E10: =VLOOKUP(A10,Sheet1!$G$15:$H$23,2)/100 -> 0 | F10: =D10-E10 -> #DIV/0! | G10: =-C10/A10 -> 0 | H10: =(B9/B10-1)/0.25 -> #DIV/0!
A11: 2.25 | G11: =-C11/A11 -> 0 | H11: =(B10/B11-1)/0.25 -> #DIV/0!
A12: 2.5 | G12: =-C12/A12 -> 0 | H12: =(B11/B12-1)/0.25 -> #DIV/0!
A13: 2.75 | G13: =-C13/A13 -> 0 | H13: =(B12/B13-1)/0.25 -> #DIV/0!
A14: 3 | D14: =(1-B14)/(SUM($B$3:B14) *0.25) -> #DIV/0! | E14: =VLOOKUP(A14,Sheet1!$G$15:$H$23,2)/100 -> 0 | F14: =D14-E14 -> #DIV/0! | G14: =-C14/A14 -> 0 | H14: =(B13/B14-1)/0.25 -> #DIV/0!
A15: 3.25 | G15: =-C15/A15 -> 0 | H15: =(B14/B15-1)/0.25 -> #DIV/0!
A16: 3.5 | G16: =-C16/A16 -> 0 | H16: =(B15/B16-1)/0.25 -> #DIV/0!
A17: 3.75 | G17: =-C17/A17 -> 0 | H17: =(B16/B17-1)/0.25 -> #DIV/0!
A18: 4 | D18: =(1-B18)/(SUM($B$3:B18) *0.25) -> #DIV/0! | E18: =VLOOKUP(A18,Sheet1!$G$15:$H$23,2)/100 -> 0 | F18: =D18-E18 -> #DIV/0! | G18: =-C18/A18 -> 0 | H18: =(B17/B18-1)/0.25 -> #DIV/0!
A19: 4.25 | G19: =-C19/A19 -> 0 | H19: =(B18/B19-1)/0.25 -> #DIV/0!
A20: 4.5 | G20: =-C20/A20 -> 0 | H20: =(B19/B20-1)/0.25 -> #DIV/0!
A21: 4.75 | G21: =-C21/A21 -> 0 | H21: =(B20/B21-1)/0.25 -> #DIV/0!
A22: 5 | D22: =(1-B22)/(SUM($B$3:B22) *0.25) -> #DIV/0! | E22: =VLOOKUP(A22,Sheet1!$G$15:$H$23,2)/100 -> 0 | F22: =D22-E22 -> #DIV/0! | G22: =-C22/A22 -> 0 | H22: =(B21/B22-1)/0.25 -> #DIV/0!
A23: 5.25 | G23: =-C23/A23 -> 0 | H23: =(B22/B23-1)/0.25 -> #DIV/0!
A24: 5.5 | G24: =-C24/A24 -> 0 | H24: =(B23/B24-1)/0.25 -> #DIV/0!
A25: 5.75 | G25: =-C25/A25 -> 0 | H25: =(B24/B25-1)/0.25 -> #DIV/0!
A26: 6 | G26: =-C26/A26 -> 0 | H26: =(B25/B26-1)/0.25 -> #DIV/0!
A27: 6.25 | G27: =-C27/A27 -> 0 | H27: =(B26/B27-1)/0.25 -> #DIV/0!
A28: 6.5 | G28: =-C28/A28 -> 0 | H28: =(B27/B28-1)/0.25 -> #DIV/0!
A29: 6.75 | G29: =-C29/A29 -> 0 | H29: =(B28/B29-1)/0.25 -> #DIV/0!
A30: 7 | D30: =(1-B30)/(SUM($B$3:B30) *0.25) -> #DIV/0! | E30: =VLOOKUP(A30,Sheet1!$G$15:$H$23,2)/100 -> 0 | F30: =D30-E30 -> #DIV/0! | G30: =-C30/A30 -> 0 | H30: =(B29/B30-1)/0.25 -> #DIV/0!
A31: 7.25 | G31: =-C31/A31 -> 0 | H31: =(B30/B31-1)/0.25 -> #DIV/0!
A32: 7.5 | G32: =-C32/A32 -> 0 | H32: =(B31/B32-1)/0.25 -> #DIV/0!
A33: 7.75 | G33: =-C33/A33 -> 0 | H33: =(B32/B33-1)/0.25 -> #DIV/0!
A34: 8 | G34: =-C34/A34 -> 0 | H34: =(B33/B34-1)/0.25 -> #DIV/0!
A35: 8.25 | G35: =-C35/A35 -> 0 | H35: =(B34/B35-1)/0.25 -> #DIV/0! | J35: Total | K35: =SUM(K3:K34) -> 0 | L35: =SUM(L3:L34) -> 0
A36: 8.5 | G36: =-C36/A36 -> 0 | H36: =(B35/B36-1)/0.25 -> #DIV/0!
A37: 8.75 | G37: =-C37/A37 -> 0 | H37: =(B36/B37-1)/0.25 -> #DIV/0!
A38: 9 | G38: =-C38/A38 -> 0 | H38: =(B37/B38-1)/0.25 -> #DIV/0!
A39: 9.25 | G39: =-C39/A39 -> 0 | H39: =(B38/B39-1)/0.25 -> #DIV/0!
A40: 9.5 | G40: =-C40/A40 -> 0 | H40: =(B39/B40-1)/0.25 -> #DIV/0!
...

Sheet 3Y duration
A1: Bootstraping | J1: 8Y swap | K1: =Sheet1!C27 -> 0
A2: Maturity | B2: DF | C2: LN(DF) | D2: 이론 rate | E2: 실제 rate | F2: error | G2: spot curve | H2: forward curve | K2: fixed | L2: floating
A3: {=_xlfn.SEQUENCE(40,,0.25,0.25)} -> 0.25 | G3: =-C3/A3 -> 0 | H3: =(1/B3-1)/0.25 -> #DIV/0!
A4: 0.5 | G4: =-C4/A4 -> 0 | H4: =(B3/B4-1)/0.25 -> #DIV/0!
A5: 0.75 | G5: =-C5/A5 -> 0 | H5: =(B4/B5-1)/0.25 -> #DIV/0!
A6: 1 | D6: =(1-B6)/(SUM($B$3:B6) *0.25) -> #DIV/0! | E6: =VLOOKUP(A6,Sheet1!$J$15:$K$23,2)/100 -> 0 | F6: =D6-E6 -> #DIV/0! | G6: =-C6/A6 -> 0 | H6: =(B5/B6-1)/0.25 -> #DIV/0!
A7: 1.25 | G7: =-C7/A7 -> 0 | H7: =(B6/B7-1)/0.25 -> #DIV/0!
A8: 1.5 | G8: =-C8/A8 -> 0 | H8: =(B7/B8-1)/0.25 -> #DIV/0!
A9: 1.75 | G9: =-C9/A9 -> 0 | H9: =(B8/B9-1)/0.25 -> #DIV/0!
A10: 2 | D10: =(1-B10)/(SUM($B$3:B10) *0.25) -> #DIV/0! | E10: =VLOOKUP(A10,Sheet1!$J$15:$K$23,2)/100 -> 0 | F10: =D10-E10 -> #DIV/0! | G10: =-C10/A10 -> 0 | H10: =(B9/B10-1)/0.25 -> #DIV/0!
A11: 2.25 | G11: =-C11/A11 -> 0 | H11: =(B10/B11-1)/0.25 -> #DIV/0!
A12: 2.5 | G12: =-C12/A12 -> 0 | H12: =(B11/B12-1)/0.25 -> #DIV/0!
A13: 2.75 | G13: =-C13/A13 -> 0 | H13: =(B12/B13-1)/0.25 -> #DIV/0!
A14: 3 | D14: =(1-B14)/(SUM($B$3:B14) *0.25) -> #DIV/0! | E14: =VLOOKUP(A14,Sheet1!$J$15:$K$23,2)/100 -> 0 | F14: =D14-E14 -> #DIV/0! | G14: =-C14/A14 -> 0 | H14: =(B13/B14-1)/0.25 -> #DIV/0!
A15: 3.25 | G15: =-C15/A15 -> 0 | H15: =(B14/B15-1)/0.25 -> #DIV/0!
A16: 3.5 | G16: =-C16/A16 -> 0 | H16: =(B15/B16-1)/0.25 -> #DIV/0!
A17: 3.75 | G17: =-C17/A17 -> 0 | H17: =(B16/B17-1)/0.25 -> #DIV/0!
A18: 4 | D18: =(1-B18)/(SUM($B$3:B18) *0.25) -> #DIV/0! | E18: =VLOOKUP(A18,Sheet1!$J$15:$K$23,2)/100 -> 0 | F18: =D18-E18 -> #DIV/0! | G18: =-C18/A18 -> 0 | H18: =(B17/B18-1)/0.25 -> #DIV/0!
A19: 4.25 | G19: =-C19/A19 -> 0 | H19: =(B18/B19-1)/0.25 -> #DIV/0!
A20: 4.5 | G20: =-C20/A20 -> 0 | H20: =(B19/B20-1)/0.25 -> #DIV/0!
A21: 4.75 | G21: =-C21/A21 -> 0 | H21: =(B20/B21-1)/0.25 -> #DIV/0!
A22: 5 | D22: =(1-B22)/(SUM($B$3:B22) *0.25) -> #DIV/0! | E22: =VLOOKUP(A22,Sheet1!$J$15:$K$23,2)/100 -> 0 | F22: =D22-E22 -> #DIV/0! | G22: =-C22/A22 -> 0 | H22: =(B21/B22-1)/0.25 -> #DIV/0!
A23: 5.25 | G23: =-C23/A23 -> 0 | H23: =(B22/B23-1)/0.25 -> #DIV/0!
A24: 5.5 | G24: =-C24/A24 -> 0 | H24: =(B23/B24-1)/0.25 -> #DIV/0!
A25: 5.75 | G25: =-C25/A25 -> 0 | H25: =(B24/B25-1)/0.25 -> #DIV/0!
A26: 6 | G26: =-C26/A26 -> 0 | H26: =(B25/B26-1)/0.25 -> #DIV/0!
A27: 6.25 | G27: =-C27/A27 -> 0 | H27: =(B26/B27-1)/0.25 -> #DIV/0!
A28: 6.5 | G28: =-C28/A28 -> 0 | H28: =(B27/B28-1)/0.25 -> #DIV/0!
A29: 6.75 | G29: =-C29/A29 -> 0 | H29: =(B28/B29-1)/0.25 -> #DIV/0!
A30: 7 | D30: =(1-B30)/(SUM($B$3:B30) *0.25) -> #DIV/0! | E30: =VLOOKUP(A30,Sheet1!$J$15:$K$23,2)/100 -> 0 | F30: =D30-E30 -> #DIV/0! | G30: =-C30/A30 -> 0 | H30: =(B29/B30-1)/0.25 -> #DIV/0!
A31: 7.25 | G31: =-C31/A31 -> 0 | H31: =(B30/B31-1)/0.25 -> #DIV/0!
A32: 7.5 | G32: =-C32/A32 -> 0 | H32: =(B31/B32-1)/0.25 -> #DIV/0!
A33: 7.75 | G33: =-C33/A33 -> 0 | H33: =(B32/B33-1)/0.25 -> #DIV/0!
A34: 8 | G34: =-C34/A34 -> 0 | H34: =(B33/B34-1)/0.25 -> #DIV/0!
A35: 8.25 | G35: =-C35/A35 -> 0 | H35: =(B34/B35-1)/0.25 -> #DIV/0! | J35: Total | K35: =SUM(K3:K34) -> 0 | L35: =SUM(L3:L34) -> 0
A36: 8.5 | G36: =-C36/A36 -> 0 | H36: =(B35/B36-1)/0.25 -> #DIV/0!
A37: 8.75 | G37: =-C37/A37 -> 0 | H37: =(B36/B37-1)/0.25 -> #DIV/0!
A38: 9 | G38: =-C38/A38 -> 0 | H38: =(B37/B38-1)/0.25 -> #DIV/0!
A39: 9.25 | G39: =-C39/A39 -> 0 | H39: =(B38/B39-1)/0.25 -> #DIV/0!
A40: 9.5 | G40: =-C40/A40 -> 0 | H40: =(B39/B40-1)/0.25 -> #DIV/0!
...

Sheet 4Y duration
A1: Bootstraping | J1: 8Y swap | K1: =Sheet1!C27 -> 0
A2: Maturity | B2: DF | C2: LN(DF) | D2: 이론 rate | E2: 실제 rate | F2: error | G2: spot curve | H2: forward curve | K2: fixed | L2: floating
A3: {=_xlfn.SEQUENCE(40,,0.25,0.25)} -> 0.25 | G3: =-C3/A3 -> 0 | H3: =(1/B3-1)/0.25 -> #DIV/0!
A4: 0.5 | G4: =-C4/A4 -> 0 | H4: =(B3/B4-1)/0.25 -> #DIV/0!
A5: 0.75 | G5: =-C5/A5 -> 0 | H5: =(B4/B5-1)/0.25 -> #DIV/0!
A6: 1 | D6: =(1-B6)/(SUM($B$3:B6) *0.25) -> #DIV/0! | E6: =VLOOKUP(A6,Sheet1!$M$15:$N$23,2)/100 -> 0 | F6: =D6-E6 -> #DIV/0! | G6: =-C6/A6 -> 0 | H6: =(B5/B6-1)/0.25 -> #DIV/0!
A7: 1.25 | G7: =-C7/A7 -> 0 | H7: =(B6/B7-1)/0.25 -> #DIV/0!
A8: 1.5 | G8: =-C8/A8 -> 0 | H8: =(B7/B8-1)/0.25 -> #DIV/0!
A9: 1.75 | G9: =-C9/A9 -> 0 | H9: =(B8/B9-1)/0.25 -> #DIV/0!
A10: 2 | D10: =(1-B10)/(SUM($B$3:B10) *0.25) -> #DIV/0! | E10: =VLOOKUP(A10,Sheet1!$M$15:$N$23,2)/100 -> 0 | F10: =D10-E10 -> #DIV/0! | G10: =-C10/A10 -> 0 | H10: =(B9/B10-1)/0.25 -> #DIV/0!
A11: 2.25 | G11: =-C11/A11 -> 0 | H11: =(B10/B11-1)/0.25 -> #DIV/0!
A12: 2.5 | G12: =-C12/A12 -> 0 | H12: =(B11/B12-1)/0.25 -> #DIV/0!
A13: 2.75 | G13: =-C13/A13 -> 0 | H13: =(B12/B13-1)/0.25 -> #DIV/0!
A14: 3 | D14: =(1-B14)/(SUM($B$3:B14) *0.25) -> #DIV/0! | E14: =VLOOKUP(A14,Sheet1!$M$15:$N$23,2)/100 -> 0 | F14: =D14-E14 -> #DIV/0! | G14: =-C14/A14 -> 0 | H14: =(B13/B14-1)/0.25 -> #DIV/0!
A15: 3.25 | G15: =-C15/A15 -> 0 | H15: =(B14/B15-1)/0.25 -> #DIV/0!
A16: 3.5 | G16: =-C16/A16 -> 0 | H16: =(B15/B16-1)/0.25 -> #DIV/0!
A17: 3.75 | G17: =-C17/A17 -> 0 | H17: =(B16/B17-1)/0.25 -> #DIV/0!
A18: 4 | D18: =(1-B18)/(SUM($B$3:B18) *0.25) -> #DIV/0! | E18: =VLOOKUP(A18,Sheet1!$M$15:$N$23,2)/100 -> 0 | F18: =D18-E18 -> #DIV/0! | G18: =-C18/A18 -> 0 | H18: =(B17/B18-1)/0.25 -> #DIV/0!
A19: 4.25 | G19: =-C19/A19 -> 0 | H19: =(B18/B19-1)/0.25 -> #DIV/0!
A20: 4.5 | G20: =-C20/A20 -> 0 | H20: =(B19/B20-1)/0.25 -> #DIV/0!
A21: 4.75 | G21: =-C21/A21 -> 0 | H21: =(B20/B21-1)/0.25 -> #DIV/0!
A22: 5 | D22: =(1-B22)/(SUM($B$3:B22) *0.25) -> #DIV/0! | E22: =VLOOKUP(A22,Sheet1!$M$15:$N$23,2)/100 -> 0 | F22: =D22-E22 -> #DIV/0! | G22: =-C22/A22 -> 0 | H22: =(B21/B22-1)/0.25 -> #DIV/0!
A23: 5.25 | G23: =-C23/A23 -> 0 | H23: =(B22/B23-1)/0.25 -> #DIV/0!
A24: 5.5 | G24: =-C24/A24 -> 0 | H24: =(B23/B24-1)/0.25 -> #DIV/0!
A25: 5.75 | G25: =-C25/A25 -> 0 | H25: =(B24/B25-1)/0.25 -> #DIV/0!
A26: 6 | G26: =-C26/A26 -> 0 | H26: =(B25/B26-1)/0.25 -> #DIV/0!
A27: 6.25 | G27: =-C27/A27 -> 0 | H27: =(B26/B27-1)/0.25 -> #DIV/0!
A28: 6.5 | G28: =-C28/A28 -> 0 | H28: =(B27/B28-1)/0.25 -> #DIV/0!
A29: 6.75 | G29: =-C29/A29 -> 0 | H29: =(B28/B29-1)/0.25 -> #DIV/0!
A30: 7 | D30: =(1-B30)/(SUM($B$3:B30) *0.25) -> #DIV/0! | E30: =VLOOKUP(A30,Sheet1!$M$15:$N$23,2)/100 -> 0 | F30: =D30-E30 -> #DIV/0! | G30: =-C30/A30 -> 0 | H30: =(B29/B30-1)/0.25 -> #DIV/0!
A31: 7.25 | G31: =-C31/A31 -> 0 | H31: =(B30/B31-1)/0.25 -> #DIV/0!
A32: 7.5 | G32: =-C32/A32 -> 0 | H32: =(B31/B32-1)/0.25 -> #DIV/0!
A33: 7.75 | G33: =-C33/A33 -> 0 | H33: =(B32/B33-1)/0.25 -> #DIV/0!
A34: 8 | G34: =-C34/A34 -> 0 | H34: =(B33/B34-1)/0.25 -> #DIV/0!
A35: 8.25 | G35: =-C35/A35 -> 0 | H35: =(B34/B35-1)/0.25 -> #DIV/0! | J35: Total | K35: =SUM(K3:K34) -> 0 | L35: =SUM(L3:L34) -> 0
A36: 8.5 | G36: =-C36/A36 -> 0 | H36: =(B35/B36-1)/0.25 -> #DIV/0!
A37: 8.75 | G37: =-C37/A37 -> 0 | H37: =(B36/B37-1)/0.25 -> #DIV/0!
A38: 9 | G38: =-C38/A38 -> 0 | H38: =(B37/B38-1)/0.25 -> #DIV/0!
A39: 9.25 | G39: =-C39/A39 -> 0 | H39: =(B38/B39-1)/0.25 -> #DIV/0!
A40: 9.5 | G40: =-C40/A40 -> 0 | H40: =(B39/B40-1)/0.25 -> #DIV/0!
...

Sheet 5Y duration
A1: Bootstraping | J1: 8Y swap | K1: =Sheet1!C27 -> 0
A2: Maturity | B2: DF | C2: LN(DF) | D2: 이론 rate | E2: 실제 rate | F2: error | G2: spot curve | H2: forward curve | K2: fixed | L2: floating
A3: {=_xlfn.SEQUENCE(40,,0.25,0.25)} -> 0.25 | G3: =-C3/A3 -> 0 | H3: =(1/B3-1)/0.25 -> #DIV/0!
A4: 0.5 | G4: =-C4/A4 -> 0 | H4: =(B3/B4-1)/0.25 -> #DIV/0!
A5: 0.75 | G5: =-C5/A5 -> 0 | H5: =(B4/B5-1)/0.25 -> #DIV/0!
A6: 1 | D6: =(1-B6)/(SUM($B$3:B6) *0.25) -> #DIV/0! | E6: =VLOOKUP(A6,Sheet1!$P$15:$Q$23,2)/100 -> 0 | F6: =D6-E6 -> #DIV/0! | G6: =-C6/A6 -> 0 | H6: =(B5/B6-1)/0.25 -> #DIV/0!
A7: 1.25 | G7: =-C7/A7 -> 0 | H7: =(B6/B7-1)/0.25 -> #DIV/0!
A8: 1.5 | G8: =-C8/A8 -> 0 | H8: =(B7/B8-1)/0.25 -> #DIV/0!
A9: 1.75 | G9: =-C9/A9 -> 0 | H9: =(B8/B9-1)/0.25 -> #DIV/0!
A10: 2 | D10: =(1-B10)/(SUM($B$3:B10) *0.25) -> #DIV/0! | E10: =VLOOKUP(A10,Sheet1!$P$15:$Q$23,2)/100 -> 0 | F10: =D10-E10 -> #DIV/0! | G10: =-C10/A10 -> 0 | H10: =(B9/B10-1)/0.25 -> #DIV/0!
A11: 2.25 | G11: =-C11/A11 -> 0 | H11: =(B10/B11-1)/0.25 -> #DIV/0!
A12: 2.5 | G12: =-C12/A12 -> 0 | H12: =(B11/B12-1)/0.25 -> #DIV/0!
A13: 2.75 | G13: =-C13/A13 -> 0 | H13: =(B12/B13-1)/0.25 -> #DIV/0!
A14: 3 | D14: =(1-B14)/(SUM($B$3:B14) *0.25) -> #DIV/0! | E14: =VLOOKUP(A14,Sheet1!$P$15:$Q$23,2)/100 -> 0 | F14: =D14-E14 -> #DIV/0! | G14: =-C14/A14 -> 0 | H14: =(B13/B14-1)/0.25 -> #DIV/0!
A15: 3.25 | G15: =-C15/A15 -> 0 | H15: =(B14/B15-1)/0.25 -> #DIV/0!
A16: 3.5 | G16: =-C16/A16 -> 0 | H16: =(B15/B16-1)/0.25 -> #DIV/0!
A17: 3.75 | G17: =-C17/A17 -> 0 | H17: =(B16/B17-1)/0.25 -> #DIV/0!
A18: 4 | D18: =(1-B18)/(SUM($B$3:B18) *0.25) -> #DIV/0! | E18: =VLOOKUP(A18,Sheet1!$P$15:$Q$23,2)/100 -> 0 | F18: =D18-E18 -> #DIV/0! | G18: =-C18/A18 -> 0 | H18: =(B17/B18-1)/0.25 -> #DIV/0!
A19: 4.25 | G19: =-C19/A19 -> 0 | H19: =(B18/B19-1)/0.25 -> #DIV/0!
A20: 4.5 | G20: =-C20/A20 -> 0 | H20: =(B19/B20-1)/0.25 -> #DIV/0!
A21: 4.75 | G21: =-C21/A21 -> 0 | H21: =(B20/B21-1)/0.25 -> #DIV/0!
A22: 5 | D22: =(1-B22)/(SUM($B$3:B22) *0.25) -> #DIV/0! | E22: =VLOOKUP(A22,Sheet1!$P$15:$Q$23,2)/100 -> 0 | F22: =D22-E22 -> #DIV/0! | G22: =-C22/A22 -> 0 | H22: =(B21/B22-1)/0.25 -> #DIV/0!
A23: 5.25 | G23: =-C23/A23 -> 0 | H23: =(B22/B23-1)/0.25 -> #DIV/0!
A24: 5.5 | G24: =-C24/A24 -> 0 | H24: =(B23/B24-1)/0.25 -> #DIV/0!
A25: 5.75 | G25: =-C25/A25 -> 0 | H25: =(B24/B25-1)/0.25 -> #DIV/0!
A26: 6 | G26: =-C26/A26 -> 0 | H26: =(B25/B26-1)/0.25 -> #DIV/0!
A27: 6.25 | G27: =-C27/A27 -> 0 | H27: =(B26/B27-1)/0.25 -> #DIV/0!
A28: 6.5 | G28: =-C28/A28 -> 0 | H28: =(B27/B28-1)/0.25 -> #DIV/0!
A29: 6.75 | G29: =-C29/A29 -> 0 | H29: =(B28/B29-1)/0.25 -> #DIV/0!
A30: 7 | D30: =(1-B30)/(SUM($B$3:B30) *0.25) -> #DIV/0! | E30: =VLOOKUP(A30,Sheet1!$P$15:$Q$23,2)/100 -> 0 | F30: =D30-E30 -> #DIV/0! | G30: =-C30/A30 -> 0 | H30: =(B29/B30-1)/0.25 -> #DIV/0!
A31: 7.25 | G31: =-C31/A31 -> 0 | H31: =(B30/B31-1)/0.25 -> #DIV/0!
A32: 7.5 | G32: =-C32/A32 -> 0 | H32: =(B31/B32-1)/0.25 -> #DIV/0!
A33: 7.75 | G33: =-C33/A33 -> 0 | H33: =(B32/B33-1)/0.25 -> #DIV/0!
A34: 8 | G34: =-C34/A34 -> 0 | H34: =(B33/B34-1)/0.25 -> #DIV/0!
A35: 8.25 | G35: =-C35/A35 -> 0 | H35: =(B34/B35-1)/0.25 -> #DIV/0! | J35: Total | K35: =SUM(K3:K34) -> 0 | L35: =SUM(L3:L34) -> 0
A36: 8.5 | G36: =-C36/A36 -> 0 | H36: =(B35/B36-1)/0.25 -> #DIV/0!
A37: 8.75 | G37: =-C37/A37 -> 0 | H37: =(B36/B37-1)/0.25 -> #DIV/0!
A38: 9 | G38: =-C38/A38 -> 0 | H38: =(B37/B38-1)/0.25 -> #DIV/0!
A39: 9.25 | G39: =-C39/A39 -> 0 | H39: =(B38/B39-1)/0.25 -> #DIV/0!
A40: 9.5 | G40: =-C40/A40 -> 0 | H40: =(B39/B40-1)/0.25 -> #DIV/0!
...

Sheet 7Y duration
A1: Bootstraping | J1: 8Y swap | K1: =Sheet1!C27 -> 0
A2: Maturity | B2: DF | C2: LN(DF) | D2: 이론 rate | E2: 실제 rate | F2: error | G2: spot curve | H2: forward curve | K2: fixed | L2: floating
A3: {=_xlfn.SEQUENCE(40,,0.25,0.25)} -> 0.25 | G3: =-C3/A3 -> 0 | H3: =(1/B3-1)/0.25 -> #DIV/0!
A4: 0.5 | G4: =-C4/A4 -> 0 | H4: =(B3/B4-1)/0.25 -> #DIV/0!
A5: 0.75 | G5: =-C5/A5 -> 0 | H5: =(B4/B5-1)/0.25 -> #DIV/0!
A6: 1 | D6: =(1-B6)/(SUM($B$3:B6) *0.25) -> #DIV/0! | E6: =VLOOKUP(A6,Sheet1!$S$15:$T$23,2)/100 -> 0 | F6: =D6-E6 -> #DIV/0! | G6: =-C6/A6 -> 0 | H6: =(B5/B6-1)/0.25 -> #DIV/0!
A7: 1.25 | G7: =-C7/A7 -> 0 | H7: =(B6/B7-1)/0.25 -> #DIV/0!
A8: 1.5 | G8: =-C8/A8 -> 0 | H8: =(B7/B8-1)/0.25 -> #DIV/0!
A9: 1.75 | G9: =-C9/A9 -> 0 | H9: =(B8/B9-1)/0.25 -> #DIV/0!
A10: 2 | D10: =(1-B10)/(SUM($B$3:B10) *0.25) -> #DIV/0! | E10: =VLOOKUP(A10,Sheet1!$S$15:$T$23,2)/100 -> 0 | F10: =D10-E10 -> #DIV/0! | G10: =-C10/A10 -> 0 | H10: =(B9/B10-1)/0.25 -> #DIV/0!
A11: 2.25 | G11: =-C11/A11 -> 0 | H11: =(B10/B11-1)/0.25 -> #DIV/0!
A12: 2.5 | G12: =-C12/A12 -> 0 | H12: =(B11/B12-1)/0.25 -> #DIV/0!
A13: 2.75 | G13: =-C13/A13 -> 0 | H13: =(B12/B13-1)/0.25 -> #DIV/0!
A14: 3 | D14: =(1-B14)/(SUM($B$3:B14) *0.25) -> #DIV/0! | E14: =VLOOKUP(A14,Sheet1!$S$15:$T$23,2)/100 -> 0 | F14: =D14-E14 -> #DIV/0! | G14: =-C14/A14 -> 0 | H14: =(B13/B14-1)/0.25 -> #DIV/0!
A15: 3.25 | G15: =-C15/A15 -> 0 | H15: =(B14/B15-1)/0.25 -> #DIV/0!
A16: 3.5 | G16: =-C16/A16 -> 0 | H16: =(B15/B16-1)/0.25 -> #DIV/0!
A17: 3.75 | G17: =-C17/A17 -> 0 | H17: =(B16/B17-1)/0.25 -> #DIV/0!
A18: 4 | D18: =(1-B18)/(SUM($B$3:B18) *0.25) -> #DIV/0! | E18: =VLOOKUP(A18,Sheet1!$S$15:$T$23,2)/100 -> 0 | F18: =D18-E18 -> #DIV/0! | G18: =-C18/A18 -> 0 | H18: =(B17/B18-1)/0.25 -> #DIV/0!
A19: 4.25 | G19: =-C19/A19 -> 0 | H19: =(B18/B19-1)/0.25 -> #DIV/0!
A20: 4.5 | G20: =-C20/A20 -> 0 | H20: =(B19/B20-1)/0.25 -> #DIV/0!
A21: 4.75 | G21: =-C21/A21 -> 0 | H21: =(B20/B21-1)/0.25 -> #DIV/0!
A22: 5 | D22: =(1-B22)/(SUM($B$3:B22) *0.25) -> #DIV/0! | E22: =VLOOKUP(A22,Sheet1!$S$15:$T$23,2)/100 -> 0 | F22: =D22-E22 -> #DIV/0! | G22: =-C22/A22 -> 0 | H22: =(B21/B22-1)/0.25 -> #DIV/0!
A23: 5.25 | G23: =-C23/A23 -> 0 | H23: =(B22/B23-1)/0.25 -> #DIV/0!
A24: 5.5 | G24: =-C24/A24 -> 0 | H24: =(B23/B24-1)/0.25 -> #DIV/0!
A25: 5.75 | G25: =-C25/A25 -> 0 | H25: =(B24/B25-1)/0.25 -> #DIV/0!
A26: 6 | G26: =-C26/A26 -> 0 | H26: =(B25/B26-1)/0.25 -> #DIV/0!
A27: 6.25 | G27: =-C27/A27 -> 0 | H27: =(B26/B27-1)/0.25 -> #DIV/0!
A28: 6.5 | G28: =-C28/A28 -> 0 | H28: =(B27/B28-1)/0.25 -> #DIV/0!
A29: 6.75 | G29: =-C29/A29 -> 0 | H29: =(B28/B29-1)/0.25 -> #DIV/0!
A30: 7 | D30: =(1-B30)/(SUM($B$3:B30) *0.25) -> #DIV/0! | E30: =VLOOKUP(A30,Sheet1!$S$15:$T$23,2)/100 -> 0 | F30: =D30-E30 -> #DIV/0! | G30: =-C30/A30 -> 0 | H30: =(B29/B30-1)/0.25 -> #DIV/0!
A31: 7.25 | G31: =-C31/A31 -> 0 | H31: =(B30/B31-1)/0.25 -> #DIV/0!
A32: 7.5 | G32: =-C32/A32 -> 0 | H32: =(B31/B32-1)/0.25 -> #DIV/0!
A33: 7.75 | G33: =-C33/A33 -> 0 | H33: =(B32/B33-1)/0.25 -> #DIV/0!
A34: 8 | G34: =-C34/A34 -> 0 | H34: =(B33/B34-1)/0.25 -> #DIV/0!
A35: 8.25 | G35: =-C35/A35 -> 0 | H35: =(B34/B35-1)/0.25 -> #DIV/0! | J35: Total | K35: =SUM(K3:K34) -> 0 | L35: =SUM(L3:L34) -> 0
A36: 8.5 | G36: =-C36/A36 -> 0 | H36: =(B35/B36-1)/0.25 -> #DIV/0!
A37: 8.75 | G37: =-C37/A37 -> 0 | H37: =(B36/B37-1)/0.25 -> #DIV/0!
A38: 9 | G38: =-C38/A38 -> 0 | H38: =(B37/B38-1)/0.25 -> #DIV/0!
A39: 9.25 | G39: =-C39/A39 -> 0 | H39: =(B38/B39-1)/0.25 -> #DIV/0!
A40: 9.5 | G40: =-C40/A40 -> 0 | H40: =(B39/B40-1)/0.25 -> #DIV/0!
...

Sheet 10Y duration
A1: Bootstraping | J1: 8Y swap | K1: =Sheet1!C27 -> 0
A2: Maturity | B2: DF | C2: LN(DF) | D2: 이론 rate | E2: 실제 rate | F2: error | G2: spot curve | H2: forward curve | K2: fixed | L2: floating
A3: {=_xlfn.SEQUENCE(40,,0.25,0.25)} -> 0.25 | G3: =-C3/A3 -> 0 | H3: =(1/B3-1)/0.25 -> #DIV/0!
A4: 0.5 | G4: =-C4/A4 -> 0 | H4: =(B3/B4-1)/0.25 -> #DIV/0!
A5: 0.75 | G5: =-C5/A5 -> 0 | H5: =(B4/B5-1)/0.25 -> #DIV/0!
A6: 1 | D6: =(1-B6)/(SUM($B$3:B6) *0.25) -> #DIV/0! | E6: =VLOOKUP(A6,Sheet1!$V$15:$W$23,2)/100 -> 0 | F6: =D6-E6 -> #DIV/0! | G6: =-C6/A6 -> 0 | H6: =(B5/B6-1)/0.25 -> #DIV/0!
A7: 1.25 | G7: =-C7/A7 -> 0 | H7: =(B6/B7-1)/0.25 -> #DIV/0!
A8: 1.5 | G8: =-C8/A8 -> 0 | H8: =(B7/B8-1)/0.25 -> #DIV/0!
A9: 1.75 | G9: =-C9/A9 -> 0 | H9: =(B8/B9-1)/0.25 -> #DIV/0!
A10: 2 | D10: =(1-B10)/(SUM($B$3:B10) *0.25) -> #DIV/0! | E10: =VLOOKUP(A10,Sheet1!$V$15:$W$23,2)/100 -> 0 | F10: =D10-E10 -> #DIV/0! | G10: =-C10/A10 -> 0 | H10: =(B9/B10-1)/0.25 -> #DIV/0!
A11: 2.25 | G11: =-C11/A11 -> 0 | H11: =(B10/B11-1)/0.25 -> #DIV/0!
A12: 2.5 | G12: =-C12/A12 -> 0 | H12: =(B11/B12-1)/0.25 -> #DIV/0!
A13: 2.75 | G13: =-C13/A13 -> 0 | H13: =(B12/B13-1)/0.25 -> #DIV/0!
A14: 3 | D14: =(1-B14)/(SUM($B$3:B14) *0.25) -> #DIV/0! | E14: =VLOOKUP(A14,Sheet1!$V$15:$W$23,2)/100 -> 0 | F14: =D14-E14 -> #DIV/0! | G14: =-C14/A14 -> 0 | H14: =(B13/B14-1)/0.25 -> #DIV/0!
A15: 3.25 | G15: =-C15/A15 -> 0 | H15: =(B14/B15-1)/0.25 -> #DIV/0!
A16: 3.5 | G16: =-C16/A16 -> 0 | H16: =(B15/B16-1)/0.25 -> #DIV/0!
A17: 3.75 | G17: =-C17/A17 -> 0 | H17: =(B16/B17-1)/0.25 -> #DIV/0!
A18: 4 | D18: =(1-B18)/(SUM($B$3:B18) *0.25) -> #DIV/0! | E18: =VLOOKUP(A18,Sheet1!$V$15:$W$23,2)/100 -> 0 | F18: =D18-E18 -> #DIV/0! | G18: =-C18/A18 -> 0 | H18: =(B17/B18-1)/0.25 -> #DIV/0!
A19: 4.25 | G19: =-C19/A19 -> 0 | H19: =(B18/B19-1)/0.25 -> #DIV/0!
A20: 4.5 | G20: =-C20/A20 -> 0 | H20: =(B19/B20-1)/0.25 -> #DIV/0!
A21: 4.75 | G21: =-C21/A21 -> 0 | H21: =(B20/B21-1)/0.25 -> #DIV/0!
A22: 5 | D22: =(1-B22)/(SUM($B$3:B22) *0.25) -> #DIV/0! | E22: =VLOOKUP(A22,Sheet1!$V$15:$W$23,2)/100 -> 0 | F22: =D22-E22 -> #DIV/0! | G22: =-C22/A22 -> 0 | H22: =(B21/B22-1)/0.25 -> #DIV/0!
A23: 5.25 | G23: =-C23/A23 -> 0 | H23: =(B22/B23-1)/0.25 -> #DIV/0!
A24: 5.5 | G24: =-C24/A24 -> 0 | H24: =(B23/B24-1)/0.25 -> #DIV/0!
A25: 5.75 | G25: =-C25/A25 -> 0 | H25: =(B24/B25-1)/0.25 -> #DIV/0!
A26: 6 | G26: =-C26/A26 -> 0 | H26: =(B25/B26-1)/0.25 -> #DIV/0!
A27: 6.25 | G27: =-C27/A27 -> 0 | H27: =(B26/B27-1)/0.25 -> #DIV/0!
A28: 6.5 | G28: =-C28/A28 -> 0 | H28: =(B27/B28-1)/0.25 -> #DIV/0!
A29: 6.75 | G29: =-C29/A29 -> 0 | H29: =(B28/B29-1)/0.25 -> #DIV/0!
A30: 7 | D30: =(1-B30)/(SUM($B$3:B30) *0.25) -> #DIV/0! | E30: =VLOOKUP(A30,Sheet1!$V$15:$W$23,2)/100 -> 0 | F30: =D30-E30 -> #DIV/0! | G30: =-C30/A30 -> 0 | H30: =(B29/B30-1)/0.25 -> #DIV/0!
A31: 7.25 | G31: =-C31/A31 -> 0 | H31: =(B30/B31-1)/0.25 -> #DIV/0!
A32: 7.5 | G32: =-C32/A32 -> 0 | H32: =(B31/B32-1)/0.25 -> #DIV/0!
A33: 7.75 | G33: =-C33/A33 -> 0 | H33: =(B32/B33-1)/0.25 -> #DIV/0!
A34: 8 | G34: =-C34/A34 -> 0 | H34: =(B33/B34-1)/0.25 -> #DIV/0!
A35: 8.25 | G35: =-C35/A35 -> 0 | H35: =(B34/B35-1)/0.25 -> #DIV/0! | J35: Total | K35: =SUM(K3:K34) -> 0 | L35: =SUM(L3:L34) -> 0
A36: 8.5 | G36: =-C36/A36 -> 0 | H36: =(B35/B36-1)/0.25 -> #DIV/0!
A37: 8.75 | G37: =-C37/A37 -> 0 | H37: =(B36/B37-1)/0.25 -> #DIV/0!
A38: 9 | G38: =-C38/A38 -> 0 | H38: =(B37/B38-1)/0.25 -> #DIV/0!
A39: 9.25 | G39: =-C39/A39 -> 0 | H39: =(B38/B39-1)/0.25 -> #DIV/0!
A40: 9.5 | G40: =-C40/A40 -> 0 | H40: =(B39/B40-1)/0.25 -> #DIV/0!
...
