Workbook

Sheet data_treasury
A2: x | B2: 1. Input
C3: Treasury Par Yield Curve Rates
F4: Tenor | G4: Year Fraction | H4: Value | I4: Effective Date | J4: 01/23/2026 | K4: 금리 값들에 변수 연결
F5: 1 Mo | G5: =1/12 -> 0.083333333 | H5: =K5 + (analysis!$B$2 / 10000) -> 0.0378 | K5: 0.0378
F6: 1.5 Mo | G6: =1.5/12 -> 0.125 | H6: =K6 + (analysis!$B$2 / 10000) -> 0.0371 | K6: 0.0371
F7: 2 Mo | G7: =2/12 -> 0.16666667 | H7: =K7 + (analysis!$B$2 / 10000) -> 0.0372 | K7: 0.0372
F8: 3 Mo | G8: =3/12 -> 0.25 | H8: =K8 + (analysis!$B$2 / 10000) -> 0.037 | K8: 0.037
F9: 4 Mo | G9: =4/12 -> 0.33333333 | H9: =K9 + (analysis!$B$2 / 10000) -> 0.0367 | K9: 0.0367
F10: 6 Mo | G10: =6/12 -> 0.5 | H10: =K10 + (analysis!$B$2 / 10000) -> 0.0361 | K10: 0.0361
F11: 1 Yr | G11: 1 | H11: =K11 + (analysis!$B$2 / 10000) -> 0.0353 | K11: 0.0353
F12: 2 Yr | G12: 2 | H12: =K12 + (analysis!$B$2 / 10000) -> 0.036 | K12: 0.036
F13: 3 Yr | G13: 3 | H13: =K13 + (analysis!$B$2 / 10000) -> 0.0367 | K13: 0.0367
F14: 5 Yr | G14: 5 | H14: =K14 + (analysis!$B$2 / 10000) -> 0.0384 | K14: 0.0384
F15: 7 Yr | G15: 7 | H15: =K15 + (analysis!$B$2 / 10000) -> 0.0403 | K15: 0.0403
F16: 10 Yr | G16: 10 | H16: =K16 + (analysis!$B$2 / 10000) -> 0.0424 | K16: 0.0424
F17: 20 Yr | G17: 20 | H17: =K17 + (analysis!$B$2 / 10000) -> 0.0478 | K17: 0.0478
F18: 30 Yr | G18: 30 | H18: =K18 + (analysis!$B$2 / 10000) -> 0.0482 | K18: 0.0482
A21: x | B21: 2. (primary) Discount Factor (6m)
F22: T | G22: Discount Factor | H22: Par | I22: Spot(Continuously Compounded) | J22: Spot(Semi Annually Compounded) | K22: Forward Rate | L22: Price | M22: Error
F23: 0.5 | G23: =1/(1+VLOOKUP(F23,$G$5:$H$18,2,0)*F23) -> 0.98227003 | H23: =_xlfn.XLOOKUP(F23,$G$5:$G$18,$H$5:$H$18,"",0) -> 0.0361 | I23: =-LN(G23)/F23 -> 0.035778066 | J23: =2*(G23^(-1/(2*F23))-1) -> 0.0361 | K23: =I23 -> 0.035778066
F24: 1 | G24: 0.96561975 | H24: =_xlfn.XLOOKUP(F24,$G$5:$G$18,$H$5:$H$18,"",0) -> 0.0353 | I24: =-LN(G24)/F24 -> 0.03498516 | J24: =2*(G24^(-1/(2*F24))-1) -> 0.035292943 | K24: =(I24*F24-I23*F23)/(F24-F23) -> 0.034192255 | L24: =100*H24/2*SUM($G$23:G24)+100*G24 -> 100 | M24: =L24-100 -> 0
F25: 1.5 | G25: =EXP((F26-F25)/(F26-F24)*LN(G24)+(F25-F24)/(F26-F24)*LN(G26)) -> 0.94820802 | H25: =AVERAGE(H24,H26) -> 0.03565 | I25: =-LN(G25)/F25 -> 0.035454248 | J25: =2*(G25^(-1/(2*F25))-1) -> 0.035770364 | K25: =(I25*F25-I24*F24)/(F25-F24) -> 0.036392422
F26: 2 | G26: 0.93111026 | H26: =_xlfn.XLOOKUP(F26,$G$5:$G$18,$H$5:$H$18,"",0) -> 0.036 | I26: =-LN(G26)/F26 -> 0.035688791 | J26: =2*(G26^(-1/(2*F26))-1) -> 0.036009116 | K26: =(I26*F26-I25*F25)/(F26-F25) -> 0.036392422 | L26: =100*H26/2*SUM($G$23:G26)+100*G26 -> 100 | M26: =L26-100 -> -1.9468871e-12
F27: 2.5 | G27: =EXP((F28-F27)/(F28-F26)*LN(G26)+(F27-F26)/(F28-F26)*LN(G28)) -> 0.91366835 | H27: =AVERAGE(H28,H26) -> 0.03635 | I27: =-LN(G27)/F27 -> 0.036115053 | J27: =2*(G27^(-1/(2*F27))-1) -> 0.036443099 | K27: =(I27*F27-I26*F26)/(F27-F26) -> 0.0378201
F28: 3 | G28: 0.89655317 | H28: =_xlfn.XLOOKUP(F28,$G$5:$G$18,$H$5:$H$18,"",0) -> 0.0367 | I28: =-LN(G28)/F28 -> 0.036399227 | J28: =2*(G28^(-1/(2*F28))-1) -> 0.036732472 | K28: =(I28*F28-I27*F27)/(F28-F27) -> 0.0378201 | L28: =100*H28/2*SUM($G$23:G28)+100*G28 -> 100 | M28: =L28-100 -> 0
F29: 3.5 | G29: =EXP(($F$32-F29)/($F$32-$F$28)*LN($G$28)+(F29-$F$28)/($F$32-$F$28)*LN($G$32)) -> 0.87845204 | H29: =($F$32-F29)/($F$32-$F$28)*$H$28+(F29-$F$28)/($F$32-$F$28)*$H$32 -> 0.037125 | I29: =-LN(G29)/F29 -> 0.037026848 | J29: =2*(G29^(-1/(2*F29))-1) -> 0.03737172 | K29: =(I29*F29-I28*F28)/(F29-F28) -> 0.040792571
F30: 4 | G30: =EXP(($F$32-F30)/($F$32-$F$28)*LN($G$28)+(F30-$F$28)/($F$32-$F$28)*LN($G$32)) -> 0.86071637 | H30: =($F$32-F30)/($F$32-$F$28)*$H$28+(F30-$F$28)/($F$32-$F$28)*$H$32 -> 0.03755 | I30: =-LN(G30)/F30 -> 0.037497563 | J30: =2*(G30^(-1/(2*F30))-1) -> 0.037851287 | K30: =(I30*F30-I29*F29)/(F30-F29) -> 0.040792571
F31: 4.5 | G31: =EXP(($F$32-F31)/($F$32-$F$28)*LN($G$28)+(F31-$F$28)/($F$32-$F$28)*LN($G$32)) -> 0.84333877 | H31: =($F$32-F31)/($F$32-$F$28)*$H$28+(F31-$F$28)/($F$32-$F$28)*$H$32 -> 0.037975 | I31: =-LN(G31)/F31 -> 0.037863675 | J31: =2*(G31^(-1/(2*F31))-1) -> 0.038224362 | K31: =(I31*F31-I30*F30)/(F31-F30) -> 0.040792571
F32: 5 | G32: 0.82631202 | H32: =_xlfn.XLOOKUP(F32,$G$5:$G$18,$H$5:$H$18,"",0) -> 0.0384 | I32: =-LN(G32)/F32 -> 0.038156565 | J32: =2*(G32^(-1/(2*F32))-1) -> 0.038522871 | K32: =(I32*F32-I31*F31)/(F32-F31) -> 0.040792571 | L32: =100*H32/2*SUM($G$23:G32)+100*G32 -> 100 | M32: =L32-100 -> -3.3401193e-10
F33: 5.5 | G33: =EXP(($F$36-F33)/($F$36-$F$32)*LN($G$32)+(F33-$F$32)/($F$36-$F$32)*LN($G$36)) -> 0.8078126 | H33: =($F$36-F33)/($F$36-$F$32)*$H$32+(F33-$F$32)/($F$36-$F$32)*$H$36 -> 0.038875 | I33: =-LN(G33)/F33 -> 0.038804577 | J33: =2*(G33^(-1/(2*F33))-1) -> 0.039183472 | K33: =(I33*F33-I32*F32)/(F33-F32) -> 0.045284697
F34: 6 | G34: =EXP(($F$36-F34)/($F$36-$F$32)*LN($G$32)+(F34-$F$32)/($F$36-$F$32)*LN($G$36)) -> 0.78972735 | H34: =($F$36-F34)/($F$36-$F$32)*$H$32+(F34-$F$32)/($F$36-$F$32)*$H$36 -> 0.03935 | I34: =-LN(G34)/F34 -> 0.039344587 | J34: =2*(G34^(-1/(2*F34))-1) -> 0.039734136 | K34: =(I34*F34-I33*F33)/(F34-F33) -> 0.045284697
F35: 6.5 | G35: =EXP(($F$36-F35)/($F$36-$F$32)*LN($G$32)+(F35-$F$32)/($F$36-$F$32)*LN($G$36)) -> 0.77204698 | H35: =($F$36-F35)/($F$36-$F$32)*$H$32+(F35-$F$32)/($F$36-$F$32)*$H$36 -> 0.039825 | I35: =-LN(G35)/F35 -> 0.039801518 | J35: =2*(G35^(-1/(2*F35))-1) -> 0.040200199 | K35: =(I35*F35-I34*F34)/(F35-F34) -> 0.045284697
F36: 7 | G36: 0.75476245 | H36: =_xlfn.XLOOKUP(F36,$G$5:$G$18,$H$5:$H$18,"",0) -> 0.0403 | I36: =-LN(G36)/F36 -> 0.040193174 | J36: =2*(G36^(-1/(2*F36))-1) -> 0.040599766 | K36: =(I36*F36-I35*F35)/(F36-F35) -> 0.045284697 | L36: =100*H36/2*SUM($G$23:G36)+100*G36 -> 100 | M36: =L36-100 -> -1.4418333e-10
F37: 7.5 | G37: =EXP(($F$42-F37)/($F$42-$F$36)*LN($G$36)+(F37-$F$36)/($F$42-$F$36)*LN($G$42)) -> 0.73688104 | H37: =($F$42-F37)/($F$42-$F$36)*$H$36+(F37-$F$36)/($F$42-$F$36)*$H$42 -> 0.04065 | I37: =-LN(G37)/F37 -> 0.040710508 | J37: =2*(G37^(-1/(2*F37))-1) -> 0.04112767 | K37: =(I37*F37-I36*F36)/(F37-F36) -> 0.047953188
F38: 8 | G38: =EXP(($F$42-F38)/($F$42-$F$36)*LN($G$36)+(F38-$F$36)/($F$42-$F$36)*LN($G$42)) -> 0.71942327 | H38: =($F$42-F38)/($F$42-$F$36)*$H$36+(F38-$F$36)/($F$42-$F$36)*$H$42 -> 0.041 | I38: =-LN(G38)/F38 -> 0.041163176 | J38: =2*(G38^(-1/(2*F38))-1) -> 0.041589699 | K38: =(I38*F38-I37*F37)/(F38-F37) -> 0.047953188
F39: 8.5 | G39: =EXP(($F$42-F39)/($F$42-$F$36)*LN($G$36)+(F39-$F$36)/($F$42-$F$36)*LN($G$42)) -> 0.70237909 | H39: =($F$42-F39)/($F$42-$F$36)*$H$36+(F39-$F$36)/($F$42-$F$36)*$H$42 -> 0.04135 | I39: =-LN(G39)/F39 -> 0.041562588 | J39: =2*(G39^(-1/(2*F39))-1) -> 0.041997458 | K39: =(I39*F39-I38*F38)/(F39-F38) -> 0.047953188
F40: 9 | G40: =EXP(($F$42-F40)/($F$42-$F$36)*LN($G$36)+(F40-$F$36)/($F$42-$F$36)*LN($G$42)) -> 0.68573872 | H40: =($F$42-F40)/($F$42-$F$36)*$H$36+(F40-$F$36)/($F$42-$F$36)*$H$42 -> 0.0417 | I40: =-LN(G40)/F40 -> 0.041917622 | J40: =2*(G40^(-1/(2*F40))-1) -> 0.042359978 | K40: =(I40*F40-I39*F39)/(F40-F39) -> 0.047953188
F41: 9.5 | G41: =EXP(($F$42-F41)/($F$42-$F$36)*LN($G$36)+(F41-$F$36)/($F$42-$F$36)*LN($G$42)) -> 0.66949259 | H41: =($F$42-F41)/($F$42-$F$36)*$H$36+(F41-$F$36)/($F$42-$F$36)*$H$42 -> 0.04205 | I41: =-LN(G41)/F41 -> 0.042235283 | J41: =2*(G41^(-1/(2*F41))-1) -> 0.042684394 | K41: =(I41*F41-I40*F40)/(F41-F40) -> 0.047953188
F42: 10 | G42: 0.65363134 | H42: =_xlfn.XLOOKUP(F42,$G$5:$G$18,$H$5:$H$18,"",0) -> 0.0424 | I42: =-LN(G42)/F42 -> 0.042521178 | J42: =2*(G42^(-1/(2*F42))-1) -> 0.042976411 | K42: =(I42*F42-I41*F41)/(F42-F41) -> 0.047953188 | L42: =100*H42/2*SUM($G$23:G42)+100*G42 -> 100 | M42: =L42-100 -> 2.4471092e-11
F43: 10.5 | G43: =EXP(($F$62-F43)/($F$62-$F$42)*LN($G$42)+(F43-$F$42)/($F$62-$F$42)*LN($G$62)) -> 0.63560053 | H43: =($F$62-F43)/($F$62-$F$42)*$H$42+(F43-$F$42)/($F$62-$F$42)*$H$62 -> 0.04267 | I43: =-LN(G43)/F43 -> 0.043160477 | J43: =2*(G43^(-1/(2*F43))-1) -> 0.043629552 | K43: =(I43*F43-I42*F42)/(F43-F42) -> 0.055946447
...

Sheet data_ois
F1: Year Fraction | G1: DF | H1: ln(DF) | I1: Spot Curve | J1: Forward Curve(F(t,t+0.25)) | L1: Effective Date | M1: 01/23/2026
F2: 0.25 | G2: 0.99093408 | H2: -0.0091072675 | I2: 0.03642907 | J2: 0.036083261
F3: 0.5 | G3: 0.98207496 | H3: -0.018087638 | I3: 0.036175276 | J3: 0.034866012
F4: 0.75 | G4: 0.97358867 | H4: -0.026766372 | I4: 0.035688496 | J4: 0.03159175
F5: 1 | G5: 0.96595958 | H5: -0.034633284 | I5: 0.034633284 | J5: 0.033058749
F6: 1.25 | G6: 0.95804167 | H6: -0.042864006 | I6: 0.034291204 | J6: 0.033058749
F7: 1.5 | G7: 0.95018866 | H7: -0.051094727 | I7: 0.034063151 | J7: 0.033058749
F8: 1.75 | G8: 0.94240002 | H8: -0.059325449 | I8: 0.033900257 | J8: 0.033058749
F9: 2 | G9: 0.93467522 | H9: -0.067556171 | I9: 0.033778085 | J9: 0.034813399
F10: 2.25 | G10: 0.9266106 | H10: -0.076221864 | I10: 0.033876384 | J10: 0.034813399
F11: 2.5 | G11: 0.91861557 | H11: -0.084887558 | I11: 0.033955023 | J11: 0.034813399
F12: 2.75 | G12: 0.91068952 | H12: -0.093553252 | I12: 0.034019364 | J12: 0.034813399
F13: 3 | G13: 0.90283186 | H13: -0.10221895 | I13: 0.034072982 | J13: 0.03712408
... F120: 29.75 | G120: 0.28641137 | H120: -1.2503261 | I120: 0.042027769 | J120: 0.043222652
F121: 30 | G121: 0.28334959 | H121: -1.2610738 | I121: 0.042035794

Sheet engine
A1: [Input Parameters] | D1: [Pricing] 2-3번 | H1: [Benchmak] 3번 | I1: 검증
A2: Valuation Date | B2: 46045 | D2: Spot Dirty Price ($S$) | E2: =SUM(J17:J76) -> 77.458677 | F2: ← 전체 PV 합계 | H2: Forward Dirty Price | I2: =SUM(K17:K100) -> 72.408706 | J2: 3년뒤시점 현가합 (k열)
A3: Bond Name | B3: US Treasury 30Y | D3: (-) PV of Coupons ($I$) | E3: =SUM(J17:J22) -> 12.723235 | F3: ← Forward Date 이전 쿠폰만 | H3: (-) Fwd Accrued | I3: =E7 -> 0.30821918
A4: Maturity Date | B4: 57002 | D4: (=) Net Spot Value | E4: =E2 - E3 -> 64.735442 | H4: (=) Fwd Clean Price | I4: =I2 - I3 -> 72.100487
A5: Coupon Rate | B5: 0.045 | C5: 임의 | D5: (x) Repo Factor | E5: =EXP(B12 * B13) -> 1.1210761 | F5: ← OIS 3Y Spot Rate * 잔존만기
A6: Frequency | B6: 2 | D6: (=) Fwd Dirty Price | E6: =E4 * E5 -> 72.573355 | H6: Diff | I6: =E8-I4 -> 0.16464874
A7: Face Value | B7: 100 | D7: (-) Fwd Accrued | E7: =$B$7 * $B$5 * YEARFRAC(B22, $B$8, 1) -> 0.30821918 | F7: ← 선도 만기일 시점 경과이자 계산 (Act/Act)
A8: Forward Date | B8: 47166 | D8: (=) Fwd Clean Price | E8: =E6 - E7 -> 72.265136 | F8: 최종 쿼트 | L8: 3번 푸실때 활용해주시면 됩니다
A9: [Funding Cost] 1번 | L9: Fwd PV 구하기
A10: SOFR Rate | B10: =-LN(0.902831858529217) / 3 -> 0.034072982 | C10: ← continuous compounding 변환 | L10: =$B$13 -> 3.0691307
A11: Haircut | B11: 0.085 | C11: 임의 | L11: Lower T | M11: Upper T | N11: Lower DF | O11: Upper DF
A12: Effective Rate | B12: =B10 / (1 - B11) -> 0.037238232 | L12: 3 | M12: 3.5 | N12: =data_treasury!G28 -> 0.89655317 | O12: =data_treasury!G29 -> 0.87845204
A13: Time to Fwd | B13: =YEARFRAC(B2, B8, 1) -> 3.0691307 | L13: |
B14: "Time: YEARFRAC(VD, PaymentDate, 1) = Act/Act" 두 날짜 사이의 기간을 연단위의 소수점으로 환산해 주는 함수 | L14: |
L15: FWD Interpolated DF
A16: Index | B16: Payment Date | C16: 2-1번 Time(YEARFRAC)사용 | D16: Cash Flow | E16: Lower T | F16: Upper T | G16: Lower DF | H16: Upper DF | I16: 2-2번 Interpolated DF | J16: PV | K16: FWD PV | L16: =N12*EXP(LN(O12/N12)*($B$13-L12)/(M12-L12)) -> 0.89402843
A17: 1 | B17: =COUPNCD($B$2, $B$4, $B$6, 1) -> 46226 | C17: =YEARFRAC($B$2, B17, 1) -> 0.49589041 | D17: =$B$7 * $B$5 / $B$6 -> 2.25 | E17: =INDEX(data_ois!$F$2:$F$121, MATCH(C17, data_ois!$F$2:$F$121, 1)) -> 0.25 | F17: {=INDEX(data_ois!$F$2:$F$121, MATCH(C17, data_ois!$F$2:$F$121, 1)+1)} -> 0.5 | G17: =INDEX(data_ois!$G$2:$G$121, MATCH(C17, data_ois!$F$2:$F$121, 1)) -> 0.99093408 | H17: {=INDEX(data_ois!$G$2:$G$121, MATCH(C17, data_ois!$F$2:$F$121, 1)+1)} -> 0.98207496 | I17: =G17 + (H17 - G17) * (C17 - E17) / (F17 - E17) -> 0.98222059 | J17: =D17 * I17 -> 2.2099963 | K17: =IF(C17>$B$13, D17*(I17/$L$16), 0) -> 0
A18: =IF(B17="","",IF(B17<$B$4,A17+1,"")) -> 2 | B18: =IF(A18="","",EDATE(B17,12/$B$6)) -> 46410 | C18: =YEARFRAC($B$2, B18, 1) -> 1 | D18: =$B$7 * $B$5 / $B$6 -> 2.25 | E18: =INDEX(data_ois!$F$2:$F$121, MATCH(C18, data_ois!$F$2:$F$121, 1)) -> 1 | F18: {=INDEX(data_ois!$F$2:$F$121, MATCH(C18, data_ois!$F$2:$F$121, 1)+1)} -> 1.25 | G18: =INDEX(data_ois!$G$2:$G$121, MATCH(C18, data_ois!$F$2:$F$121, 1)) -> 0.96595958 | H18: {=INDEX(data_ois!$G$2:$G$121, MATCH(C18, data_ois!$F$2:$F$121, 1)+1)} -> 0.95804167 | I18: =G18 + (H18 - G18) * (C18 - E18) / (F18 - E18) -> 0.96595958 | J18: =D18 * I18 -> 2.1734091 | K18: =IF(C18>$B$13, D18*(I18/$L$16), 0) -> 0
A19: =IF(B18="","",IF(B18<$B$4,A18+1,"")) -> 3 | B19: =IF(A19="","",EDATE(B18,12/$B$6)) -> 46591 | C19: =YEARFRAC($B$2, B19, 1) -> 1.4958904 | D19: =$B$7 * $B$5 / $B$6 -> 2.25 | E19: =INDEX(data_ois!$F$2:$F$121, MATCH(C19, data_ois!$F$2:$F$121, 1)) -> 1.25 | F19: {=INDEX(data_ois!$F$2:$F$121, MATCH(C19, data_ois!$F$2:$F$121, 1)+1)} -> 1.5 | G19: =INDEX(data_ois!$G$2:$G$121, MATCH(C19, data_ois!$F$2:$F$121, 1)) -> 0.95804167 | H19: {=INDEX(data_ois!$G$2:$G$121, MATCH(C19, data_ois!$F$2:$F$121, 1)+1)} -> 0.95018866 | I19: =G19 + (H19 - G19) * (C19 - E19) / (F19 - E19) -> 0.95031775 | J19: =D19 * I19 -> 2.1382149 | K19: =IF(C19>$B$13, D19*(I19/$L$16), 0) -> 0
A20: =IF(B19="","",IF(B19<$B$4,A19+1,"")) -> 4 | B20: =IF(A20="","",EDATE(B19,12/$B$6)) -> 46775 | C20: =YEARFRAC($B$2, B20, 1) -> 1.9981752 | D20: =$B$7 * $B$5 / $B$6 -> 2.25 | E20: =INDEX(data_ois!$F$2:$F$121, MATCH(C20, data_ois!$F$2:$F$121, 1)) -> 1.75 | F20: {=INDEX(data_ois!$F$2:$F$121, MATCH(C20, data_ois!$F$2:$F$121, 1)+1)} -> 2 | G20: =INDEX(data_ois!$G$2:$G$121, MATCH(C20, data_ois!$F$2:$F$121, 1)) -> 0.94240002 | H20: {=INDEX(data_ois!$G$2:$G$121, MATCH(C20, data_ois!$F$2:$F$121, 1)+1)} -> 0.93467522 | I20: =G20 + (H20 - G20) * (C20 - E20) / (F20 - E20) -> 0.9347316 | J20: =D20 * I20 -> 2.1031461 | K20: =IF(C20>$B$13, D20*(I20/$L$16), 0) -> 0
A21: =IF(B20="","",IF(B20<$B$4,A20+1,"")) -> 5 | B21: =IF(A21="","",EDATE(B20,12/$B$6)) -> 46957 | C21: =YEARFRAC($B$2, B21, 1) -> 2.4963504 | D21: =$B$7 * $B$5 / $B$6 -> 2.25 | E21: =INDEX(data_ois!$F$2:$F$121, MATCH(C21, data_ois!$F$2:$F$121, 1)) -> 2.25 | F21: {=INDEX(data_ois!$F$2:$F$121, MATCH(C21, data_ois!$F$2:$F$121, 1)+1)} -> 2.5 | G21: =INDEX(data_ois!$G$2:$G$121, MATCH(C21, data_ois!$F$2:$F$121, 1)) -> 0.9266106 | H21: {=INDEX(data_ois!$G$2:$G$121, MATCH(C21, data_ois!$F$2:$F$121, 1)+1)} -> 0.91861557 | I21: =G21 + (H21 - G21) * (C21 - E21) / (F21 - E21) -> 0.91873229 | J21: =D21 * I21 -> 2.0671476 | K21: =IF(C21>$B$13, D21*(I21/$L$16), 0) -> 0
A22: =IF(B21="","",IF(B21<$B$4,A21+1,"")) -> 6 | B22: =IF(A22="","",EDATE(B21,12/$B$6)) -> 47141 | C22: =YEARFRAC($B$2, B22, 1) -> 3.0006845 | D22: =$B$7 * $B$5 / $B$6 -> 2.25 | E22: =INDEX(data_ois!$F$2:$F$121, MATCH(C22, data_ois!$F$2:$F$121, 1)) -> 3 | F22: {=INDEX(data_ois!$F$2:$F$121, MATCH(C22, data_ois!$F$2:$F$121, 1)+1)} -> 3.25 | G22: =INDEX(data_ois!$G$2:$G$121, MATCH(C22, data_ois!$F$2:$F$121, 1)) -> 0.90283186 | H22: {=INDEX(data_ois!$G$2:$G$121, MATCH(C22, data_ois!$F$2:$F$121, 1)+1)} -> 0.89452971 | I22: =G22 + (H22 - G22) * (C22 - E22) / (F22 - E22) -> 0.90280913 | J22: =D22 * I22 -> 2.0313205 | K22: =IF(C22>$B$13, D22*(I22/$L$16), 0) -> 0
A23: =IF(B22="","",IF(B22<$B$4,A22+1,"")) -> 7 | B23: =IF(A23="","",EDATE(B22,12/$B$6)) -> 47322 | C23: =YEARFRAC($B$2, B23, 1) -> 3.4962355 | D23: =$B$7 * $B$5 / $B$6 -> 2.25 | E23: =INDEX(data_ois!$F$2:$F$121, MATCH(C23, data_ois!$F$2:$F$121, 1)) -> 3.25 | F23: {=INDEX(data_ois!$F$2:$F$121, MATCH(C23, data_ois!$F$2:$F$121, 1)+1)} -> 3.5 | G23: =INDEX(data_ois!$G$2:$G$121, MATCH(C23, data_ois!$F$2:$F$121, 1)) -> 0.89452971 | H23: {=INDEX(data_ois!$G$2:$G$121, MATCH(C23, data_ois!$F$2:$F$121, 1)+1)} -> 0.88630391 | I23: =G23 + (H23 - G23) * (C23 - E23) / (F23 - E23) -> 0.88642777 | J23: =D23 * I23 -> 1.9944625 | K23: =IF(C23>$B$13, D23*(I23/$L$16), 0) -> 2.2308714 | L23: 미래 캐시플로를 FwdDate 시점으로 할인
A24: =IF(B23="","",IF(B23<$B$4,A23+1,"")) -> 8 | B24: =IF(A24="","",EDATE(B23,12/$B$6)) -> 47506 | C24: =YEARFRAC($B$2, B24, 1) -> 4.0005476 | D24: =$B$7 * $B$5 / $B$6 -> 2.25 | E24: =INDEX(data_ois!$F$2:$F$121, MATCH(C24, data_ois!$F$2:$F$121, 1)) -> 4 | F24: {=INDEX(data_ois!$F$2:$F$121, MATCH(C24, data_ois!$F$2:$F$121, 1)+1)} -> 4.25 | G24: =INDEX(data_ois!$G$2:$G$121, MATCH(C24, data_ois!$F$2:$F$121, 1)) -> 0.87007853 | H24: {=INDEX(data_ois!$G$2:$G$121, MATCH(C24, data_ois!$F$2:$F$121, 1)+1)} -> 0.86207757 | I24: =G24 + (H24 - G24) * (C24 - E24) / (F24 - E24) -> 0.870061 | J24: =D24 * I24 -> 1.9576373 | K24: =IF(C24>$B$13, D24*(I24/$L$16), 0) -> 2.1896812
A25: =IF(B24="","",IF(B24<$B$4,A24+1,"")) -> 9 | B25: =IF(A25="","",EDATE(B24,12/$B$6)) -> 47687 | C25: =YEARFRAC($B$2, B25, 1) -> 4.4961665 | D25: =$B$7 * $B$5 / $B$6 -> 2.25 | E25: =INDEX(data_ois!$F$2:$F$121, MATCH(C25, data_ois!$F$2:$F$121, 1)) -> 4.25 | F25: {=INDEX(data_ois!$F$2:$F$121, MATCH(C25, data_ois!$F$2:$F$121, 1)+1)} -> 4.5 | G25: =INDEX(data_ois!$G$2:$G$121, MATCH(C25, data_ois!$F$2:$F$121, 1)) -> 0.86207757 | H25: {=INDEX(data_ois!$G$2:$G$121, MATCH(C25, data_ois!$F$2:$F$121, 1)+1)} -> 0.85415018 | I25: =G25 + (H25 - G25) * (C25 - E25) / (F25 - E25) -> 0.85427174 | J25: =D25 * I25 -> 1.9221114 | K25: =IF(C25>$B$13, D25*(I25/$L$16), 0) -> 2.1499444
A26: =IF(B25="","",IF(B25<$B$4,A25+1,"")) -> 10 | B26: =IF(A26="","",EDATE(B25,12/$B$6)) -> 47871 | C26: =YEARFRAC($B$2, B26, 1) -> 5.0004564 | D26: =$B$7 * $B$5 / $B$6 -> 2.25 | E26: =INDEX(data_ois!$F$2:$F$121, MATCH(C26, data_ois!$F$2:$F$121, 1)) -> 5 | F26: {=INDEX(data_ois!$F$2:$F$121, MATCH(C26, data_ois!$F$2:$F$121, 1)+1)} -> 5.25 | G26: =INDEX(data_ois!$G$2:$G$121, MATCH(C26, data_ois!$F$2:$F$121, 1)) -> 0.83851344 | H26: {=INDEX(data_ois!$G$2:$G$121, MATCH(C26, data_ois!$F$2:$F$121, 1)+1)} -> 0.83016388 | I26: =G26 + (H26 - G26) * (C26 - E26) / (F26 - E26) -> 0.83849819 | J26: =D26 * I26 -> 1.8866209 | K26: =IF(C26>$B$13, D26*(I26/$L$16), 0) -> 2.1102471
A27: =IF(B26="","",IF(B26<$B$4,A26+1,"")) -> 11 | B27: =IF(A27="","",EDATE(B26,12/$B$6)) -> 48052 | C27: =YEARFRAC($B$2, B27, 1) -> 5.4961205 | D27: =$B$7 * $B$5 / $B$6 -> 2.25 | E27: =INDEX(data_ois!$F$2:$F$121, MATCH(C27, data_ois!$F$2:$F$121, 1)) -> 5.25 | F27: {=INDEX(data_ois!$F$2:$F$121, MATCH(C27, data_ois!$F$2:$F$121, 1)+1)} -> 5.5 | G27: =INDEX(data_ois!$G$2:$G$121, MATCH(C27, data_ois!$F$2:$F$121, 1)) -> 0.83016388 | H27: {=INDEX(data_ois!$G$2:$G$121, MATCH(C27, data_ois!$F$2:$F$121, 1)+1)} -> 0.82189746 | I27: =G27 + (H27 - G27) * (C27 - E27) / (F27 - E27) -> 0.82202573 | J27: =D27 * I27 -> 1.8495579 | K27: =IF(C27>$B$13, D27*(I27/$L$16), 0) -> 2.0687909
A28: =IF(B27="","",IF(B27<$B$4,A27+1,"")) -> 12 | B28: =IF(A28="","",EDATE(B27,12/$B$6)) -> 48236 | C28: =YEARFRAC($B$2, B28, 1) -> 5.9980446 | D28: =$B$7 * $B$5 / $B$6 -> 2.25 | E28: =INDEX(data_ois!$F$2:$F$121, MATCH(C28, data_ois!$F$2:$F$121, 1)) -> 5.75 | F28: {=INDEX(data_ois!$F$2:$F$121, MATCH(C28, data_ois!$F$2:$F$121, 1)+1)} -> 6 | G28: =INDEX(data_ois!$G$2:$G$121, MATCH(C28, data_ois!$F$2:$F$121, 1)) -> 0.81371335 | H28: {=INDEX(data_ois!$G$2:$G$121, MATCH(C28, data_ois!$F$2:$F$121, 1)+1)} -> 0.80561074 | I28: =G28 + (H28 - G28) * (C28 - E28) / (F28 - E28) -> 0.80567411 | J28: =D28 * I28 -> 1.8127668 | K28: =IF(C28>$B$13, D28*(I28/$L$16), 0) -> 2.0276388
A29: =IF(B28="","",IF(B28<$B$4,A28+1,"")) -> 13 | B29: =IF(A29="","",EDATE(B28,12/$B$6)) -> 48418 | C29: =YEARFRAC($B$2, B29, 1) -> 6.4962847 | D29: =$B$7 * $B$5 / $B$6 -> 2.25 | E29: =INDEX(data_ois!$F$2:$F$121, MATCH(C29, data_ois!$F$2:$F$121, 1)) -> 6.25 | F29: {=INDEX(data_ois!$F$2:$F$121, MATCH(C29, data_ois!$F$2:$F$121, 1)+1)} -> 6.5 | G29: =INDEX(data_ois!$G$2:$G$121, MATCH(C29, data_ois!$F$2:$F$121, 1)) -> 0.79758881 | H29: {=INDEX(data_ois!$G$2:$G$121, MATCH(C29, data_ois!$F$2:$F$121, 1)+1)} -> 0.78964676 | I29: =G29 + (H29 - G29) * (C29 - E29) / (F29 - E29) -> 0.78976478 | J29: =D29 * I29 -> 1.7769708 | K29: =IF(C29>$B$13, D29*(I29/$L$16), 0) -> 1.9875998
A30: =IF(B29="","",IF(B29<$B$4,A29+1,"")) -> 14 | B30: =IF(A30="","",EDATE(B29,12/$B$6)) -> 48602 | C30: =YEARFRAC($B$2, B30, 1) -> 7.0006845 | D30: =$B$7 * $B$5 / $B$6 -> 2.25 | E30: =INDEX(data_ois!$F$2:$F$121, MATCH(C30, data_ois!$F$2:$F$121, 1)) -> 7 | F30: {=INDEX(data_ois!$F$2:$F$121, MATCH(C30, data_ois!$F$2:$F$121, 1)+1)} -> 7.25 | G30: =INDEX(data_ois!$G$2:$G$121, MATCH(C30, data_ois!$F$2:$F$121, 1)) -> 0.77399912 | H30: {=INDEX(data_ois!$G$2:$G$121, MATCH(C30, data_ois!$F$2:$F$121, 1)+1)} -> 0.76575368 | I30: =G30 + (H30 - G30) * (C30 - E30) / (F30 - E30) -> 0.77397654 | J30: =D30 * I30 -> 1.7414472 | K30: =IF(C30>$B$13, D30*(I30/$L$16), 0) -> 1.9478656
A31: =IF(B30="","",IF(B30<$B$4,A30+1,"")) -> 15 | B31: =IF(A31="","",EDATE(B30,12/$B$6)) -> 48783 | C31: =YEARFRAC($B$2, B31, 1) -> 7.4962355 | D31: =$B$7 * $B$5 / $B$6 -> 2.25 | E31: =INDEX(data_ois!$F$2:$F$121, MATCH(C31, data_ois!$F$2:$F$121, 1)) -> 7.25 | F31: {=INDEX(data_ois!$F$2:$F$121, MATCH(C31, data_ois!$F$2:$F$121, 1)+1)} -> 7.5 | G31: =INDEX(data_ois!$G$2:$G$121, MATCH(C31, data_ois!$F$2:$F$121, 1)) -> 0.76575368 | H31: {=INDEX(data_ois!$G$2:$G$121, MATCH(C31, data_ois!$F$2:$F$121, 1)+1)} -> 0.75759608 | I31: =G31 + (H31 - G31) * (C31 - E31) / (F31 - E31) -> 0.75771892 | J31: =D31 * I31 -> 1.7048676 | K31: =IF(C31>$B$13, D31*(I31/$L$16), 0) -> 1.9069501
A32: =IF(B31="","",IF(B31<$B$4,A31+1,"")) -> 16 | B32: =IF(A32="","",EDATE(B31,12/$B$6)) -> 48967 | C32: =YEARFRAC($B$2, B32, 1) -> 8.0006085 | D32: =$B$7 * $B$5 / $B$6 -> 2.25 | E32: =INDEX(data_ois!$F$2:$F$121, MATCH(C32, data_ois!$F$2:$F$121, 1)) -> 8 | F32: {=INDEX(data_ois!$F$2:$F$121, MATCH(C32, data_ois!$F$2:$F$121, 1)+1)} -> 8.25 | G32: =INDEX(data_ois!$G$2:$G$121, MATCH(C32, data_ois!$F$2:$F$121, 1)) -> 0.74154067 | H32: {=INDEX(data_ois!$G$2:$G$121, MATCH(C32, data_ois!$F$2:$F$121, 1)+1)} -> 0.73364101 | I32: =G32 + (H32 - G32) * (C32 - E32) / (F32 - E32) -> 0.74152144 | J32: =D32 * I32 -> 1.6684232 | K32: =IF(C32>$B$13, D32*(I32/$L$16), 0) -> 1.8661859
A33: =IF(B32="","",IF(B32<$B$4,A32+1,"")) -> 17 | B33: =IF(A33="","",EDATE(B32,12/$B$6)) -> 49148 | C33: =YEARFRAC($B$2, B33, 1) -> 8.4961971 | D33: =$B$7 * $B$5 / $B$6 -> 2.25 | E33: =INDEX(data_ois!$F$2:$F$121, MATCH(C33, data_ois!$F$2:$F$121, 1)) -> 8.25 | F33: {=INDEX(data_ois!$F$2:$F$121, MATCH(C33, data_ois!$F$2:$F$121, 1)+1)} -> 8.5 | G33: =INDEX(data_ois!$G$2:$G$121, MATCH(C33, data_ois!$F$2:$F$121, 1)) -> 0.73364101 | H33: {=INDEX(data_ois!$G$2:$G$121, MATCH(C33, data_ois!$F$2:$F$121, 1)+1)} -> 0.72582551 | I33: =G33 + (H33 - G33) * (C33 - E33) / (F33 - E33) -> 0.72594439 | J33: =D33 * I33 -> 1.6333749 | K33: =IF(C33>$B$13, D33*(I33/$L$16), 0) -> 1.8269832
A34: =IF(B33="","",IF(B33<$B$4,A33+1,"")) -> 18 | B34: =IF(A34="","",EDATE(B33,12/$B$6)) -> 49332 | C34: =YEARFRAC($B$2, B34, 1) -> 9.0005476 | D34: =$B$7 * $B$5 / $B$6 -> 2.25 | E34: =INDEX(data_ois!$F$2:$F$121, MATCH(C34, data_ois!$F$2:$F$121, 1)) -> 9 | F34: {=INDEX(data_ois!$F$2:$F$121, MATCH(C34, data_ois!$F$2:$F$121, 1)+1)} -> 9.25 | G34: =INDEX(data_ois!$G$2:$G$121, MATCH(C34, data_ois!$F$2:$F$121, 1)) -> 0.71044339 | H34: {=INDEX(data_ois!$G$2:$G$121, MATCH(C34, data_ois!$F$2:$F$121, 1)+1)} -> 0.70287502 | I34: =G34 + (H34 - G34) * (C34 - E34) / (F34 - E34) -> 0.71042681 | J34: =D34 * I34 -> 1.5984603 | K34: =IF(C34>$B$13, D34*(I34/$L$16), 0) -> 1.7879301
A35: =IF(B34="","",IF(B34<$B$4,A34+1,"")) -> 19 | B35: =IF(A35="","",EDATE(B34,12/$B$6)) -> 49513 | C35: =YEARFRAC($B$2, B35, 1) -> 9.4961665 | D35: =$B$7 * $B$5 / $B$6 -> 2.25 | E35: =INDEX(data_ois!$F$2:$F$121, MATCH(C35, data_ois!$F$2:$F$121, 1)) -> 9.25 | F35: {=INDEX(data_ois!$F$2:$F$121, MATCH(C35, data_ois!$F$2:$F$121, 1)+1)} -> 9.5 | G35: =INDEX(data_ois!$G$2:$G$121, MATCH(C35, data_ois!$F$2:$F$121, 1)) -> 0.70287502 | H35: {=INDEX(data_ois!$G$2:$G$121, MATCH(C35, data_ois!$F$2:$F$121, 1)+1)} -> 0.69538727 | I35: =G35 + (H35 - G35) * (C35 - E35) / (F35 - E35) -> 0.69550208 | J35: =D35 * I35 -> 1.5648797 | K35: =IF(C35>$B$13, D35*(I35/$L$16), 0) -> 1.750369
... A76: =IF(B75="","",IF(B75<$B$4,A75+1,"")) -> 60 | B76: =IF(A76="","",EDATE(B75,12/$B$6)) -> 57002 | C76: =YEARFRAC($B$2, B76, 1) -> 29.997969 | D76: =$B$7 * $B$5 / $B$6 -> 2.25 | E76: =INDEX(data_ois!$F$2:$F$121, MATCH(C76, data_ois!$F$2:$F$121, 1)) -> 29.75 | F76: {=INDEX(data_ois!$F$2:$F$121, MATCH(C76, data_ois!$F$2:$F$121, 1)+1)} -> 30 | G76: =INDEX(data_ois!$G$2:$G$121, MATCH(C76, data_ois!$F$2:$F$121, 1)) -> 0.28641137 | H76: {=INDEX(data_ois!$G$2:$G$121, MATCH(C76, data_ois!$F$2:$F$121, 1)+1)} -> 0.28334959 | I76: =G76 + (H76 - G76) * (C76 - E76) / (F76 - E76) -> 0.28337447 | J76: =D76 * I76 -> 0.63759256 | K76: =IF(C76>$B$13, D76*(I76/$L$16), 0) -> 0.7131681
A77: =IF(B76="","",IF(B76<$B$4,A76+1,"")) | B77: =IF(A77="","",EDATE(B76,12/$B$6)) | C77: =IF(B77="","",YEARFRAC($B$2, B77, 1)) | D77: =IF(B77="","",IF(B77=$B$4, ($B$5/$B$6)*$B$7 + $B$7, ($B$5/$B$6)*$B$7))
A78: =IF(B77="","",IF(B77<$B$4,A77+1,"")) | B78: =IF(A78="","",EDATE(B77,12/$B$6)) | C78: =IF(B78="","",YEARFRAC($B$2, B78, 1)) | D78: =IF(B78="","",IF(B78=$B$4, ($B$5/$B$6)*$B$7 + $B$7, ($B$5/$B$6)*$B$7))
A79: =IF(B78="","",IF(B78<$B$4,A78+1,"")) | B79: =IF(A79="","",EDATE(B78,12/$B$6)) | C79: =IF(B79="","",YEARFRAC($B$2, B79, 1)) | D79: =IF(B79="","",IF(B79=$B$4, ($B$5/$B$6)*$B$7 + $B$7, ($B$5/$B$6)*$B$7))
A80: =IF(B79="","",IF(B79<$B$4,A79+1,"")) | B80: =IF(A80="","",EDATE(B79,12/$B$6)) | C80: =IF(B80="","",YEARFRAC($B$2, B80, 1)) | D80: =IF(B80="","",IF(B80=$B$4, ($B$5/$B$6)*$B$7 + $B$7, ($B$5/$B$6)*$B$7))
...

Sheet analysis
A1: [Scenario] | D1: [Sensitivity Analysis] | F1: DV01 | G1: 민감도 분석
A2: Curve Shift | B2: 0 | E2: =engine!E8 -> 72.265136
A3: Current Fwd Price | B3: =engine!$E$8 -> 72.265136 | D3: -10 | E3: =engine!E9 -> 0 | F3: =E3-$E$6 -> 0
D4: -5 | E4: =engine!E10 -> 0 | F4: =E4-$E$6 -> 0
D5: -1 | E5: =engine!E11 -> 0 | F5: =E5-$E$6 -> 0
D6: 0 | E6: =engine!E12 -> 0 | F6: =E6-$E$6 -> 0
D7: 1 | E7: =engine!E13 -> 0 | F7: =E7-$E$6 -> 0
D8: 5 | E8: =engine!E14 -> 0 | F8: =E8-$E$6 -> 0
D9: 10 | E9: =engine!E15 -> 0 | F9: =E9-$E$6 -> 0
E10: 데이터표 D2:E9드래그 - 데이터 - 가상분석 - 데이터표 -열입력B2
A12: [analysis]
A13: Spread | B13: 5 | C13: 데스크마진(단위bp)
A14: Adjusted Sofr | B14: =engine!B10 + (B13 / 10000) -> 0.034572982 | C14: 5bp 더해주기 +5/10000
A15: Adj Efective rate | B15: =engine!B12 + (B13 / 10000) -> 0.037738232 | C15: 마진 얹은 실효 조달금리
A16: Ask Fwd Price | B16: =(engine!E2 - engine!E3) * EXP(B15 * engine!B13) - engine!E7 -> 72.37659 | C16: 마진 얹은 최종 호가
A17: Base Mid Price (Dealer) | B17: =engine!E8 -> 72.265136 | C17: 순수원가
A18: Margin per 100 Face | B18: =B16 - B17 -> 0.11145405 | C18: 순수익 마진
A19: Total Notional ($) | B19: 1000000 | C19: 사이즈
A20: Total Day 1 PnL ($) | B20: =(B18 / 100) * B19 -> 1114.5405 | C20: $
C21: OIS 무위험 조달금리에 데스크 마진을 더해 고객(보험사)에게 호가를 제시하고, 이것이 마진수익이 됩니다.
E31: 리스크 분석 부분 어떻게 해야하는지 모르겠어요ㅠㅠㅠㅠ
